Workbook
Name BEARING_WALL_SYSTEMS_no_frame: Sheet3!$C$10:$C$13
Name BUILDING_FRAME_SYSTEMS_with_bracing_or_shear_wall: Sheet3!$C$14:$C$21
Name BWS: Sheet3!$C$10:$C$13
Name DUAL_SHEAR_WALL_FRAME_SYSTEM: Sheet3!$C$36
Name DUAL_SYSTEMS_INTERMEDIATE_MOMENT_FRAMES: Sheet3!$C$32:$C$35
Name DUAL_SYSTEMS_SPECIAL_MOMENT_FRAMES: Sheet3!$C$28:$C$31
Name framesystem: Sheet3!$B$39:$B$45
Name make: Sheet3!$B$39:$B$41
Name MOMENT_RESISTING_FRAME_SYSTEMS_no_shear_wall: Sheet3!$C$22:$C$27
Name STEEL_SYSTEMS_NOT_SPECIFICALLY_DETAILED: Sheet3!$C$37

Sheet Video & Instruction 
B14: qLearnify is an educational platform dedicated to the professional development of engineers and architects.
C17: Website: | E17: https://qlearnify.com/
C18: Facebook: | E18: https://www.facebook.com/qlearnify
C19: Youtube (Bangla): | E19: https://www.youtube.com/@qlearnify-bn
C20: Youtube (English): | E20: https://www.youtube.com/@qlearnify-en
C21: WhatsApp: | E21: https://wa.me/8801511250108
C22: LinkedIn: | E22: https://www.linkedin.com/company/qlearnify/
B24: Note: This Excel sheet has been created for educational purposes; please validate it according to your own standards before using it for professional work.
A34: Bangla: | B34: https://youtube.com/playlist?list=PLxle8F-wJI7P43K0GljphED4I5TRXu6Zx&si=el-Lrxm5mB1Vmgcf
A36: English: | B36: https://youtube.com/playlist?list=PLTscI_CLWNfB_1x6_7zylwLZWo7mKypCq&si=QzFh_rJa61GU0YNW

Sheet EQ Analysis
B1: This is the Poperty of qLearnify
B2: This are Manageing By SM Hedaetullah And N.J. Disha
B3: Support us And stay connected
B4: This file is only for edicational Perpose. Pls don't misuse it.
B9: Length (L) ft | C9: Width (B) | D9: No of Sotry (n) | E9: w (psf) | F9: Hight above base (Ft) | G9: Soil Type | H9: Town | I9: Z | J9: Zone | K9: Occupancy Category | L9: Importance factor I
B10: 120 | C10: 100 | D10: 6 | E10: 200 | F10: 97 | G10: SD | H10: Dhaka | I10: =VLOOKUP(H10,Sheet2!C14:D79,2,FALSE) -> 0.2 | J10: =IF(I10=0.12,1,IF(I10=0.2,2,IF(I10=0.28,3,IF(I10=0.36,4,"")))) -> 2 | K10: I, II | L10: =VLOOKUP(K10,Sheet2!L14:M16,2,FALSE) -> 1
B13: Structural Type --> | F13: DUAL_SYSTEMS_SPECIAL_MOMENT_FRAMES | G13: Coefficients to Estimate Approximate Period | N13: Required value for Etabs Calculation (According code)
B14: Seismic Force Resisting System --> | F14: 3. Special reinforced concrete shear walls | G14: Structure type | H14: Ct | I14: m | N14: ASCE 7-05/7-10 | Q14: BNBC-2020 ( User Coefficent)
B15: Percentage of critical damping--> | F15: 0.05 | G15: CMRF | H15: =VLOOKUP(G15,Sheet2!P14:Q17,2,0) -> 0.0466 | I15: =VLOOKUP(G15,Sheet2!P14:R17,3,FALSE) -> 0.9 | N15: T | P15: =I20 -> 0.98218663 | Q15: C | S15: =F27/100 -> 0.052361303
B16: Response Reduction Factor(R)--> | F16: =VLOOKUP(F14,Sheet3!C10:D37,2,0) -> 7 | N16: R | P16: =F16 -> 7 | Q16: K | S16: =G29 -> 1.2410933
N17: Cd | P17: =I25 -> 5.5
N18: Ss | P18: =HLOOKUP(J10,Sheet2!G23:J25,2,FALSE) -> 0.5
E19: ƞ | F19: Revised | N19: S1 | P19: =HLOOKUP(J10,Sheet2!G23:J25,3,FALSE) -> 0.2
E20: =SQRT((10/(5+F15*100))) -> 1 | F20: =IF(E20<0.55,0.55,E20) -> 1 | G20: Revised | H20: Building Period, T (s) | I20: =H15*((F10/3.28)^I15) -> 0.98218663 | N20: Fa | P20: =INDEX(Sheet2!G30:J34,MATCH('EQ Analysis'!G10,Sheet2!F30:F34,0),MATCH('EQ Analysis'!J10,Sheet2!G29:J29,0)) -> 1.35
E21: Cs | F21: =I24*(1+((I20/I21)*((2.5*F20)-1))) -> 11.29464 | G21: =IF(AND(0<=I20,I20<=I21),F21,0) -> 0 | H21: TB (s) | I21: =VLOOKUP(G10,Sheet2!F14:H18,3,0) -> 0.2 | N21: Fv | P21: =INDEX(Sheet2!G39:J43,MATCH('EQ Analysis'!G10,Sheet2!F39:F43,0),MATCH('EQ Analysis'!J10,Sheet2!G38:J38,0)) -> 2.7
E22: Cs | F22: =2.5*I24*F20 -> 3.375 | G22: =IF(G21<>0,0,IF(AND(I21<=I20,I20<=I22),F22,0)) -> 0 | H22: TC (s) | I22: =VLOOKUP(G10,Sheet2!F14:I18,4,0) -> 0.8 | N22: Long Period Trans. | P22: =IF(I20<2,2,4) -> 2
E23: Cs | F23: =2.5*I24*F20*(I22/I20) -> 2.7489684 | G23: =IF(SUM(G21:G22)<>0,0,IF(AND(I22<=I20,I20<=I23),F23,0)) -> 2.7489684 | H23: TD (s) | I23: =VLOOKUP(G10,Sheet2!F14:J18,5,0) -> 2 | N23: Ω | P23: =VLOOKUP(F14,Sheet3!C10:F37,3,FALSE) -> 2.5
E24: Cs | F24: =2.5*I24*F20*((I22*I23)/I20^2) -> 5.5976498 | G24: =IF(SUM(G21:G23)<>0,0,IF(AND(I22<=I20,I20<=4),F24,0)) -> 0 | H24: S | I24: =VLOOKUP(G10,Sheet2!F14:G18,2,0) -> 1.35
E25: Cs | F25: =SUM(G21:G24) -> 2.7489684 | G25: =F25 -> 2.7489684 | H25: Cd | I25: =VLOOKUP(F14,Sheet3!C10:F37,4,FALSE) -> 5.5
E27: Sa | F27: =MAX(((2*I10*L10*G25)/(3*F16)),(0.67*0.15*I10*L10*I24*I24))*100 -> 5.2361303 | G27: K
E28: Wa | F28: =B10*C10*D10*E10/1000 -> 14400
E29: V | F29: =F28*F27/100 -> 754.00276 | G29: =IF(I20<=0.5,1,IF(I20>=2.5,2,IF(AND(I20>0.5,I20<2.5),(1+(0.5*(I20-0.5))),""))) -> 1.2410933
B34: Base Shear Distribution (Horizontal Direction)
B35: Story No | C35: Story Hight Above Base (ft) | D35: Cum. Hight (hi) (ft) | E35: Effective seismic weight (Wx)-Kips | F35: Wxhi^k | G35: ∑Wxhi^k | H35: Fh ( Kips) | I35: Fh ( KN)
A36: 1 | B36: GF | C36: 10 | D36: =IF(C36="","",C36) -> 10 | E36: =IF(D36="","",F$28/D$10) -> 2400 | F36: =IF(E36="","",(E36*D36^G$29)) -> 41812.348 | G36: =SUM(F36:F50) -> 845919.04 | H36: =IF(F36="","",(F36*F$29)/G$36) -> 37.269082 | I36: =IF(H36="","",(H36*4.45)) -> 165.84741
A37: 2 | B37: f1 | C37: 10 | D37: =IF(C37="","",(C37+D36)) -> 20 | E37: =IF(D37="","",F$28/D$10) -> 2400 | F37: =IF(E37="","",(E37*D37^G$29)) -> 98835.024 | H37: =IF(F37="","",(F37*F$29)/G$36) -> 88.09576 | I37: =IF(H37="","",(H37*4.45)) -> 392.02613
A38: 3 | B38: f2 | C38: 10 | D38: =IF(C38="","",(C38+D37)) -> 30 | E38: =IF(D38="","",F$28/D$10) -> 2400 | F38: =IF(E38="","",(E38*D38^G$29)) -> 163476.96 | H38: =IF(F38="","",(F38*F$29)/G$36) -> 145.7138 | I38: =IF(H38="","",(H38*4.45)) -> 648.42642
A39: 4 | B39: f3 | C39: 10 | D39: =IF(C39="","",(C39+D38)) -> 40 | E39: =IF(D39="","",F$28/D$10) -> 2400 | F39: =IF(E39="","",(E39*D39^G$29)) -> 233623.86 | H39: =IF(F39="","",(F39*F$29)/G$36) -> 208.23864 | I39: =IF(H39="","",(H39*4.45)) -> 926.66196
A40: 5 | B40: f4 | C40: 10 | D40: =IF(C40="","",(C40+D39)) -> 50 | E40: =IF(D40="","",F$28/D$10) -> 2400 | F40: =IF(E40="","",(E40*D40^G$29)) -> 308170.85 | H40: =IF(F40="","",(F40*F$29)/G$36) -> 274.68547 | I40: =IF(H40="","",(H40*4.45)) -> 1222.3504
D41: =IF(C41="","",(C41+D40)) | E41: =IF(D41="","",F$28/D$10) | F41: =IF(E41="","",(E41*D41^G$29)) | H41: =IF(F41="","",(F41*F$29)/G$36) | I41: =IF(H41="","",(H41*4.45))
D42: =IF(C42="","",(C42+D41)) | E42: =IF(D42="","",F$28/D$10) | F42: =IF(E42="","",(E42*D42^G$29)) | H42: =IF(F42="","",(F42*F$29)/G$36) | I42: =IF(H42="","",(H42*4.45))
D43: =IF(C43="","",(C43+D42)) | E43: =IF(D43="","",F$28/D$10) | F43: =IF(E43="","",(E43*D43^G$29)) | H43: =IF(F43="","",(F43*F$29)/G$36) | I43: =IF(H43="","",(H43*4.45))
D44: =IF(C44="","",(C44+D43)) | E44: =IF(D44="","",F$28/D$10) | F44: =IF(E44="","",(E44*D44^G$29)) | H44: =IF(F44="","",(F44*F$29)/G$36) | I44: =IF(H44="","",(H44*4.45))
D45: =IF(C45="","",(C45+D44)) | E45: =IF(D45="","",F$28/D$10) | F45: =IF(E45="","",(E45*D45^G$29)) | H45: =IF(F45="","",(F45*F$29)/G$36) | I45: =IF(H45="","",(H45*4.45))
D46: =IF(C46="","",(C46+D45)) | E46: =IF(D46="","",F$28/D$10) | F46: =IF(E46="","",(E46*D46^G$29)) | H46: =IF(F46="","",(F46*F$29)/G$36) | I46: =IF(H46="","",(H46*4.45))
D47: =IF(C47="","",(C47+D46)) | E47: =IF(D47="","",F$28/D$10) | F47: =IF(E47="","",(E47*D47^G$29)) | H47: =IF(F47="","",(F47*F$29)/G$36) | I47: =IF(H47="","",(H47*4.45))
D48: =IF(C48="","",(C48+D47)) | E48: =IF(D48="","",F$28/D$10) | F48: =IF(E48="","",(E48*D48^G$29)) | H48: =IF(F48="","",(F48*F$29)/G$36) | I48: =IF(H48="","",(H48*4.45))
D49: =IF(C49="","",(C49+D48)) | E49: =IF(D49="","",F$28/D$10) | F49: =IF(E49="","",(E49*D49^G$29)) | H49: =IF(F49="","",(F49*F$29)/G$36) | I49: =IF(H49="","",(H49*4.45))
D50: =IF(C50="","",(C50+D49)) | E50: =IF(D50="","",F$28/D$10) | F50: =IF(E50="","",(E50*D50^G$29)) | H50: =IF(F50="","",(F50*F$29)/G$36) | I50: =IF(H50="","",(H50*4.45))
D51: =IF(C51="","",(C51+D50)) | E51: =IF(D51="","",F$28/D$10) | F51: =IF(E51="","",(E51*D51^G$29)) | H51: =IF(F51="","",(F51*F$29)/G$36) | I51: =IF(H51="","",(H51*4.45))

Sheet Sheet2
B1: This is the Poperty of School of civil Engineering
B2: This Channel are Manageing By SM Hedaetullah And N.J. Disha (B.Sc. In Civil Engineering)
B3: Support us And stay connected
B4: This file is only for edicational Perpose. Pls don't misuse it.
B10: Table 6.2.15: Seismic Zone Coefficient Z for Some Important Towns of Bangladesh | F10: Table 6.2.16: Site Dependent Soil Factor and Other Parameters Defining Elastic Response Spectrum | K10: Table 6.2.17: Importance Factors for Buildings and Structures for Earthquake design | O10: Table 6.2.20: Values for Coefficients to Estimate Approximate Period
C13: Town | D13: Z | F13: Soil type | G13: S | H13: TB(s) | I13: TC (s) | J13: TD (s) | L13: Occupancy Category | M13: Importance factor I | O13: Structure type | Q13: Ct | R13: m
C14: Bagerhat | D14: 0.12 | F14: SA | G14: 1 | H14: 0.15 | I14: 0.4 | J14: 2 | L14: I, II | M14: 1 | O14: Concrete moment-resisting frames | P14: CMRF | Q14: 0.0466 | R14: 0.9
C15: Bandarban | D15: 0.28 | F15: SB | G15: 1.2 | H15: 0.15 | I15: 0.5 | J15: 2 | L15: III | M15: 1.25 | O15: Steel moment-resisting frames | P15: SMRF | Q15: 0.0724 | R15: 0.8
C16: Barguna | D16: 0.12 | F16: SC | G16: 1.15 | H16: 0.2 | I16: 0.6 | J16: 2 | L16: IV | M16: 1.5 | O16: Eccentrically braced steel frame | P16: EBSF | Q16: 0.0731 | R16: 0.75
C17: Barisal | D17: 0.12 | F17: SD | G17: 1.35 | H17: 0.2 | I17: 0.8 | J17: 2 | O17: All other structural systems | P17: AOSS | Q17: 0.0488 | R17: 0.75
C18: Bhola | D18: 0.12 | F18: SE | G18: 1.4 | H18: 0.15 | I18: 0.5 | J18: 2
C19: Bogra | D19: 0.28
C20: Brahmanbaria | D20: 0.28 | F20: Table 6.C.1: Spectral Response Acceleration Parameter SS and S1 for Different Seismic Zone
C21: Chandpur | D21: 0.2
C22: Chapainababganj | D22: 0.12
C23: Chittagong | D23: 0.28 | F23: Zone--> | G23: 1 | H23: 2 | I23: 3 | J23: 4
C24: Chuadanga | D24: 0.12 | F24: Ss | G24: 0.3 | H24: 0.5 | I24: 0.7 | J24: 0.9
C25: Comilla | D25: 0.2 | F25: S1 | G25: 0.12 | H25: 0.2 | I25: 0.28 | J25: 0.36
C26: Cox's Bazar | D26: 0.28
C27: Dhaka | D27: 0.2 | F27: Table 6.C.2: Site Coefficient (Fa) for Different Seismic Zone and Soil Type
C28: Dinajpur | D28: 0.2
C29: Faridpur | D29: 0.2 | F29: ST/Z-> | G29: 1 | H29: 2 | I29: 3 | J29: 4
C30: Feni | D30: 0.2 | F30: SA | G30: 1 | H30: 1 | I30: 1 | J30: 1
C31: Gaibandha | D31: 0.28 | F31: SB | G31: 1.2 | H31: 1.2 | I31: 1.2 | J31: 1.2
C32: Gazipur | D32: 0.2 | F32: SC | G32: 1.15 | H32: 1.15 | I32: 1.15 | J32: 1.15
C33: Gopalganj | D33: 0.12 | F33: SD | G33: 1.35 | H33: 1.35 | I33: 1.35 | J33: 1.35
C34: Habiganj | D34: 0.36 | F34: SE | G34: 1.4 | H34: 1.4 | I34: 1.4 | J34: 1.4
C35: Jaipurhat | D35: 0.2
C36: Jamalpur | D36: 0.36 | F36: Table 6.C.3: Site Coefficient for Different Seismic Zone and Soil Type
C37: Jessore | D37: 0.12
C38: Jhalokati | D38: 0.12 | F38: ST/Zone-> | G38: 1 | H38: 2 | I38: 3 | J38: 4
C39: Jhenaidah | D39: 0.12 | F39: SA | G39: 1 | H39: 1 | I39: 1 | J39: 1
C40: Khagrachari | D40: 0.28 | F40: SB | G40: 1.5 | H40: 1.5 | I40: 1.5 | J40: 1.5
C41: Khulna | D41: 0.12 | F41: SC | G41: 1.725 | H41: 1.725 | I41: 1.725 | J41: 1.725
C42: Kishoreganj | D42: 0.36 | F42: SD | G42: 2.7 | H42: 2.7 | I42: 2.7 | J42: 2.7
C43: Kurigram | D43: 0.36 | F43: SE | G43: 1.75 | H43: 1.75 | I43: 1.75 | J43: 1.75
C44: Kushtia | D44: 0.2
C45: Lakshmipur | D45: 0.2
C46: Lalmanirhat | D46: 0.28
C47: Madaripur | D47: 0.2
...

Sheet Sheet3
B1: This is the Poperty of School of civil Engineering
B2: This Channel are Manageing By SM Hedaetullah And N.J. Disha (B.Sc. In Civil Engineering)
B3: Support us And stay connected
B4: This file is only for edicational Perpose. Pls don't misuse it.
B7: Table 6.2.19: Response Reduction Factor, Deflection Amplification Factor and Height Limitations for Different Structural Systems
B8: Sturctural type | C8: Seismic Force Resisting System | D8: Response Reduction Factor, R | E8: System Overstrength Factor, | F8: Deflection Amplification Factor, | G8: Seismic Design Category (B) | H8: Seismic Design Category (C) | I8: Seismic Design Category (D)
G9: Value of Hight limit (m)
B10: BEARING_WALL_SYSTEMS_no_frame | C10: 1. Special reinforced concrete shear walls | D10: 5 | E10: 2.5 | F10: 5 | G10: NL | H10: NL | I10: 50
C11: 2. Ordinary reinforced concrete shear walls | D11: 4 | E11: 2.5 | F11: 4 | G11: NL | H11: NL | I11: NP
C12: 3. Ordinary reinforced masonry shear walls | D12: 2 | E12: 2.5 | F12: 1.75 | G12: NL | H12: 50 | I12: NP
C13: 4. Ordinary plain masonry shear walls | D13: 1.5 | E13: 2.5 | F13: 1.25 | G13: 18 | H13: NP | I13: NP
B14: BUILDING_FRAME_SYSTEMS_with_bracing_or_shear_wall | C14: 1. Steel eccentrically braced frames, moment resisting connections at columns away from links | D14: 8 | E14: 2 | F14: 4 | G14: NL | H14: NL | I14: 50
C15: 2. Steel eccentrically braced frames, non-moment-resisting, connections at columns away from links | D15: 7 | E15: 2 | F15: 4 | G15: NL | H15: NL | I15: 50
C16: 3. Special steel concentrically braced frames | D16: 6 | E16: 2 | F16: 5 | G16: NL | H16: NL | I16: 50
C17: 4. Ordinary steel concentrically braced frames | D17: 3.25 | E17: 2 | F17: 3.25 | G17: NL | H17: NL | I17: 11
C18: 5. Special reinforced concrete shear walls | D18: 6 | E18: 2.5 | F18: 5 | G18: NL | H18: 50 | I18: 50
C19: 6. Ordinary reinforced concrete shear walls | D19: 5 | E19: 2.5 | F19: 4.25 | G19: NL | H19: NL | I19: NP
C20: 7. Ordinary reinforced masonry shear walls | D20: 2 | E20: 2.5 | F20: 2 | G20: NL | H20: 50 | I20: NP
C21: 8. Ordinary plain masonry shear walls | D21: 1.5 | E21: 2.5 | F21: 1.25 | G21: 18 | H21: NP | I21: NP
B22: MOMENT_RESISTING_FRAME_SYSTEMS_no_shear_wall | C22: 1. Special steel moment frames | D22: 8 | E22: 3 | F22: 5.5 | G22: NL | H22: NL | I22: NL
C23: 2. Intermediate steel moment frames | D23: 4.5 | E23: 3 | F23: 4 | G23: NL | H23: NL | I23: 35
C24: 3. Ordinary steel moment frames | D24: 3.5 | E24: 3 | F24: 3 | G24: NL | H24: NL | I24: NP
C25: 4. Special reinforced concrete moment frames | D25: 8 | E25: 3 | F25: 5.5 | G25: NL | H25: NL | I25: NL
C26: 5. Intermediate reinforced concrete moment frames | D26: 5 | E26: 3 | F26: 4.5 | G26: NL | H26: NL | I26: NP
C27: 6. Ordinary reinforced concrete moment | D27: 3 | E27: 3 | F27: 2.5 | G27: NL | H27: NP | I27: NP
B28: DUAL_SYSTEMS_SPECIAL_MOMENT_FRAMES | C28: 1. Steel eccentrically braced frames | D28: 8 | E28: 2.5 | F28: 4 | G28: NL | H28: NL | I28: NL
C29: 2. Special steel concentrically braced frames | D29: 7 | E29: 2.5 | F29: 5.5 | G29: NL | H29: NL | I29: NL
C30: 3. Special reinforced concrete shear walls | D30: 7 | E30: 2.5 | F30: 5.5 | G30: NL | H30: NL | I30: NL
C31: 4. Ordinary reinforced concrete shear walls | D31: 6 | E31: 2.5 | F31: 5 | G31: NL | H31: NL | I31: NP
B32: DUAL_SYSTEMS_INTERMEDIATE_MOMENT_FRAMES | C32: 1. Special steel concentrically braced frames | D32: 6 | E32: 2.5 | F32: 5 | G32: NL | H32: NL | I32: 11
C33: 2. Special reinforced concrete shear walls | D33: 6.5 | E33: 2.5 | F33: 5 | G33: NL | H33: NL | I33: 50
C34: 3. Ordinary reinforced masonry shear wall | D34: 3 | E34: 3 | F34: 3 | G34: NL | H34: 50 | I34: NP
C35: 4. Ordinary reinforced concrete shear wall | D35: 5.5 | E35: 2.5 | F35: 4.5 | G35: NL | H35: NL | I35: NP
B36: DUAL_SHEAR_WALL_FRAME_SYSTEM | C36: DUAL SHEAR WALL-FRAME SYSTEM | D36: 4.5 | E36: 2.5 | F36: 4 | G36: NL | H36: NP | I36: NP
B37: STEEL_SYSTEMS_NOT_SPECIFICALLY_DETAILED | C37: STEEL SYSTEMS NOT SPECIFICALLY DETAILED | D37: 3 | E37: 3 | F37: 3 | G37: NL | H37: NL | I37: NP
B39: =B10 -> BEARING_WALL_SYSTEMS_no_frame
B40: =B14 -> BUILDING_FRAME_SYSTEMS_with_bracing_or_shear_wall
B41: =B22 -> MOMENT_RESISTING_FRAME_SYSTEMS_no_shear_wall
B42: =B28 -> DUAL_SYSTEMS_SPECIAL_MOMENT_FRAMES
B43: =B32 -> DUAL_SYSTEMS_INTERMEDIATE_MOMENT_FRAMES
...
