Workbook
Name asd: 'MWFRS (Any Ht.)'!$E$65
Name asds: 'MWFRS (Any Ht.)'!$J$54
Name B: 'MWFRS (Any Ht.)'!$O$12
Name Cp.L: 'MWFRS (Any Ht.)'!$C$57
Name Cp.S: 'MWFRS (Any Ht.)'!$C$58
Name Cp.w: 'MWFRS (Any Ht.)'!$C$56
Name f: 'Gust Factor Cal.'!$H$22
Name framesystem: [1]Sheet3!$B$39:$B$45
Name G: 'Gust Factor Cal.'!$C$7
Name G.: 'MWFRS (Any Ht.)'!$C$49
Name GCpi_N: 'MWFRS (Any Ht.)'!$O$37
Name GCpi_P: 'MWFRS (Any Ht.)'!$O$36
Name gQ: 'Gust Factor Cal.'!$H$34
Name gR: 'Gust Factor Cal.'!$H$33
Name gv: 'Gust Factor Cal.'!$H$35
Name h: 'MWFRS (Any Ht.)'!$O$14
Name I: 'MWFRS (Any Ht.)'!$O$50
Name Iz: 'Gust Factor Cal.'!$C$6
Name Kd: 'MWFRS (Any Ht.)'!$J$54
Name Kd.: 'MWFRS (Any Ht.)'!$O$51
Name Kzt: 'MWFRS (Any Ht.)'!$E$65
Name Kzt.: 'MWFRS (Any Ht.)'!$O$40
Name L: 'MWFRS (Any Ht.)'!$O$13
Name Lz: 'Gust Factor Cal.'!$C$4
Name N.1: 'Gust Factor Cal.'!$H$27
Name Ƞb: 'Gust Factor Cal.'!$M$24
Name Ƞh: 'Gust Factor Cal.'!$M$23
Name ȠL: 'Gust Factor Cal.'!$M$25
Name Q: 'Gust Factor Cal.'!$C$5
Name qi: 'MWFRS (Any Ht.)'!$O$62
Name R.: 'Gust Factor Cal.'!$H$31
Name RB: 'Gust Factor Cal.'!$H$24
Name Rh: 'Gust Factor Cal.'!$H$23
Name RL: 'Gust Factor Cal.'!$H$25
Name Rn: 'Gust Factor Cal.'!$H$29
Name V: 'MWFRS (Any Ht.)'!$O$18
Name Zg: 'MWFRS (Any Ht.)'!$O$59
Name α: 'MWFRS (Any Ht.)'!$O$58
Name β: 'MWFRS (Any Ht.)'!$C$16

Sheet Video & Instruction 
B14: qLearnify is an educational platform dedicated to the professional development of engineers and architects.
C17: Website: | E17: https://qlearnify.com/
C18: Facebook: | E18: https://www.facebook.com/qlearnify
C19: Youtube (Bangla): | E19: https://www.youtube.com/@qlearnify-bn
C20: Youtube (English): | E20: https://www.youtube.com/@qlearnify-en
C21: WhatsApp: | E21: https://wa.me/8801511250108
C22: LinkedIn: | E22: https://www.linkedin.com/company/qlearnify/
B24: Note: This Excel sheet has been created for educational purposes; please validate it according to your own standards before using it for professional work.
A34: Bangla: | B34: https://youtube.com/playlist?list=PLxle8F-wJI7P43K0GljphED4I5TRXu6Zx&si=el-Lrxm5mB1Vmgcf
A36: English: | B36: https://youtube.com/playlist?list=PLTscI_CLWNfB_1x6_7zylwLZWo7mKypCq&si=QzFh_rJa61GU0YNW

Sheet MWFRS (Any Ht.)
B4: Input Data
N5: Calculation
B6: Location= | C6: Dhaka | D6: Sec-2.4.4 & Table-6.2.8 | N6: Roof Angle, θ = | O6: =IF($C$14="Gable",DEGREES(ATAN(($C$9-$C$10)/($C$11/2))),DEGREES(ATAN(($C$9-$C$10)/($C$11)))) -> 0 | R6: N TO R | S6: P TO R
B7: Occupancy Category= | C7: II | D7: Sec-1.2.3 & Table-6.1.1 | N7: Mean Roof Ht., h = | O7: =(IF($C$23<=10,$C$10,$C$10+($C$9-$C$10)/2))/3.28 -> 33.536585 | P7: m | R7: =S11 -> 89 | S7: =R8 -> 76
B8: Exposure Type= | C8: A | D8: Sec-2.4.6 | N8: Lesser of L or B = | O8: =IF(C11<C12,C11,C12) -> 76 | P8: ft | R8: =S10 -> 76 | S8: =R7 -> 89
B9: Ridge Height, hr = | C9: 110 | D9: ft. (hr >= he)
B10: Eave Height, he = | C10: 110 | D10: ft. (he <= hr) | N10: hr= | O10: =C9/3.28 -> 33.536585 | P10: m | Q10: Normal | R10: L= | S10: =IF($C$13="Normal",$C$11,$C$12) -> 76 | T10: ft.
B11: Building Width = | C11: 89 | D11: ft. (Normal to Building Ridge-X) | N11: he= | O11: =C10/3.28 -> 33.536585 | P11: m | Q11: Parallel | R11: B= | S11: =IF($C$13="Normal",$C$12,$C$11) -> 89 | T11: ft.
B12: Building Length= | C12: 76 | D12: ft. (Parallel to Building Ridge-Y) | N12: B= | O12: =S11/3.28 -> 27.134146 | P12: m
B13: Wind Direction= | C13: Parallel | D13: (Normal or Parallel to building ridge) | N13: L= | O13: =S10/3.28 -> 23.170732 | P13: m
B14: Roof Types= | C14: Gable | N14: h= | O14: =C24/3.28 -> 33.536585 | P14: m
B15: Enclosure Classification= | C15: EB | N15: Check 'Low-Rise' Criteria:
B16: Damping Ratio, β = | C16: 0.05 | D16: (Suggested Range = 0.010-0.070) | N16: Is h <= 60'? | O16: =IF(C24<=60,"YES","NO") -> NO
B17: Structure Type= | C17: TYPE-1 | N17: Is h <= Lesser L,B? | O17: =IF($O$7<=($O$8/3.28),"Yes","No") -> No
B18: Structure Frame type= | C18: CMRF | D18: (Sect. 2.4.7 & Figure 6.2.4) | N18: V= | O18: ='Gust Factor Cal.'!H16 -> 65.7 | P18: m/s
B19: Topo. Factor, Kzt = | C19: 1
N20: Structure type | O20: =C18 -> CMRF
B21: Parameters and Coefficients Calculation: | N21: Ct= | O21: =VLOOKUP(O20,'BNBC 20 Data'!N7:P10,2,FALSE) -> 0.0466
N22: m= | O22: =VLOOKUP(O20,'BNBC 20 Data'!N7:P10,3,FALSE) -> 0.9
B23: Roof Angle, θ = | C23: =O6 -> 0 | D23: deg | N23: T= | O23: =O21*(O14^O22) -> 1.0998992 | P23: Sec.
B24: Mean Roof Ht., h = | C24: =O7*3.28 -> 110 | D24: =IF($C$23<=10,"ft. (h = he, for angle <=10 deg.)","ft. (h = he+(hr+he)/2, for angle >10 deg.)") -> ft. (h = he, for angle <=10 deg.) | N24: n1/f= | O24: =1/O23 -> 0.90917425 | P24: Hz
B26: Check Criteria for a Low-Rise Building: | N26: Is Building Flexible? | O26: =IF($O$24<1,"Yes","No") -> Yes
B27: 1. Is h <= 60' ? | C27: =IF($O$16="Yes","Yes, O.K.","No, Violation!") -> No, Violation!
B28: 2. Is h <= Lesser of L or B? | C28: =IF($O$17="Yes","Yes, O.K.","No, Violation!") -> No, Violation!
N29: Velocity Pressure Exposure Coefficients | R29: A_Case1 | S29: 2 | T29: A | U29: =IF(O16="YES",R29,R30) -> A_Case2 | V29: =IF(C8="A",U29,C8) -> A_Case2
B30: Structure Conditions: | R30: A_Case2 | S30: 3 | T30: B | U30: B
N31: Case No= | O31: =VLOOKUP(C8,T29:U31,2,FALSE) -> A_Case2 | P31: =VLOOKUP(O31,R29:S32,2,FALSE) -> 3 | R31: B | S31: 4 | T31: C | U31: C
B32: T= | C32: =O23 -> 1.0998992 | D32: = Ct*h^m , sec. (Approximate fundamental period) | R32: C | S32: 5
B33: f= | C33: =O24 -> 0.90917425 | D33: = 1/T , Hz. (Natural Frequency)
N34: Positive & Negative Internal Pressure Coefficients, GCpi
B35: Is Building Flexible? | C35: =IF(O26="No","No, Rigid","Yes") -> Yes | D35: =IF($O$24>=1,"f >=1 Hz.","f < 1 Hz.") -> f < 1 Hz. | N35: GCpi= | O35: =VLOOKUP(C15,'BNBC 20 Data'!F27:G29,2,FALSE) -> 0.18
N36: + GCpi (PIPC) | O36: =O35 -> 0.18
B37: Velocity Pressure Exposure Coefficients, Kh and Kz: | N37: - GCpi (PIPC) | O37: =-O36 -> -0.18
B39: Kh= | C39: ='Kh and Kz Cal.'!L8 -> 0.99 | D39: Sec-2.4.6.6 & Table-6.2.11
N40: Topo. Factor, Kzt = | O40: =C19 -> 1
B41: Directionality Factor, Kd:
B43: Kd= | C43: =O51 -> 0.85 | D43: Sec-2.4.6.6 & Table-6.2.11
N44: Wall Pressure Coefficients, Cp
B45: Gust Factor, G or Gf: | N45: h/L= | O45: =O7/L -> 1.4473684
N46: L/B= | O46: =L/B -> 0.85393258
...

Sheet e1 & e2 ratio Cal.
B3: Data From Etabs | G3: Output Data For Etabs | K3: Rigid | N3: N TO R | O3: P TO R
B4: 1 | C4: XCM | D4: YCM | E4: XCR | F4: YCR | G4: eR1 | H4: eR2 | I4: e1 | J4: e2 | K4: ex/Bx | L4: ey/By | N4: ='MWFRS (Any Ht.)'!R7/3.28 -> 27.134146 | O4: =N5 -> 23.170732
B5: 2 | C5: m | D5: m | E5: m | F5: m | M5: ='MWFRS (Any Ht.)'!C13 -> Parallel | N5: ='MWFRS (Any Ht.)'!R8/3.28 -> 23.170732 | O5: =N4 -> 27.134146
B6: 3 | C6: 5.461 | D6: 9.7615 | E6: 5.3787 | F6: 10.2195 | G6: =(IF(C6="","",ABS(E6-C6))) -> 0.0823 | H6: =IF(D6="","",ABS(F6-D6)) -> 0.458 | I6: =IF(G6="","",(((0.15+(1.7*Iz*(SQRT(((3.4*Q*0.15)^2)+(gR*R.*'e1 & e2 ratio Cal.'!G6)^2)))))/((1+(1.7*Iz*(SQRT(((3.4*Q)^2)+(gR*R.)^2))))))) -> 0.14734696 | J6: =IF(H6="","",(((0.15+(1.7*Iz*(SQRT(((3.4*Q*0.15)^2)+(gR*R.*'e1 & e2 ratio Cal.'!H6)^2)))))/((1+(1.7*Iz*(SQRT(((3.4*Q)^2)+(gR*R.)^2))))))) -> 0.17691882 | K6: =IF(C6="","",IF($M$5="Normal",(G6/$N$4),(G6/$O$4))) -> 0.0035518947 | L6: =IF(D6="","",IF($M$5="Normal",(H6/$N$5),(H6/$O$5))) -> 0.016879101
B7: 4 | C7: 5.478 | D7: 5.5817 | E7: 5.4829 | F7: 8.9978 | G7: =(IF(C7="","",ABS(E7-C7))) -> 0.0049 | H7: =IF(D7="","",ABS(F7-D7)) -> 3.4161 | I7: =IF(G7="","",(((0.15+(1.7*Iz*(SQRT(((3.4*Q*0.15)^2)+(gR*R.*'e1 & e2 ratio Cal.'!G7)^2)))))/((1+(1.7*Iz*(SQRT(((3.4*Q)^2)+(gR*R.)^2))))))) -> 0.14618228 | J7: =IF(H7="","",(((0.15+(1.7*Iz*(SQRT(((3.4*Q*0.15)^2)+(gR*R.*'e1 & e2 ratio Cal.'!H7)^2)))))/((1+(1.7*Iz*(SQRT(((3.4*Q)^2)+(gR*R.)^2))))))) -> 0.64851839 | K7: =IF(C7="","",IF($M$5="Normal",(G7/$N$4),(G7/$O$4))) -> 0.00021147368 | L7: =IF(D7="","",IF($M$5="Normal",(H7/$N$5),(H7/$O$5))) -> 0.12589672
B8: 5 | C8: 5.431 | D8: 5.5344 | E8: 5.4748 | F8: 9.2175 | G8: =(IF(C8="","",ABS(E8-C8))) -> 0.0438 | H8: =IF(D8="","",ABS(F8-D8)) -> 3.6831 | I8: =IF(G8="","",(((0.15+(1.7*Iz*(SQRT(((3.4*Q*0.15)^2)+(gR*R.*'e1 & e2 ratio Cal.'!G8)^2)))))/((1+(1.7*Iz*(SQRT(((3.4*Q)^2)+(gR*R.)^2))))))) -> 0.14651084 | J8: =IF(H8="","",(((0.15+(1.7*Iz*(SQRT(((3.4*Q*0.15)^2)+(gR*R.*'e1 & e2 ratio Cal.'!H8)^2)))))/((1+(1.7*Iz*(SQRT(((3.4*Q)^2)+(gR*R.)^2))))))) -> 0.69336341 | K8: =IF(C8="","",IF($M$5="Normal",(G8/$N$4),(G8/$O$4))) -> 0.0018903158 | L8: =IF(D8="","",IF($M$5="Normal",(H8/$N$5),(H8/$O$5))) -> 0.13573672
B9: 6 | C9: 5.431 | D9: 5.5344 | E9: 5.4712 | F9: 9.4348 | G9: =(IF(C9="","",ABS(E9-C9))) -> 0.0402 | H9: =IF(D9="","",ABS(F9-D9)) -> 3.9004 | I9: =IF(G9="","",(((0.15+(1.7*Iz*(SQRT(((3.4*Q*0.15)^2)+(gR*R.*'e1 & e2 ratio Cal.'!G9)^2)))))/((1+(1.7*Iz*(SQRT(((3.4*Q)^2)+(gR*R.)^2))))))) -> 0.14645848 | J9: =IF(H9="","",(((0.15+(1.7*Iz*(SQRT(((3.4*Q*0.15)^2)+(gR*R.*'e1 & e2 ratio Cal.'!H9)^2)))))/((1+(1.7*Iz*(SQRT(((3.4*Q)^2)+(gR*R.)^2))))))) -> 0.729903 | K9: =IF(C9="","",IF($M$5="Normal",(G9/$N$4),(G9/$O$4))) -> 0.0017349474 | L9: =IF(D9="","",IF($M$5="Normal",(H9/$N$5),(H9/$O$5))) -> 0.14374508
B10: 7 | C10: 5.431 | D10: 5.5344 | E10: 5.4843 | F10: 9.514 | G10: =(IF(C10="","",ABS(E10-C10))) -> 0.0533 | H10: =IF(D10="","",ABS(F10-D10)) -> 3.9796 | I10: =IF(G10="","",(((0.15+(1.7*Iz*(SQRT(((3.4*Q*0.15)^2)+(gR*R.*'e1 & e2 ratio Cal.'!G10)^2)))))/((1+(1.7*Iz*(SQRT(((3.4*Q)^2)+(gR*R.)^2))))))) -> 0.14667036 | J10: =IF(H10="","",(((0.15+(1.7*Iz*(SQRT(((3.4*Q*0.15)^2)+(gR*R.*'e1 & e2 ratio Cal.'!H10)^2)))))/((1+(1.7*Iz*(SQRT(((3.4*Q)^2)+(gR*R.)^2))))))) -> 0.74322879 | K10: =IF(C10="","",IF($M$5="Normal",(G10/$N$4),(G10/$O$4))) -> 0.0023003158 | L10: =IF(D10="","",IF($M$5="Normal",(H10/$N$5),(H10/$O$5))) -> 0.14666391
B11: 8 | C11: 5.431 | D11: 5.5344 | E11: 5.5075 | F11: 9.1773 | G11: =(IF(C11="","",ABS(E11-C11))) -> 0.0765 | H11: =IF(D11="","",ABS(F11-D11)) -> 3.6429 | I11: =IF(G11="","",(((0.15+(1.7*Iz*(SQRT(((3.4*Q*0.15)^2)+(gR*R.*'e1 & e2 ratio Cal.'!G11)^2)))))/((1+(1.7*Iz*(SQRT(((3.4*Q)^2)+(gR*R.)^2))))))) -> 0.14718898 | J11: =IF(H11="","",(((0.15+(1.7*Iz*(SQRT(((3.4*Q*0.15)^2)+(gR*R.*'e1 & e2 ratio Cal.'!H11)^2)))))/((1+(1.7*Iz*(SQRT(((3.4*Q)^2)+(gR*R.)^2))))))) -> 0.68660756 | K11: =IF(C11="","",IF($M$5="Normal",(G11/$N$4),(G11/$O$4))) -> 0.0033015789 | L11: =IF(D11="","",IF($M$5="Normal",(H11/$N$5),(H11/$O$5))) -> 0.13425519 | O11: ='MWFRS (Any Ht.)'!C33 -> 0.90917425 | P11: Final Value (Flx)
B12: 9 | C12: 5.3218 | D12: 5.8101 | E12: 5.4259 | F12: 6.9971 | G12: =(IF(C12="","",ABS(E12-C12))) -> 0.1041 | H12: =IF(D12="","",ABS(F12-D12)) -> 1.187 | I12: =IF(G12="","",(((0.15+(1.7*Iz*(SQRT(((3.4*Q*0.15)^2)+(gR*R.*'e1 & e2 ratio Cal.'!G12)^2)))))/((1+(1.7*Iz*(SQRT(((3.4*Q)^2)+(gR*R.)^2))))))) -> 0.14804044 | J12: =IF(H12="","",(((0.15+(1.7*Iz*(SQRT(((3.4*Q*0.15)^2)+(gR*R.*'e1 & e2 ratio Cal.'!H12)^2)))))/((1+(1.7*Iz*(SQRT(((3.4*Q)^2)+(gR*R.)^2))))))) -> 0.28105277 | K12: =IF(C12="","",IF($M$5="Normal",(G12/$N$4),(G12/$O$4))) -> 0.0044927368 | L12: =IF(D12="","",IF($M$5="Normal",(H12/$N$5),(H12/$O$5))) -> 0.043745618 | N12: Final Value | P12: e1= | Q12: =MAX(I6:I78) -> 0.14818824
B13: 10 | C13: 5.3107 | D13: 8.1979 | E13: 5.4189 | F13: 9.1649 | G13: =(IF(C13="","",ABS(E13-C13))) -> 0.1082 | H13: =IF(D13="","",ABS(F13-D13)) -> 0.967 | I13: =IF(G13="","",(((0.15+(1.7*Iz*(SQRT(((3.4*Q*0.15)^2)+(gR*R.*'e1 & e2 ratio Cal.'!G13)^2)))))/((1+(1.7*Iz*(SQRT(((3.4*Q)^2)+(gR*R.)^2))))))) -> 0.14818824 | J13: =IF(H13="","",(((0.15+(1.7*Iz*(SQRT(((3.4*Q*0.15)^2)+(gR*R.*'e1 & e2 ratio Cal.'!H13)^2)))))/((1+(1.7*Iz*(SQRT(((3.4*Q)^2)+(gR*R.)^2))))))) -> 0.24710153 | K13: =IF(C13="","",IF($M$5="Normal",(G13/$N$4),(G13/$O$4))) -> 0.0046696842 | L13: =IF(D13="","",IF($M$5="Normal",(H13/$N$5),(H13/$O$5))) -> 0.035637753 | N13: e1= | O13: =IF($O$11>=1,Q15,Q12) -> 0.14818824 | P13: e2= | Q13: =MAX(J6:J78) -> 0.74322879
B14: 11 | G14: =(IF(C14="","",ABS(E14-C14))) | H14: =IF(D14="","",ABS(F14-D14)) | I14: =IF(G14="","",(((0.15+(1.7*Iz*(SQRT(((3.4*Q*0.15)^2)+(gR*R.*'e1 & e2 ratio Cal.'!G14)^2)))))/((1+(1.7*Iz*(SQRT(((3.4*Q)^2)+(gR*R.)^2))))))) | J14: =IF(H14="","",(((0.15+(1.7*Iz*(SQRT(((3.4*Q*0.15)^2)+(gR*R.*'e1 & e2 ratio Cal.'!H14)^2)))))/((1+(1.7*Iz*(SQRT(((3.4*Q)^2)+(gR*R.)^2))))))) | K14: =IF(C14="","",IF($M$5="Normal",(G14/$N$4),(G14/$O$4))) | L14: =IF(D14="","",IF($M$5="Normal",(H14/$N$5),(H14/$O$5))) | N14: e2= | O14: =IF($O$11>=1,Q16,Q13) -> 0.74322879 | P14: Final Value (Rgd)
B15: 12 | G15: =(IF(C15="","",ABS(E15-C15))) | H15: =IF(D15="","",ABS(F15-D15)) | I15: =IF(G15="","",(((0.15+(1.7*Iz*(SQRT(((3.4*Q*0.15)^2)+(gR*R.*'e1 & e2 ratio Cal.'!G15)^2)))))/((1+(1.7*Iz*(SQRT(((3.4*Q)^2)+(gR*R.)^2))))))) | J15: =IF(H15="","",(((0.15+(1.7*Iz*(SQRT(((3.4*Q*0.15)^2)+(gR*R.*'e1 & e2 ratio Cal.'!H15)^2)))))/((1+(1.7*Iz*(SQRT(((3.4*Q)^2)+(gR*R.)^2))))))) | K15: =IF(C15="","",IF($M$5="Normal",(G15/$N$4),(G15/$O$4))) | L15: =IF(D15="","",IF($M$5="Normal",(H15/$N$5),(H15/$O$5))) | P15: e1= | Q15: =MAX(K6:K78) -> 0.0046696842
B16: 13 | G16: =(IF(C16="","",ABS(E16-C16))) | H16: =IF(D16="","",ABS(F16-D16)) | I16: =IF(G16="","",(((0.15+(1.7*Iz*(SQRT(((3.4*Q*0.15)^2)+(gR*R.*'e1 & e2 ratio Cal.'!G16)^2)))))/((1+(1.7*Iz*(SQRT(((3.4*Q)^2)+(gR*R.)^2))))))) | J16: =IF(H16="","",(((0.15+(1.7*Iz*(SQRT(((3.4*Q*0.15)^2)+(gR*R.*'e1 & e2 ratio Cal.'!H16)^2)))))/((1+(1.7*Iz*(SQRT(((3.4*Q)^2)+(gR*R.)^2))))))) | K16: =IF(C16="","",IF($M$5="Normal",(G16/$N$4),(G16/$O$4))) | L16: =IF(D16="","",IF($M$5="Normal",(H16/$N$5),(H16/$O$5))) | P16: e2= | Q16: =MAX(L6:L78) -> 0.14666391
B17: 14 | G17: =(IF(C17="","",ABS(E17-C17))) | H17: =IF(D17="","",ABS(F17-D17)) | I17: =IF(G17="","",(((0.15+(1.7*Iz*(SQRT(((3.4*Q*0.15)^2)+(gR*R.*'e1 & e2 ratio Cal.'!G17)^2)))))/((1+(1.7*Iz*(SQRT(((3.4*Q)^2)+(gR*R.)^2))))))) | J17: =IF(H17="","",(((0.15+(1.7*Iz*(SQRT(((3.4*Q*0.15)^2)+(gR*R.*'e1 & e2 ratio Cal.'!H17)^2)))))/((1+(1.7*Iz*(SQRT(((3.4*Q)^2)+(gR*R.)^2))))))) | K17: =IF(C17="","",IF($M$5="Normal",(G17/$N$4),(G17/$O$4))) | L17: =IF(D17="","",IF($M$5="Normal",(H17/$N$5),(H17/$O$5)))
B18: 15 | G18: =(IF(C18="","",ABS(E18-C18))) | H18: =IF(D18="","",ABS(F18-D18)) | I18: =IF(G18="","",(((0.15+(1.7*Iz*(SQRT(((3.4*Q*0.15)^2)+(gR*R.*'e1 & e2 ratio Cal.'!G18)^2)))))/((1+(1.7*Iz*(SQRT(((3.4*Q)^2)+(gR*R.)^2))))))) | J18: =IF(H18="","",(((0.15+(1.7*Iz*(SQRT(((3.4*Q*0.15)^2)+(gR*R.*'e1 & e2 ratio Cal.'!H18)^2)))))/((1+(1.7*Iz*(SQRT(((3.4*Q)^2)+(gR*R.)^2))))))) | K18: =IF(C18="","",IF($M$5="Normal",(G18/$N$4),(G18/$O$4))) | L18: =IF(D18="","",IF($M$5="Normal",(H18/$N$5),(H18/$O$5)))
B19: 16 | G19: =(IF(C19="","",ABS(E19-C19))) | H19: =IF(D19="","",ABS(F19-D19)) | I19: =IF(G19="","",(((0.15+(1.7*Iz*(SQRT(((3.4*Q*0.15)^2)+(gR*R.*'e1 & e2 ratio Cal.'!G19)^2)))))/((1+(1.7*Iz*(SQRT(((3.4*Q)^2)+(gR*R.)^2))))))) | J19: =IF(H19="","",(((0.15+(1.7*Iz*(SQRT(((3.4*Q*0.15)^2)+(gR*R.*'e1 & e2 ratio Cal.'!H19)^2)))))/((1+(1.7*Iz*(SQRT(((3.4*Q)^2)+(gR*R.)^2))))))) | K19: =IF(C19="","",IF($M$5="Normal",(G19/$N$4),(G19/$O$4))) | L19: =IF(D19="","",IF($M$5="Normal",(H19/$N$5),(H19/$O$5)))
B20: 17 | G20: =(IF(C20="","",ABS(E20-C20))) | H20: =IF(D20="","",ABS(F20-D20)) | I20: =IF(G20="","",(((0.15+(1.7*Iz*(SQRT(((3.4*Q*0.15)^2)+(gR*R.*'e1 & e2 ratio Cal.'!G20)^2)))))/((1+(1.7*Iz*(SQRT(((3.4*Q)^2)+(gR*R.)^2))))))) | J20: =IF(H20="","",(((0.15+(1.7*Iz*(SQRT(((3.4*Q*0.15)^2)+(gR*R.*'e1 & e2 ratio Cal.'!H20)^2)))))/((1+(1.7*Iz*(SQRT(((3.4*Q)^2)+(gR*R.)^2))))))) | K20: =IF(C20="","",IF($M$5="Normal",(G20/$N$4),(G20/$O$4))) | L20: =IF(D20="","",IF($M$5="Normal",(H20/$N$5),(H20/$O$5)))
B21: 18 | G21: =(IF(C21="","",ABS(E21-C21))) | H21: =IF(D21="","",ABS(F21-D21)) | I21: =IF(G21="","",(((0.15+(1.7*Iz*(SQRT(((3.4*Q*0.15)^2)+(gR*R.*'e1 & e2 ratio Cal.'!G21)^2)))))/((1+(1.7*Iz*(SQRT(((3.4*Q)^2)+(gR*R.)^2))))))) | J21: =IF(H21="","",(((0.15+(1.7*Iz*(SQRT(((3.4*Q*0.15)^2)+(gR*R.*'e1 & e2 ratio Cal.'!H21)^2)))))/((1+(1.7*Iz*(SQRT(((3.4*Q)^2)+(gR*R.)^2))))))) | K21: =IF(C21="","",IF($M$5="Normal",(G21/$N$4),(G21/$O$4))) | L21: =IF(D21="","",IF($M$5="Normal",(H21/$N$5),(H21/$O$5)))
B22: 19 | G22: =(IF(C22="","",ABS(E22-C22))) | H22: =IF(D22="","",ABS(F22-D22)) | I22: =IF(G22="","",(((0.15+(1.7*Iz*(SQRT(((3.4*Q*0.15)^2)+(gR*R.*'e1 & e2 ratio Cal.'!G22)^2)))))/((1+(1.7*Iz*(SQRT(((3.4*Q)^2)+(gR*R.)^2))))))) | J22: =IF(H22="","",(((0.15+(1.7*Iz*(SQRT(((3.4*Q*0.15)^2)+(gR*R.*'e1 & e2 ratio Cal.'!H22)^2)))))/((1+(1.7*Iz*(SQRT(((3.4*Q)^2)+(gR*R.)^2))))))) | K22: =IF(C22="","",IF($M$5="Normal",(G22/$N$4),(G22/$O$4))) | L22: =IF(D22="","",IF($M$5="Normal",(H22/$N$5),(H22/$O$5)))
B23: 20 | G23: =(IF(C23="","",ABS(E23-C23))) | H23: =IF(D23="","",ABS(F23-D23)) | I23: =IF(G23="","",(((0.15+(1.7*Iz*(SQRT(((3.4*Q*0.15)^2)+(gR*R.*'e1 & e2 ratio Cal.'!G23)^2)))))/((1+(1.7*Iz*(SQRT(((3.4*Q)^2)+(gR*R.)^2))))))) | J23: =IF(H23="","",(((0.15+(1.7*Iz*(SQRT(((3.4*Q*0.15)^2)+(gR*R.*'e1 & e2 ratio Cal.'!H23)^2)))))/((1+(1.7*Iz*(SQRT(((3.4*Q)^2)+(gR*R.)^2))))))) | K23: =IF(C23="","",IF($M$5="Normal",(G23/$N$4),(G23/$O$4))) | L23: =IF(D23="","",IF($M$5="Normal",(H23/$N$5),(H23/$O$5)))
B24: 21 | G24: =(IF(C24="","",ABS(E24-C24))) | H24: =IF(D24="","",ABS(F24-D24)) | I24: =IF(G24="","",(((0.15+(1.7*Iz*(SQRT(((3.4*Q*0.15)^2)+(gR*R.*'e1 & e2 ratio Cal.'!G24)^2)))))/((1+(1.7*Iz*(SQRT(((3.4*Q)^2)+(gR*R.)^2))))))) | J24: =IF(H24="","",(((0.15+(1.7*Iz*(SQRT(((3.4*Q*0.15)^2)+(gR*R.*'e1 & e2 ratio Cal.'!H24)^2)))))/((1+(1.7*Iz*(SQRT(((3.4*Q)^2)+(gR*R.)^2))))))) | K24: =IF(C24="","",IF($M$5="Normal",(G24/$N$4),(G24/$O$4))) | L24: =IF(D24="","",IF($M$5="Normal",(H24/$N$5),(H24/$O$5)))
B25: 22 | G25: =(IF(C25="","",ABS(E25-C25))) | H25: =IF(D25="","",ABS(F25-D25)) | I25: =IF(G25="","",(((0.15+(1.7*Iz*(SQRT(((3.4*Q*0.15)^2)+(gR*R.*'e1 & e2 ratio Cal.'!G25)^2)))))/((1+(1.7*Iz*(SQRT(((3.4*Q)^2)+(gR*R.)^2))))))) | J25: =IF(H25="","",(((0.15+(1.7*Iz*(SQRT(((3.4*Q*0.15)^2)+(gR*R.*'e1 & e2 ratio Cal.'!H25)^2)))))/((1+(1.7*Iz*(SQRT(((3.4*Q)^2)+(gR*R.)^2))))))) | K25: =IF(C25="","",IF($M$5="Normal",(G25/$N$4),(G25/$O$4))) | L25: =IF(D25="","",IF($M$5="Normal",(H25/$N$5),(H25/$O$5)))
B26: 23 | G26: =(IF(C26="","",ABS(E26-C26))) | H26: =IF(D26="","",ABS(F26-D26)) | I26: =IF(G26="","",(((0.15+(1.7*Iz*(SQRT(((3.4*Q*0.15)^2)+(gR*R.*'e1 & e2 ratio Cal.'!G26)^2)))))/((1+(1.7*Iz*(SQRT(((3.4*Q)^2)+(gR*R.)^2))))))) | J26: =IF(H26="","",(((0.15+(1.7*Iz*(SQRT(((3.4*Q*0.15)^2)+(gR*R.*'e1 & e2 ratio Cal.'!H26)^2)))))/((1+(1.7*Iz*(SQRT(((3.4*Q)^2)+(gR*R.)^2))))))) | K26: =IF(C26="","",IF($M$5="Normal",(G26/$N$4),(G26/$O$4))) | L26: =IF(D26="","",IF($M$5="Normal",(H26/$N$5),(H26/$O$5)))
B27: 24 | G27: =(IF(C27="","",ABS(E27-C27))) | H27: =IF(D27="","",ABS(F27-D27)) | I27: =IF(G27="","",(((0.15+(1.7*Iz*(SQRT(((3.4*Q*0.15)^2)+(gR*R.*'e1 & e2 ratio Cal.'!G27)^2)))))/((1+(1.7*Iz*(SQRT(((3.4*Q)^2)+(gR*R.)^2))))))) | J27: =IF(H27="","",(((0.15+(1.7*Iz*(SQRT(((3.4*Q*0.15)^2)+(gR*R.*'e1 & e2 ratio Cal.'!H27)^2)))))/((1+(1.7*Iz*(SQRT(((3.4*Q)^2)+(gR*R.)^2))))))) | K27: =IF(C27="","",IF($M$5="Normal",(G27/$N$4),(G27/$O$4))) | L27: =IF(D27="","",IF($M$5="Normal",(H27/$N$5),(H27/$O$5)))
B28: 25 | G28: =(IF(C28="","",ABS(E28-C28))) | H28: =IF(D28="","",ABS(F28-D28)) | I28: =IF(G28="","",(((0.15+(1.7*Iz*(SQRT(((3.4*Q*0.15)^2)+(gR*R.*'e1 & e2 ratio Cal.'!G28)^2)))))/((1+(1.7*Iz*(SQRT(((3.4*Q)^2)+(gR*R.)^2))))))) | J28: =IF(H28="","",(((0.15+(1.7*Iz*(SQRT(((3.4*Q*0.15)^2)+(gR*R.*'e1 & e2 ratio Cal.'!H28)^2)))))/((1+(1.7*Iz*(SQRT(((3.4*Q)^2)+(gR*R.)^2))))))) | K28: =IF(C28="","",IF($M$5="Normal",(G28/$N$4),(G28/$O$4))) | L28: =IF(D28="","",IF($M$5="Normal",(H28/$N$5),(H28/$O$5)))
... B78: 75 | G78: =(IF(C78="","",ABS(E78-C78))) | H78: =IF(D78="","",ABS(F78-D78)) | I78: =IF(G78="","",(((0.15+(1.7*Iz*(SQRT(((3.4*Q*0.15)^2)+(gR*R.*'e1 & e2 ratio Cal.'!G78)^2)))))/((1+(1.7*Iz*(SQRT(((3.4*Q)^2)+(gR*R.)^2))))))) | J78: =IF(H78="","",(((0.15+(1.7*Iz*(SQRT(((3.4*Q*0.15)^2)+(gR*R.*'e1 & e2 ratio Cal.'!H78)^2)))))/((1+(1.7*Iz*(SQRT(((3.4*Q)^2)+(gR*R.)^2))))))) | K78: =IF(C78="","",IF($M$5="Normal",(G78/$N$4),(G78/$O$4))) | L78: =IF(D78="","",IF($M$5="Normal",(H78/$N$5),(H78/$O$5)))

Sheet Software Input
B1: This is the Poperty of School of civil Engineering
B2: This Channel are Manageing By Engr Hedaetullah And N.J. Disha (B.Sc. In Civil Engineering)
B3: Support us And stay connected
B4: This file is only for edicational Perpose. Pls don't misuse it.
B6: Required Data For Etbas Input
B7: For BNBC 2020, ASCE 7-05, ASCE 7-10
B8: Basic Wind Speed (mph) | E8: ='MWFRS (Any Ht.)'!O18*2.23694 -> 146.96696
B9: Importance Factor (I) | E9: =IF(E8<=(44*2.23694),VLOOKUP('MWFRS (Any Ht.)'!C7,'BNBC 20 Data'!E7:F10,2,FALSE),VLOOKUP('MWFRS (Any Ht.)'!C7,'BNBC 20 Data'!E7:G10,3,FALSE)) -> 1
B10: Directionality Factor (Kd) | E10: ='MWFRS (Any Ht.)'!O51 -> 0.85
B11: Exposure type | E11: ='MWFRS (Any Ht.)'!C8 -> A
B12: Topographical Factor (Kzt) | E12: ='MWFRS (Any Ht.)'!O40 -> 1
B13: Gust Factor | E13: ='MWFRS (Any Ht.)'!O53 -> 0.85942026
B14: e1 | E14: ='e1 & e2 ratio Cal.'!$O$13 -> 0.14818824
B15: e2 | E15: ='e1 & e2 ratio Cal.'!$O$14 -> 0.74322879
B16: Windward- (Cp) | E16: ='MWFRS (Any Ht.)'!O47 -> 0.8
B17: LeeWard- (Cp) | E17: =-'MWFRS (Any Ht.)'!O48 -> 0.5

Sheet BNBC 20 Data
B4: Table 6.2.8: Basic Wind Speeds, V, for Selected Locations in Bangladesh | E4: Table 6.2.9: Importance Factor, I (Wind Loads)
B6: Location | C6: Basic Wind Speed (m/s) | E6: Occupancy Category | F6: Cyclone Prone Regions with V = 38-44 m/s | G6: Cyclone Prone Regions with V > 44 m/s | I6: Structure Type | K6: Directionality Factor Kd | M6: Structure type | O6: Ct | P6: m
B7: Angarpota | C7: 47.8 | E7: I | F7: 0.87 | G7: 0.77 | I7: Buildings-Main Wind Force Resisting System | J7: TYPE-1 | K7: 0.85 | M7: Concrete moment-resisting frames | N7: CMRF | O7: 0.0466 | P7: 0.9
B8: Bagerhat | C8: 77.5 | E8: II | F8: 1 | G8: 1 | I8: Buildings-Components and Cladding | J8: TYPE-2 | K8: 0.85 | M8: Steel moment-resisting frames | N8: SMRF | O8: 0.0724 | P8: 0.8
B9: Bandarban | C9: 62.5 | E9: III | F9: 1.15 | G9: 1.15 | I9: Arched Roofs | J9: TYPE-3 | K9: 0.85 | M9: Eccentrically braced steel frame | N9: EBSF | O9: 0.0731 | P9: 0.75
B10: Barguna | C10: 80 | E10: IV | F10: 1.15 | G10: 1.15 | I10: Chimneys, Tanks, and Similar Structures-Square | J10: TYPE-4 | K10: 0.9 | M10: All other structural systems | N10: AOSS | O10: 0.0488 | P10: 0.75
B11: Barisal | C11: 78.7 | I11: Chimneys, Tanks, and Similar Structures-Hexagonal | J11: TYPE-5 | K11: 0.95
B12: Bhola | C12: 69.5 | I12: Chimneys, Tanks, and Similar Structures-Round | J12: TYPE-6 | K12: 0.95
B13: Bogra | C13: 61.9 | I13: Open Signs and Lattice Framework | J13: TYPE-7 | K13: 0.85
B14: Brahmanbaria | C14: 56.7 | I14: Trussed Towers-Triangular, square, rectangular | J14: TYPE-8 | K14: 0.85 | M14: Velocity Pressure Exposure Coefficients, Kh and Kz
B15: Chandpur | C15: 50.6 | I15: Trussed Towers-All other cross section | J15: TYPE-9 | K15: 0.95 | M15: Height above ground level, z (m) | N15: A | P15: B | Q15: C
B16: Chapai Nawabganj | C16: 41.4 | E16: Roof Types | N16: Case 1 | O16: Case 2 | P16: Case 1 & 2 | Q16: Case 1 & 2
B17: Chittagong | C17: 80 | E17: Gable | M17: 4.6 | N17: 0.7 | O17: 0.57 | P17: 0.85 | Q17: 1.03
B18: Chuadanga | C18: 61.9 | E18: Monoslope | M18: 6.1 | N18: 0.7 | O18: 0.62 | P18: 0.9 | Q18: 1.08
B19: Comilla | C19: 61.4 | M19: 7.6 | N19: 0.7 | O19: 0.66 | P19: 0.94 | Q19: 1.12
B20: Cox’s Bazar | C20: 80 | E20: Yes | M20: 9.1 | N20: 0.7 | O20: 0.7 | P20: 0.98 | Q20: 1.16
B21: Dahagram | C21: 47.8 | E21: No | M21: 12.2 | N21: 0.76 | O21: 0.76 | P21: 1.04 | Q21: 1.22
B22: Dhaka | C22: 65.7 | M22: 15.2 | N22: 0.81 | O22: 0.81 | P22: 1.09 | Q22: 1.27
B23: Dinajpur | C23: 41.4 | M23: 18 | N23: 0.85 | O23: 0.85 | P23: 1.13 | Q23: 1.31
B24: Faridpur | C24: 63.1 | E24: Figure 6.2.5 Internal pressure coefficient, GCpi main wind force resisting system component and cladding - Method 2 (All Heights) | M24: 21.3 | N24: 0.89 | O24: 0.89 | P24: 1.17 | Q24: 1.34
B25: Feni | C25: 64.1 | M25: 24.4 | N25: 0.93 | O25: 0.93 | P25: 1.21 | Q25: 1.38
B26: Gaibandha | C26: 65.6 | E26: Enclosure Classification | G26: GCpi | M26: 27.41 | N26: 0.96 | O26: 0.96 | P26: 1.24 | Q26: 1.4
B27: Gazipur | C27: 66.5 | E27: Open Building | F27: OB | G27: 0 | M27: 30.5 | N27: 0.99 | O27: 0.99 | P27: 1.26 | Q27: 1.43
B28: Gopalganj | C28: 74.5 | E28: Partially Enclosed Building | F28: PEB | G28: 0.55 | M28: 36.6 | N28: 1.04 | O28: 1.04 | P28: 1.31 | Q28: 1.48
B29: Habiganj | C29: 54.2 | E29: Enclosed Building | F29: EB | G29: 0.18 | M29: 42.7 | N29: 1.09 | O29: 1.09 | P29: 1.36 | Q29: 1.52
B30: Hatiya | C30: 80 | M30: 48.8 | N30: 1.13 | O30: 1.13 | P30: 1.39 | Q30: 1.55
B31: Ishurdi | C31: 69.5 | M31: 54.9 | N31: 1.17 | O31: 1.17 | P31: 1.43 | Q31: 1.58
B32: Joypurhat | C32: 56.7 | M32: 61 | N32: 1.2 | O32: 1.2 | P32: 1.46 | Q32: 1.61
B33: Jamalpur | C33: 56.7 | M33: 76.2 | N33: 1.28 | O33: 1.28 | P33: 1.53 | Q33: 1.68
B34: Jessore | C34: 64.1 | M34: 91.4 | N34: 1.35 | O34: 1.35 | P34: 1.59 | Q34: 1.73
B35: Jhalakati | C35: 80 | M35: 106.7 | N35: 1.41 | O35: 1.41 | P35: 1.64 | Q35: 1.78
B36: Jhenaidah | C36: 65 | E36: Figure-6.2.6 Wall Pressure Coefficients, Cp | M36: 121.9 | N36: 1.47 | O36: 1.47 | P36: 1.69 | Q36: 1.82
B37: Khagrachhari | C37: 56.7 | E37: Surface | F37: L/B | G37: Cp | H37: Use With | M37: 137.2 | N37: 1.52 | O37: 1.52 | P37: 1.73 | Q37: 1.86
B38: Khulna | C38: 73.3 | E38: Windward Wall | F38: All values | G38: 0.8 | H38: qz | M38: 152.4 | N38: 1.56 | O38: 1.56 | P38: 1.77 | Q38: 1.89
B39: Kutubdia | C39: 80 | E39: Leeward Wall | F39: 0-1 | G39: -0.5 | H39: qh | M39: Notes:
B40: Kishoreganj | C40: 64.7 | F40: 2 | G40: -0.3 | M40: 1. Case 1:
B41: Kurigram | C41: 65.6 | F41: > 4 | G41: -0.2 | M41: (a) All components and cladding.
B42: Kushtia | C42: 66.9 | E42: Side Wall | F42: All values | G42: -0.7 | H42: qh | M42: (b) Main wind force resisting system in low-rise buildings designed using Figure 6.2.10. Case 2:
B43: Lakshmipur | C43: 51.2 | M43: (a) All main wind force resisting systems in buildings except those in low-rise buildings designed using Figure 6.2.10.
B44: Lalmonirhat | C44: 63.7 | M44: (b) All main wind force resisting systems in other structures.
...

Sheet Gust Factor Cal.
B3: For Rigid Structure
B4: Lz (bar)= | C4: =F7*((F6/10)^F5) -> 123.14198 | E4: C= | F4: =VLOOKUP('MWFRS (Any Ht.)'!C8,'Gust Factor Cal.'!E11:O13,8,FALSE) -> 0.3
B5: Q= | C5: =SQRT((1/(1+(0.63*((B+h)/'Gust Factor Cal.'!C4)^0.63)))) -> 0.84415061 | F5: =VLOOKUP('MWFRS (Any Ht.)'!C8,'Gust Factor Cal.'!E11:O13,10,FALSE) -> 0.33333333
B6: Iz(bar) = | C6: =F4*(10/F6)^(1/6) -> 0.26699896 | E6: Ehos z bar= | F6: =IF((0.6*'MWFRS (Any Ht.)'!O14)<(VLOOKUP('MWFRS (Any Ht.)'!C8,'Gust Factor Cal.'!E11:O13,11,FALSE)),(VLOOKUP('MWFRS (Any Ht.)'!C8,'Gust Factor Cal.'!E11:O13,11,FALSE)),(0.6*'MWFRS (Any Ht.)'!O7)) -> 20.121951
B7: G= | C7: =0.925*((1+(1.7*3.4*C6*C5))/(1+(1.7*3.4*C6))) -> 0.83752287 | E7: l (m) = | F7: =VLOOKUP('MWFRS (Any Ht.)'!C8,'Gust Factor Cal.'!E11:O13,9,FALSE) -> 97.54
E9: Table 6.2.10: Terrain Exposure Constants
E10: Exposure | F10: α | G10: Zg (m) | H10: â | J10: ᾱ | L10: c | M10: l (m) | O10: zmin (m)*
E11: A | F11: 7 | G11: 365.76 | H11: 0.142857 | I11: 0.84 | J11: 0.25 | K11: 0.45 | L11: 0.3 | M11: 97.54 | N11: 0.33333333 | O11: 9.14
E12: B | F12: 9.5 | G12: 274.32 | H12: 0.10526316 | I12: 1 | J12: 0.15384615 | K12: 0.65 | L12: 0.2 | M12: 152.4 | N12: 0.2 | O12: 4.57
E13: C | F13: 11.5 | G13: 213.36 | H13: 0.086956522 | I13: 1.07 | J13: 0.11111111 | K13: 0.8 | L13: 0.15 | M13: 198.12 | N13: 0.125 | O13: 2.13
G15: For Flexible Structure
G16: V= | H16: =VLOOKUP(L16,'BNBC 20 Data'!B7:C80,2,FALSE) -> 65.7 | I16: m/s | L16: ='MWFRS (Any Ht.)'!C6 -> Dhaka
H17: =VLOOKUP('MWFRS (Any Ht.)'!C8,'Gust Factor Cal.'!E10:O13,7,FALSE) -> 0.45
G18: ᾱ= | H18: =VLOOKUP('MWFRS (Any Ht.)'!C8,'Gust Factor Cal.'!E10:O13,6,FALSE) -> 0.25
H19: =H16*H17*((F6/10)^H18) -> 35.212382
G22: f/n1= | H22: ='MWFRS (Any Ht.)'!O24 -> 0.90917425 | I22: Hz
G23: Rh= | H23: =IF(Ƞh>0,((1/Ƞh)-((1/(2*Ƞh^2))*(1-EXP(-2*Ƞh))))) -> 0.21955281 | L23: Ƞ= | M23: =(4.6*f*h)/$H$19 -> 3.9831659
G24: RB= | H24: =IF(Ƞb>0,((1/Ƞb)-((1/(2*Ƞb^2))*(1-EXP(-2*Ƞb))))) -> 0.2622297 | L24: Ƞ= | M24: =(4.6*f*B)/$H$19 -> 3.2227433
G25: RL= | H25: =IF(ȠL>0,((1/ȠL)-((1/(2*ȠL^2))*(1-EXP(-2*ȠL))))) -> 0.10264909 | L25: Ƞ= | M25: =(15.4*f*L)/$H$19 -> 9.2132359
G27: N1= | H27: =(f*Lz/H19) -> 3.1794927
G29: Rn= | H29: =((7.47*N.1)/((1+10.3*(N.1))^(5/3))) -> 0.067387873
G31: R= | H31: =SQRT((1/β)*Rn*Rh*RB*(0.53+(0.47*RL))) -> 0.21182259
G33: gR= | H33: =SQRT(2*LN(3600*f))+(0.577/SQRT(2*LN(3600*f))) -> 4.1667144
G34: gQ= | H34: 3.4
G35: gV= | H35: 3.4
G38: Gf= | H38: =0.925*((1+(1.7*Iz*SQRT(((gQ^2)*(Q^2))+((gR^2)*(R.^2)))))/(1+(1.7*gv*Iz))) -> 0.85942026

Sheet Kh and Kz Cal.
D2: T 6.2.11 Velocity Pressure Exposure Coefficients, Kh and Kz
D3: Height above ground level, z (m) | E3: A | G3: B | H3: C
E4: Case 1 | F4: Case 2 | G4: Case 1 & 2 | H4: Case 1 & 2
D5: 0 | E5: 0.7 | F5: 0.57 | G5: 0.85 | H5: 1.03
D6: 4.6 | E6: 0.7 | F6: 0.57 | G6: 0.85 | H6: 1.03
D7: 6.1 | E7: 0.7 | F7: 0.62 | G7: 0.9 | H7: 1.08 | L7: =h -> 33.536585
D8: 7.6 | E8: 0.7 | F8: 0.66 | G8: 0.94 | H8: 1.12 | L8: =VLOOKUP(L7,D6:H27,'MWFRS (Any Ht.)'!P31,TRUE) -> 0.99
D9: 9.1 | E9: 0.7 | F9: 0.7 | G9: 0.98 | H9: 1.16
D10: 12.2 | E10: 0.76 | F10: 0.76 | G10: 1.04 | H10: 1.22
D11: 15.2 | E11: 0.81 | F11: 0.81 | G11: 1.09 | H11: 1.27
D12: 18 | E12: 0.85 | F12: 0.85 | G12: 1.13 | H12: 1.31
D13: 21.3 | E13: 0.89 | F13: 0.89 | G13: 1.17 | H13: 1.34
D14: 24.4 | E14: 0.93 | F14: 0.93 | G14: 1.21 | H14: 1.38
D15: 27.41 | E15: 0.96 | F15: 0.96 | G15: 1.24 | H15: 1.4
D16: 30.5 | E16: 0.99 | F16: 0.99 | G16: 1.26 | H16: 1.43
D17: 36.6 | E17: 1.04 | F17: 1.04 | G17: 1.31 | H17: 1.48
D18: 42.7 | E18: 1.09 | F18: 1.09 | G18: 1.36 | H18: 1.52
D19: 48.8 | E19: 1.13 | F19: 1.13 | G19: 1.39 | H19: 1.55
D20: 54.9 | E20: 1.17 | F20: 1.17 | G20: 1.43 | H20: 1.58
... D27: 152.4 | E27: 1.56 | F27: 1.56 | G27: 1.77 | H27: 1.89
D28: Notes:
D29: 1. Case 1:
D30: (a) All components and cladding.
D31: (b) Main wind force resisting system in low-rise buildings designed using Figure 6.2.10. Case 2:
D32: (a) All main wind force resisting systems in buildings except those in low-rise buildings designed using Figure 6.2.10.
D33: (b) All main wind force resisting systems in other structures.
D34: 2. The velocity pressure exposure coefficient Kz may be determined from the following formula: For 4.57 m ≤ z ≤zg: Kz = 2.01 (z/zg)2/α
D35: For z < 4.57 m: Kz = 2.01 (4.57/zg)2/a
D36: Note: z shall not be taken less than 9.1 m for Case 1 in exposure A.
D37: 3. α and zg are tabulated in Table 6.2.3.
D38: 4. Linear interpolation for intermediate values. of height z is acceptable.
D39: 5. Exposure categories are defined in Sec 2.4.6.3.
