Workbook
Name framesystem: [1]Sheet3!$B$39:$B$45

Sheet Video & Instruction 
B14: qLearnify is an educational platform dedicated to the professional development of engineers and architects.
C17: Website: | E17: https://qlearnify.com/
C18: Facebook: | E18: https://www.facebook.com/qlearnify
C19: Youtube (Bangla): | E19: https://www.youtube.com/@qlearnify-bn
C20: Youtube (English): | E20: https://www.youtube.com/@qlearnify-en
C21: WhatsApp: | E21: https://wa.me/8801511250108
C22: LinkedIn: | E22: https://www.linkedin.com/company/qlearnify/
B24: Note: This Excel sheet has been created for educational purposes; please validate it according to your own standards before using it for professional work.
A34: Bangla: | B34: https://youtube.com/playlist?list=PLxle8F-wJI7P43K0GljphED4I5TRXu6Zx&si=el-Lrxm5mB1Vmgcf
A36: English: | B36: https://youtube.com/playlist?list=PLTscI_CLWNfB_1x6_7zylwLZWo7mKypCq&si=QzFh_rJa61GU0YNW

Sheet V1.3 (Updated 03-2025)
B1: Input the provided value In Blue Box
J3: Case 1 | K3: Case 2 | L3: Case 3 | M3: Case 4 | N3: Case 5 | O3: Case 6 | P3: Case 7 | Q3: Case 8 | R3: Case 9
B5: Materials Properties:
D6: Converted Data | E6: Main Data
D7: fs= | E7: =0.4*E10 -> 24000 | F7: psi
D8: fc= | E8: =0.45*E9 -> 1260 | F8: psi | O8: You Have Entered Shorter & longer Length Incorrectly!
D9: f'c= | E9: 2800 | F9: psi
D10: fy= | E10: 60000 | F10: psi
B11: ExtraDL (SDL+FFL) | E11: 25 | F11: psf
B12: Live Load ,L.L= | E12: 40 | F12: psf
C13: Width of Beam (bw)= | E13: 10 | F13: in
C14: Higth of Beam (bh)= | E14: 18 | F14: in
B15: Dia of provided Bar= | E15: 3.15 | F15: #
B16: Half of the Continuous Panel X= | E16: 8.5 | F16: ft
B17: Shorter Direction length ,A = | E17: 19.25 | F17: ft
B18: Longer Direction length ,B = | E18: 20.5 | F18: ft | G18: =IF(E17>E18,"You have Input Slab Length Incorrectly. Please Check it.",IF(E18/E17<=2,"Two Way Slab Is Confirm.","One Way Slab Is Confirm. Change it.")) -> Two Way Slab Is Confirm.
C19: Load Form Wall
D20: Length= | E20: 29.83 | F20: ft
D21: Thickness= | E21: 0.5 | F21: ft
D22: Hight= | E22: 9.5 | F22: ft
D23: Case | E23: Case 4
B24: Ф | C24: 0.9 | D24: =(29*10^6)/(57000*SQRT(E9)) -> 9.6148857 | G24: =IF(F33="What!","How Dare You That You Have Change My Indentity! [This Program Is Being Crushed!]","Enjoy This Softwere But Please Don’t Change Anything Except 'Blue BOX' ") -> Enjoy This Softwere But Please Don’t Change Anything Except 'Blue BOX'
B25: β | C25: 0.85
B26: ρ | C26: =0.85*C25*(E9/E10)*(0.003/(0.003+0.004)) -> 0.01445
B27: R= | C27: =C26*E10*(1-((0.59*C26*E10)/E9)) -> 708.60839
B28: Shorter Direction length ,A = | E28: =E17 -> 19.25 | F28: ft | G28: =IF(E29>=E28," ",O8)
B29: Longer Direction length ,B = | E29: =E18 -> 20.5 | F29: ft
C31: B/A= | D31: =E29/E28 -> 1.0649351 | E31: =IF(D31<2,"<2 ;Two Way Slab Is Confurm!","One Way Slab Is Confurm!") -> <2 ;Two Way Slab Is Confurm!
H32: Final Thickness
C33: Slab Thickness (Trail)= | E33: 6 | F33: ='Slab Min Thickness Calculation'!D35 -> 5.9345423 | G33: in » | H33: =IF(F33<=E33,E33,_xlfn.CEILING.MATH(F33,0.25)) -> 6 | I33: in | N33: =((1.7*C24*E9*E10*D35*12)-SQRT((1.7*C24*E9*E10*D35*12)^2-4*1.7*C24*E10*E10*E9*12*C60*12))/(2*C24*E10*E10) -> 0.24271195
B35: Shorter--> | C35: d (provided)= | D35: =H33-0.75-(E15/16) -> 5.053125 | E35: in | F35: =IF(G58<D35,"","Please Increase Slab Thickness")
B36: Longer--> | C36: d (provided)= | D36: =D35-(E15/8) -> 4.659375 | E36: in
B37: Load Form Wall
B38: Length= | C38: =E20 -> 29.83 | D38: ft
B39: Width= | C39: =E21 -> 0.5 | D39: ft
B40: Hight= | C40: =E22 -> 9.5 | D40: ft
B41: Total= | C41: =C38*C39*C40*120/(E28*E29) -> 43.086728 | D41: psf
B43: Dead Load,DL= | D43: =((H33/12)*150)+C41+E11 -> 143.08673 | E43: psf
B44: Total Load, W = | D44: =(1.6*E12)+(1.2*D43) -> 235.70407 | E44: psf
B46: Moment Coefficient Ratio, m = | E46: =(E28/E29) -> 0.93902439
...

Sheet Slab Min Thickness Calculation
B4: Lb= | C4: ='V1.3 (Updated 03-2025)'!E18 -> 20.5 | D4: ft | E4: (clear span measured in long direction face to face of column or face to face of beam )
B5: La= | C5: ='V1.3 (Updated 03-2025)'!E17 -> 19.25 | D5: ft | E5: (clear span measured in short direction face to face of column or face to face of beam )
A6: Width of Beam (bw) | C6: ='V1.3 (Updated 03-2025)'!E13 -> 10 | D6: in
A7: Depth of Beam(bh) | C7: ='V1.3 (Updated 03-2025)'!E14 -> 18 | D7: in
B8: fy= | C8: ='V1.3 (Updated 03-2025)'!E10 -> 60000 | D8: psi | E8: Yield Stress
B11: bw= | C11: = | D11: =C6 -> 10 | E11: in | F11: Width of Beam
B12: bh= | C12: = | D12: =C7 -> 18 | E12: in | F12: Depth of Beam
B13: For Edge Beam, Ib | C13: = | D13: 1.5*(bh3/12) | F13: (As L beam)
C14: = | D14: =1.5*D11*(D12^3/12) -> 7290 | E14: in4
B15: For Interior Beam, Ib | C15: = | D15: 2*(bh3/12) | F15: (As T beam)
C16: = | D16: =2*D11*(D12^3/12) -> 9720 | E16: in4
B17: Slab, L | C17: = | D17: =C4 -> 20.5 | E17: ft
B18: Slab, S | C18: = | D18: =C5 -> 19.25 | E18: ft
B19: X | C19: = | D19: ='V1.3 (Updated 03-2025)'!E16 -> 8.5 | E19: ft
B20: Slab, thickness(trial) | C20: = | D20: ='V1.3 (Updated 03-2025)'!E33 -> 6 | E20: in
B21: Is1 | C21: = | D21: =(D17*(D20^3)) -> 4428 | E21: in4
B22: Is2 | C22: = | D22: =(D18*(D20^3)) -> 4158 | E22: in4
B23: For Edge (X) Is3 | C23: = | D23: =(D19*(D20^3)) -> 1836 | E23: in4
B24: Relative Stiffness, α | C24: = | D24: EcbIb / EcsIs
C25: = | D25: Ib / Is
B26: For Slab(L) α1 | C26: = | D26: =D16/D21 -> 2.195122
B27: For Slab(S) α2 | C27: = | D27: =D16/D22 -> 2.3376623
B28: For Slab(X) α3 | C28: = | D28: =D14/D23 -> 3.9705882
B29: So,Average α | C29: = | D29: =(D26+D27+D28)/3 -> 2.8344575 | E29: =IF(D29<2,"<2",IF(D29>2,">2")) -> >2
B30: β | C30: = | D30: =(D17-0.42)/(D18-0.42) -> 1.0663834
B32: If, α<2 then hmin | C32: = | F32: = | G32: =MAX((D17*12*(0.8+(C8/200000)))/(36+5*D30*(D29-0.2)),5) -> 5.4069489 | H32: in
B33: If,α>2 then hmin | C33: = | F33: = | G33: =MAX(((D17*12*(0.8+(C8/200000)))/(36+9*D30)),3.5433) -> 5.9345423 | H33: in
B35: So, hmin | C35: = | D35: =IF(D29<2,G32,IF(D29>2,G33)) -> 5.9345423 | E35: in

Sheet Coefficients For  N M
C3: m | E3: Case 1 | F3: Case 2 | G3: Case 3 | H3: Case 4 | I3: Case 5 | J3: Case 6 | K3: Case 7 | L3: Case 8 | M3: Case 9
C4: 1 | D4: Ca,neg | F4: 0.045 | H4: 0.05 | I4: 0.075 | J4: 0.071 | L4: 0.033 | M4: 0.061
C5: 1 | D5: Cb,neg | F5: 0.045 | G5: 0.076 | H5: 0.05 | K5: 0.071 | L5: 0.061 | M5: 0.033
C6: 0.95 | D6: Ca,neg | F6: 0.05 | H6: 0.055 | I6: 0.079 | J6: 0.075 | L6: 0.038 | M6: 0.065
C7: 0.95 | D7: Cb,neg | F7: 0.041 | G7: 0.072 | H7: 0.045 | K7: 0.067 | L7: 0.056 | M7: 0.029
C8: 0.9 | D8: Ca,neg | F8: 0.055 | H8: 0.06 | I8: 0.08 | J8: 0.079 | L8: 0.043 | M8: 0.068
C9: 0.9 | D9: Cb,neg | F9: 0.037 | G9: 0.07 | H9: 0.04 | K9: 0.062 | L9: 0.052 | M9: 0.025 | P9: Ca (m) | Q9: ='V1.3 (Updated 03-2025)'!E47 -> 0.9
C10: 0.85 | D10: Ca,neg | F10: 0.06 | H10: 0.066 | I10: 0.082 | J10: 0.083 | L10: 0.049 | M10: 0.072 | P10: Cb (m) | Q10: ='V1.3 (Updated 03-2025)'!E48 -> 0.95
C11: 0.85 | D11: Cb,neg | F11: 0.031 | G11: 0.065 | H11: 0.034 | K11: 0.057 | L11: 0.046 | M11: 0.021 | P11: Case | Q11: ='V1.3 (Updated 03-2025)'!E23 -> Case 4
C12: 0.8 | D12: Ca,neg | F12: 0.065 | H12: 0.071 | I12: 0.083 | J12: 0.086 | L12: 0.055 | M12: 0.075 | P12: Ca,neg | Q12: {=INDEX(E4:M25,MATCH(Q9&P12,C4:C25&D4:D25,0),MATCH(Q11,E3:M3,0))} -> 0.06
C13: 0.8 | D13: Cb,neg | F13: 0.027 | G13: 0.061 | H13: 0.029 | K13: 0.051 | L13: 0.041 | M13: 0.017 | P13: Cb,neg | Q13: {=INDEX(E4:M25,MATCH(Q10&P13,C4:C25&D4:D25,0),MATCH(Q11,E3:M3,0))} -> 0.045
C14: 0.75 | D14: Ca,neg | F14: 0.069 | H14: 0.076 | I14: 0.085 | J14: 0.088 | L14: 0.061 | M14: 0.078
C15: 0.75 | D15: Cb,neg | F15: 0.022 | G15: 0.056 | H15: 0.024 | K15: 0.044 | L15: 0.036 | M15: 0.014
C16: 0.7 | D16: Ca,neg | F16: 0.074 | H16: 0.081 | I16: 0.086 | J16: 0.091 | L16: 0.068 | M16: 0.081
C17: 0.7 | D17: Cb,neg | F17: 0.017 | G17: 0.05 | H17: 0.019 | K17: 0.038 | L17: 0.029 | M17: 0.011
C18: 0.65 | D18: Ca,neg | F18: 0.077 | H18: 0.085 | I18: 0.087 | J18: 0.093 | L18: 0.074 | M18: 0.083
C19: 0.65 | D19: Cb,neg | F19: 0.014 | G19: 0.043 | H19: 0.015 | K19: 0.031 | L19: 0.024 | M19: 0.008
C20: 0.6 | D20: Ca,neg | F20: 0.081 | H20: 0.089 | I20: 0.088 | J20: 0.095 | L20: 0.08 | M20: 0.085
C21: 0.6 | D21: Cb,neg | F21: 0.01 | G21: 0.035 | H21: 0.011 | K21: 0.024 | L21: 0.018 | M21: 0.006
C22: 0.55 | D22: Ca,neg | F22: 0.084 | H22: 0.092 | I22: 0.089 | J22: 0.096 | L22: 0.085 | M22: 0.086
C23: 0.55 | D23: Cb,neg | F23: 0.007 | G23: 0.028 | H23: 0.008 | K23: 0.019 | L23: 0.014 | M23: 0.005
C24: 0.5 | D24: Ca,neg | F24: 0.086 | H24: 0.094 | I24: 0.09 | J24: 0.097 | L24: 0.089 | M24: 0.088
C25: 0.5 | D25: Cb,neg | F25: 0.006 | G25: 0.022 | H25: 0.006 | K25: 0.014 | L25: 0.01 | M25: 0.003

Sheet Coefficients For DL P M 
E4: Case 1 | F4: Case 2 | G4: Case 3 | H4: Case 4 | I4: Case 5 | J4: Case 6 | K4: Case 7 | L4: Case 8 | M4: Case 9
B5: 1 | C5: 1 | D5: Ca,dl | E5: 0.036 | F5: 0.018 | G5: 0.018 | H5: 0.027 | I5: 0.027 | J5: 0.033 | K5: 0.027 | L5: 0.02 | M5: 0.023
B6: 2 | C6: 1 | D6: Cb,dl | E6: 0.036 | F6: 0.018 | G6: 0.027 | H6: 0.027 | I6: 0.018 | J6: 0.027 | K6: 0.033 | L6: 0.023 | M6: 0.02
B7: 3 | C7: 0.95 | D7: Ca,dl | E7: 0.04 | F7: 0.02 | G7: 0.021 | H7: 0.03 | I7: 0.028 | J7: 0.036 | K7: 0.031 | L7: 0.022 | M7: 0.024
B8: 4 | C8: 0.95 | D8: Cb,dl | E8: 0.033 | F8: 0.016 | G8: 0.025 | H8: 0.024 | I8: 0.015 | J8: 0.024 | K8: 0.031 | L8: 0.021 | M8: 0.017
B9: 5 | C9: 0.9 | D9: Ca,dl | E9: 0.045 | F9: 0.022 | G9: 0.025 | H9: 0.033 | I9: 0.029 | J9: 0.039 | K9: 0.035 | L9: 0.025 | M9: 0.026 | Q9: Ca (m) | R9: ='V1.3 (Updated 03-2025)'!E47 -> 0.9
B10: 6 | C10: 0.9 | D10: Cb,dl | E10: 0.029 | F10: 0.014 | G10: 0.024 | H10: 0.022 | I10: 0.013 | J10: 0.021 | K10: 0.028 | L10: 0.019 | M10: 0.015 | Q10: Cb (m) | R10: ='V1.3 (Updated 03-2025)'!E48 -> 0.95
B11: 7 | C11: 0.85 | D11: Ca,dl | E11: 0.05 | F11: 0.024 | G11: 0.029 | H11: 0.036 | I11: 0.031 | J11: 0.042 | K11: 0.04 | L11: 0.029 | M11: 0.028 | Q11: Case | R11: ='V1.3 (Updated 03-2025)'!E23 -> Case 4
B12: 8 | C12: 0.85 | D12: Cb,dl | E12: 0.026 | F12: 0.012 | G12: 0.022 | H12: 0.019 | I12: 0.011 | J12: 0.017 | K12: 0.025 | L12: 0.017 | M12: 0.013 | Q12: Ca,dl | R12: {=INDEX(E5:M26,MATCH(R9&Q12,C5:C26&D5:D26,0),MATCH(R11,E4:M4,0))} -> 0.033
B13: 9 | C13: 0.8 | D13: Ca,dl | E13: 0.056 | F13: 0.026 | G13: 0.034 | H13: 0.039 | I13: 0.032 | J13: 0.045 | K13: 0.045 | L13: 0.032 | M13: 0.029 | Q13: Cb,dl | R13: {=INDEX(E5:M26,MATCH(R10&Q13,C5:C26&D5:D26,0),MATCH(R11,E4:M4,0))} -> 0.024
B14: 10 | C14: 0.8 | D14: Cb,dl | E14: 0.023 | F14: 0.011 | G14: 0.02 | H14: 0.016 | I14: 0.009 | J14: 0.015 | K14: 0.022 | L14: 0.015 | M14: 0.01
B15: 11 | C15: 0.75 | D15: Ca,dl | E15: 0.061 | F15: 0.028 | G15: 0.04 | H15: 0.043 | I15: 0.033 | J15: 0.048 | K15: 0.051 | L15: 0.036 | M15: 0.031
B16: 12 | C16: 0.75 | D16: Cb,dl | E16: 0.019 | F16: 0.009 | G16: 0.018 | H16: 0.013 | I16: 0.007 | J16: 0.012 | K16: 0.02 | L16: 0.013 | M16: 0.007
B17: 13 | C17: 0.7 | D17: Ca,dl | E17: 0.068 | F17: 0.03 | G17: 0.046 | H17: 0.046 | I17: 0.035 | J17: 0.051 | K17: 0.058 | L17: 0.04 | M17: 0.033
B18: 14 | C18: 0.7 | D18: Cb,dl | E18: 0.016 | F18: 0.007 | G18: 0.016 | H18: 0.011 | I18: 0.005 | J18: 0.009 | K18: 0.017 | L18: 0.011 | M18: 0.006
B19: 15 | C19: 0.65 | D19: Ca,dl | E19: 0.074 | F19: 0.032 | G19: 0.054 | H19: 0.05 | I19: 0.036 | J19: 0.054 | K19: 0.065 | L19: 0.044 | M19: 0.034
B20: 16 | C20: 0.65 | D20: Cb,dl | E20: 0.013 | F20: 0.006 | G20: 0.014 | H20: 0.009 | I20: 0.004 | J20: 0.007 | K20: 0.014 | L20: 0.009 | M20: 0.005
B21: 17 | C21: 0.6 | D21: Ca,dl | E21: 0.081 | F21: 0.034 | G21: 0.062 | H21: 0.053 | I21: 0.037 | J21: 0.056 | K21: 0.073 | L21: 0.048 | M21: 0.036
B22: 18 | C22: 0.6 | D22: Cb,dl | E22: 0.01 | F22: 0.004 | G22: 0.011 | H22: 0.007 | I22: 0.003 | J22: 0.006 | K22: 0.012 | L22: 0.007 | M22: 0.004
B23: 19 | C23: 0.55 | D23: Ca,dl | E23: 0.088 | F23: 0.035 | G23: 0.071 | H23: 0.056 | I23: 0.038 | J23: 0.058 | K23: 0.081 | L23: 0.052 | M23: 0.037
B24: 20 | C24: 0.55 | D24: Cb,dl | E24: 0.008 | F24: 0.003 | G24: 0.009 | H24: 0.005 | I24: 0.002 | J24: 0.004 | K24: 0.009 | L24: 0.005 | M24: 0.003
B25: 21 | C25: 0.5 | D25: Ca,dl | E25: 0.095 | F25: 0.037 | G25: 0.08 | H25: 0.059 | I25: 0.039 | J25: 0.061 | K25: 0.089 | L25: 0.056 | M25: 0.038
B26: 22 | C26: 0.5 | D26: Cb,dl | E26: 0.006 | F26: 0.002 | G26: 0.007 | H26: 0.004 | I26: 0.001 | J26: 0.003 | K26: 0.007 | L26: 0.004 | M26: 0.002

Sheet Coefficients For LL P M 
E4: Case 1 | F4: Case 2 | G4: Case 3 | H4: Case 4 | I4: Case 5 | J4: Case 6 | K4: Case 7 | L4: Case 8 | M4: Case 9
B5: 1 | C5: 1 | D5: Ca,ll | E5: 0.036 | F5: 0.027 | G5: 0.027 | H5: 0.032 | I5: 0.032 | J5: 0.035 | K5: 0.032 | L5: 0.028 | M5: 0.03
B6: 2 | C6: 1 | D6: Cb,ll | E6: 0.036 | F6: 0.027 | G6: 0.032 | H6: 0.032 | I6: 0.027 | J6: 0.032 | K6: 0.035 | L6: 0.03 | M6: 0.028
B7: 3 | C7: 0.95 | D7: Ca,ll | E7: 0.04 | F7: 0.03 | G7: 0.031 | H7: 0.035 | I7: 0.034 | J7: 0.038 | K7: 0.036 | L7: 0.031 | M7: 0.032
B8: 4 | C8: 0.95 | D8: Cb,ll | E8: 0.033 | F8: 0.025 | G8: 0.029 | H8: 0.029 | I8: 0.024 | J8: 0.029 | K8: 0.032 | L8: 0.027 | M8: 0.025
B9: 5 | C9: 0.9 | D9: Ca,ll | E9: 0.045 | F9: 0.034 | G9: 0.035 | H9: 0.039 | I9: 0.037 | J9: 0.042 | K9: 0.04 | L9: 0.035 | M9: 0.036 | Q9: Ca (m) | R9: ='V1.3 (Updated 03-2025)'!E47 -> 0.9
B10: 6 | C10: 0.9 | D10: Cb,ll | E10: 0.029 | F10: 0.022 | G10: 0.027 | H10: 0.026 | I10: 0.021 | J10: 0.025 | K10: 0.029 | L10: 0.024 | M10: 0.022 | Q10: Cb (m) | R10: ='V1.3 (Updated 03-2025)'!E48 -> 0.95
B11: 7 | C11: 0.85 | D11: Ca,ll | E11: 0.05 | F11: 0.037 | G11: 0.04 | H11: 0.043 | I11: 0.041 | J11: 0.046 | K11: 0.045 | L11: 0.04 | M11: 0.039 | Q11: Case | R11: ='V1.3 (Updated 03-2025)'!E23 -> Case 4
B12: 8 | C12: 0.85 | D12: Cb,ll | E12: 0.026 | F12: 0.019 | G12: 0.024 | H12: 0.023 | I12: 0.019 | J12: 0.022 | K12: 0.026 | L12: 0.022 | M12: 0.02 | Q12: Ca,ll | R12: {=INDEX(E5:M26,MATCH(R9&Q12,C5:C26&D5:D26,0),MATCH(R11,E4:M4,0))} -> 0.039
B13: 9 | C13: 0.8 | D13: Ca,ll | E13: 0.056 | F13: 0.041 | G13: 0.045 | H13: 0.048 | I13: 0.044 | J13: 0.051 | K13: 0.051 | L13: 0.044 | M13: 0.042 | Q13: Cb,ll | R13: {=INDEX(E5:M26,MATCH(R10&Q13,C5:C26&D5:D26,0),MATCH(R11,E4:M4,0))} -> 0.029
B14: 10 | C14: 0.8 | D14: Cb,ll | E14: 0.023 | F14: 0.017 | G14: 0.022 | H14: 0.02 | I14: 0.016 | J14: 0.019 | K14: 0.023 | L14: 0.019 | M14: 0.017
B15: 11 | C15: 0.75 | D15: Ca,ll | E15: 0.061 | F15: 0.045 | G15: 0.051 | H15: 0.052 | I15: 0.047 | J15: 0.055 | K15: 0.056 | L15: 0.049 | M15: 0.046
B16: 12 | C16: 0.75 | D16: Cb,ll | E16: 0.019 | F16: 0.014 | G16: 0.019 | H16: 0.016 | I16: 0.013 | J16: 0.016 | K16: 0.02 | L16: 0.016 | M16: 0.013
B17: 13 | C17: 0.7 | D17: Ca,ll | E17: 0.068 | F17: 0.049 | G17: 0.057 | H17: 0.057 | I17: 0.051 | J17: 0.06 | K17: 0.063 | L17: 0.054 | M17: 0.05
B18: 14 | C18: 0.7 | D18: Cb,ll | E18: 0.016 | F18: 0.012 | G18: 0.016 | H18: 0.014 | I18: 0.011 | J18: 0.013 | K18: 0.017 | L18: 0.014 | M18: 0.011
B19: 15 | C19: 0.65 | D19: Ca,ll | E19: 0.074 | F19: 0.053 | G19: 0.064 | H19: 0.062 | I19: 0.055 | J19: 0.064 | K19: 0.07 | L19: 0.059 | M19: 0.054
B20: 16 | C20: 0.65 | D20: Cb,ll | E20: 0.013 | F20: 0.01 | G20: 0.014 | H20: 0.011 | I20: 0.009 | J20: 0.01 | K20: 0.014 | L20: 0.011 | M20: 0.009
B21: 17 | C21: 0.6 | D21: Ca,ll | E21: 0.081 | F21: 0.058 | G21: 0.071 | H21: 0.067 | I21: 0.059 | J21: 0.068 | K21: 0.077 | L21: 0.065 | M21: 0.059
B22: 18 | C22: 0.6 | D22: Cb,ll | E22: 0.01 | F22: 0.007 | G22: 0.011 | H22: 0.009 | I22: 0.007 | J22: 0.008 | K22: 0.011 | L22: 0.009 | M22: 0.007
B23: 19 | C23: 0.55 | D23: Ca,ll | E23: 0.088 | F23: 0.062 | G23: 0.08 | H23: 0.072 | I23: 0.063 | J23: 0.073 | K23: 0.085 | L23: 0.07 | M23: 0.063
B24: 20 | C24: 0.55 | D24: Cb,ll | E24: 0.008 | F24: 0.006 | G24: 0.009 | H24: 0.007 | I24: 0.005 | J24: 0.006 | K24: 0.009 | L24: 0.007 | M24: 0.006
B25: 21 | C25: 0.5 | D25: Ca,ll | E25: 0.095 | F25: 0.066 | G25: 0.088 | H25: 0.077 | I25: 0.067 | J25: 0.078 | K25: 0.092 | L25: 0.076 | M25: 0.067
B26: 22 | C26: 0.5 | D26: Cb,ll | E26: 0.006 | F26: 0.004 | G26: 0.007 | H26: 0.005 | I26: 0.004 | J26: 0.005 | K26: 0.007 | L26: 0.005 | M26: 0.004
