Workbook
Name D: #REF!
Name Dt: #REF!
Name framesystem: [1]Sheet3!$B$39:$B$45
Name H: #REF!
Name n: #REF!
Name total_length: #REF!
Name Wt: #REF!

Sheet Video & Instruction 
B14: qLearnify is an educational platform dedicated to the professional development of engineers and architects.
C17: Website: | E17: https://qlearnify.com/
C18: Facebook: | E18: https://www.facebook.com/qlearnify
C19: Youtube (Bangla): | E19: https://www.youtube.com/@qlearnify-bn
C20: Youtube (English): | E20: https://www.youtube.com/@qlearnify-en
C21: WhatsApp: | E21: https://wa.me/8801511250108
C22: LinkedIn: | E22: https://www.linkedin.com/company/qlearnify/
B24: Note: This Excel sheet has been created for educational purposes; please validate it according to your own standards before using it for professional work.
A34: Bangla: | B34: https://youtube.com/playlist?list=PLxle8F-wJI7P43K0GljphED4I5TRXu6Zx&si=el-Lrxm5mB1Vmgcf
A36: English: | B36: https://youtube.com/playlist?list=PLTscI_CLWNfB_1x6_7zylwLZWo7mKypCq&si=QzFh_rJa61GU0YNW

Sheet Beam Estimating V1.1 (721.7.23)
B1: fy= | C1: 500 | D1: MPa | F1: Mix Ratio
B2: f'c= | C2: 20 | D2: MPa | F2: 1 | G2: 1 | H2: 1
B3: Span Nos= | C3: 2
D4: 0 | E4: 10 | F4: 0 | G4: 16 | H4: 0 | I4: 10 | K4: 0 | L4: 16 | M4: 0 | N4: 16 | O4: 0 | P4: 16 | R4: 0 | S4: 16 | T4: 0 | U4: 16 | V4: 0 | W4: 16 | Y4: 0 | Z4: 16 | AA4: 1 | AB4: 16 | AC4: 0 | AD4: 16 | AF4: 1 | AG4: 16 | AH4: 1 | AI4: 16 | AJ4: 1 | AK4: 16 | AM4: 1 | AN4: 16 | AO4: 1 | AP4: 16 | AQ4: 1 | AR4: 16 | AT4: 1 | AU4: 16 | AV4: 1 | AW4: 16 | AX4: 1 | AY4: 16 | BA4: 1 | BB4: 16 | BC4: 1 | BD4: 16 | BE4: 1 | BF4: 16 | BH4: 1 | BI4: 16 | BJ4: 1 | BK4: 16 | BL4: 1 | BM4: 16 | BO4: 1 | BP4: 16 | BQ4: 1 | BR4: 16 | BS4: 1 | BT4: 16 | BV4: 1 | BW4: 16 | BX4: 1 | BY4: 16 | BZ4: 1 | CA4: 16 | CC4: 1 | CD4: 16 | CE4: 1 | CF4: 16 | CG4: 1 | CH4: 16
D5: 1 | E5: 16 | F5: 2 | G5: 16 | H5: 1 | I5: 16 | K5: 1 | L5: 16 | M5: 2 | N5: 16 | O5: 1 | P5: 16 | R5: 1 | S5: 16 | T5: 2 | U5: 16 | V5: 1 | W5: 16 | Y5: 0 | Z5: 16 | AA5: 2 | AB5: 16 | AC5: 2 | AD5: 16 | AF5: 2 | AG5: 16 | AH5: 2 | AI5: 16 | AJ5: 2 | AK5: 16 | AM5: 2 | AN5: 16 | AO5: 2 | AP5: 16 | AQ5: 2 | AR5: 16 | AT5: 2 | AU5: 16 | AV5: 2 | AW5: 16 | AX5: 2 | AY5: 16 | BA5: 2 | BB5: 16 | BC5: 2 | BD5: 16 | BE5: 2 | BF5: 16 | BH5: 2 | BI5: 16 | BJ5: 2 | BK5: 16 | BL5: 2 | BM5: 16 | BO5: 2 | BP5: 16 | BQ5: 2 | BR5: 16 | BS5: 2 | BT5: 16 | BV5: 2 | BW5: 16 | BX5: 2 | BY5: 16 | BZ5: 2 | CA5: 16 | CC5: 2 | CD5: 16 | CE5: 2 | CF5: 16 | CG5: 2 | CH5: 16
C7: 12 | D7: 2 | E7: 16 | F7: 10 | H7: 1 | I7: 16 | J7: 12 | K7: 2 | L7: 16 | M7: 10 | O7: 1 | P7: 16 | Q7: 12 | R7: 2 | S7: 16 | T7: 10 | V7: 1 | W7: 16 | X7: 12 | Y7: 0 | Z7: 16 | AA7: 10 | AC7: 2 | AD7: 16 | AE7: 12 | AF7: 2 | AG7: 16 | AH7: 10 | AJ7: 2 | AK7: 16 | AL7: 12 | AM7: 2 | AN7: 16 | AO7: 10 | AQ7: 2 | AR7: 16 | AS7: 12 | AT7: 2 | AU7: 16 | AV7: 10 | AX7: 2 | AY7: 16 | AZ7: 12 | BA7: 2 | BB7: 16 | BC7: 10 | BE7: 2 | BF7: 16 | BG7: 12 | BH7: 2 | BI7: 16 | BJ7: 10 | BL7: 2 | BM7: 16 | BN7: 12 | BO7: 2 | BP7: 16 | BQ7: 10 | BS7: 2 | BT7: 16 | BU7: 12 | BV7: 2 | BW7: 16 | BX7: 10 | BZ7: 2 | CA7: 16 | CB7: 12 | CC7: 2 | CD7: 16 | CE7: 10 | CG7: 2 | CH7: 16 | CI7: 12
D8: 2 | E8: 12 | H8: 0 | I8: 16 | K8: 2 | L8: 12 | O8: 0 | P8: 16 | R8: 2 | S8: 12 | V8: 0 | W8: 16 | Y8: 0 | Z8: 16 | AC8: 1 | AD8: 16 | AF8: 1 | AG8: 16 | AJ8: 1 | AK8: 16 | AM8: 1 | AN8: 16 | AQ8: 1 | AR8: 16 | AT8: 1 | AU8: 16 | AX8: 1 | AY8: 16 | BA8: 1 | BB8: 16 | BE8: 1 | BF8: 16 | BH8: 1 | BI8: 16 | BL8: 1 | BM8: 16 | BO8: 1 | BP8: 16 | BS8: 1 | BT8: 16 | BV8: 1 | BW8: 16 | BZ8: 1 | CA8: 16 | CC8: 1 | CD8: 16 | CG8: 1 | CH8: 16
E10: Vd= | F10: =((H10/12)*(H11/12)*(F7+(C7/12)+(IF(C3=1,(J7/12),0))))*1.5 -> 16.5 | G10: B= | H10: 12 | L10: Vd= | M10: =IF(C3<2,0,((O10/12)*(O11/12)*(M7+(J7/12)+(IF(C3=2,(Q7/12),0))))*1.5) -> 18 | N10: B= | O10: 12 | S10: Vd= | T10: =IF(C3<3,0,((V10/12)*(V11/12)*(T7+(Q7/12)+(IF(C3=3,(X7/12),0)))*1.5)) -> 0 | U10: B= | V10: 12 | Z10: Vd= | AA10: =IF(C3<4,0,((AC10/12)*(AC11/12)*(AA7+(X7/12)+(IF(C3=4,(AE7/12),0))))*1.5) -> 0 | AB10: B= | AC10: 12 | AG10: Vd= | AH10: =IF(C3<5,0,((AJ10/12)*(AJ11/12)*(AH7+(AE7/12)+(IF(C3=5,(AL7/12),0)))*1.5)) -> 0 | AI10: B= | AJ10: 12 | AN10: Vd= | AO10: =IF(C3<6,0,((AQ10/12)*(AQ11/12)*(AO7+(AL7/12)+(IF(C3=6,(AS7/12),0)))*1.5)) -> 0 | AP10: B= | AQ10: 12 | AU10: Vd= | AV10: =IF(C3<7,0,((AX10/12)*(AX11/12)*(AV7+(AS7/12)+(IF(C3=7,(AZ7/12),0)))*1.5)) -> 0 | AW10: B= | AX10: 12 | BB10: Vd= | BC10: =IF(C3<8,0,((BE10/12)*(BE11/12)*(BC7+(AZ7/12)+(IF(C3=8,(BG7/12),0)))*1.5)) -> 0 | BD10: B= | BE10: 12 | BI10: Vd= | BJ10: =IF(C3<9,0,((BL10/12)*(BL11/12)*(BJ7+(BG7/12)+(IF(C3=9,(BN7/12),0)))*1.5)) -> 0 | BK10: B= | BL10: 12 | BP10: Vd= | BQ10: =IF(C3<10,0,((BS10/12)*(BS11/12)*(BQ7+(BN7/12)+(IF(C3=10,(BU7/12),0)))*1.5)) -> 0 | BR10: B= | BS10: 12 | BW10: Vd= | BX10: =IF(C3<11,0,((BZ10/12)*(BZ11/12)*(BX7+(BU7/12)+(IF(C3=11,(CB7/12),0)))*1.5)) -> 0 | BY10: B= | BZ10: 12 | CD10: Vd= | CE10: =IF(C3<12,0,((CG10/12)*(CG11/12)*(CE7+(CB7/12)+(IF(C3=12,(CI7/12),0)))*1.5)) -> 0 | CF10: B= | CG10: 12
G11: H= | H11: 12 | N11: H= | O11: 12 | U11: H= | V11: 12 | AB11: H= | AC11: 12 | AI11: H= | AJ11: 12 | AP11: H= | AQ11: 12 | AW11: H= | AX11: 12 | BD11: H= | BE11: 12 | BK11: H= | BL11: 12 | BR11: H= | BS11: 12 | BY11: H= | BZ11: 12 | CF11: H= | CG11: 12
G12: n= | H12: 29 | N12: n= | O12: 28 | U12: n= | V12: 32 | AB12: n= | AC12: 10 | AI12: n= | AJ12: 10 | AP12: n= | AQ12: 10 | AW12: n= | AX12: 10 | BD12: n= | BE12: 10 | BK12: n= | BL12: 10 | BR12: n= | BS12: 10 | BY12: n= | BZ12: 10 | CF12: n= | CG12: 10
G13: cc= | H13: 1.5 | N13: cc= | O13: 1.5 | U13: cc= | V13: 1.5 | AB13: cc= | AC13: 1.5 | AI13: cc= | AJ13: 1.5 | AP13: cc= | AQ13: 1.5 | AW13: cc= | AX13: 1.5 | BD13: cc= | BE13: 1.5 | BK13: cc= | BL13: 1.5 | BR13: cc= | BS13: 1.5 | BY13: cc= | BZ13: 1.5 | CF13: cc= | CG13: 1.5
G14: Db= | H14: 10 | N14: Db= | O14: 10 | U14: Db= | V14: 10 | AB14: Db= | AC14: 10 | AI14: Db= | AJ14: 10 | AP14: Db= | AQ14: 10 | AW14: Db= | AX14: 10 | BD14: Db= | BE14: 10 | BK14: Db= | BL14: 10 | BR14: Db= | BS14: 10 | BY14: Db= | BZ14: 10 | CF14: Db= | CG14: 10
D16: Dia | E16: Main Bar | G16: Link Bar | I16: Total | K16: Concrete | BZ16: x
D17: 8 | E17: =IF(Calculation!W61=0,"",Calculation!W61) | G17: =IF(Calculation!Y61=0,"",Calculation!Y61) | I17: =IF(SUM(E17:H17)=0,"",SUM(E17:H17)) | K17: Cement= | M17: =Calculation!H87 -> 9.2 | N17: Bags
D18: 10 | E18: =IF(Calculation!W62=0,"",Calculation!W62) | G18: =IF(Calculation!Y62=0,"",Calculation!Y62) -> 32.166758 | I18: =IF(SUM(E18:H18)=0,"",SUM(E18:H18)) -> 32.166758 | K18: Sand= | M18: =Calculation!H88 -> 11.5 | N18: cft
D19: 12 | E19: =IF(Calculation!W63=0,"",Calculation!W63) -> 12.73854 | G19: =IF(Calculation!Y63=0,"",Calculation!Y63) | I19: =IF(SUM(E19:H19)=0,"",SUM(E19:H19)) -> 12.73854 | K19: Stone/Khoa= | M19: =Calculation!H89 -> 11.5 | N19: cft
D20: 14 | E20: =IF(Calculation!W64=0,"",Calculation!W64) | G20: =IF(Calculation!Y64=0,"",Calculation!Y64) | I20: =IF(SUM(E20:H20)=0,"",SUM(E20:H20))
D21: 16 | E21: =IF(Calculation!W65=0,"",Calculation!W65) -> 63.489592 | G21: =IF(Calculation!Y65=0,"",Calculation!Y65) | I21: =IF(SUM(E21:H21)=0,"",SUM(E21:H21)) -> 63.489592
D22: 18 | E22: =IF(Calculation!W66=0,"",Calculation!W66) | G22: =IF(Calculation!Y66=0,"",Calculation!Y66) | I22: =IF(SUM(E22:H22)=0,"",SUM(E22:H22))
D23: 20 | E23: =IF(Calculation!W67=0,"",Calculation!W67) | G23: =IF(Calculation!Y67=0,"",Calculation!Y67) | I23: =IF(SUM(E23:H23)=0,"",SUM(E23:H23))
D24: 22 | E24: =IF(Calculation!W68=0,"",Calculation!W68) | G24: =IF(Calculation!Y68=0,"",Calculation!Y68) | I24: =IF(SUM(E24:H24)=0,"",SUM(E24:H24))
D25: 25 | E25: =IF(Calculation!W69=0,"",Calculation!W69) | G25: =IF(Calculation!Y69=0,"",Calculation!Y69) | I25: =IF(SUM(E25:H25)=0,"",SUM(E25:H25))
D26: 28 | E26: =IF(Calculation!W70=0,"",Calculation!W70) | G26: =IF(Calculation!Y70=0,"",Calculation!Y70) | I26: =IF(SUM(E26:H26)=0,"",SUM(E26:H26))
D27: 32 | E27: =IF(Calculation!W71=0,"",Calculation!W71) | G27: =IF(Calculation!Y71=0,"",Calculation!Y71) | I27: =IF(SUM(E27:H27)=0,"",SUM(E27:H27))
H28: Total= | I28: =SUM(I17:J27) -> 108.39489

Sheet Beam Estimating
C4: Dia | D4: Total | E4: Total | F4: Total | G4: Total | H4: Total | I4: Total | J4: Total | K4: Total | L4: Total
C5: 8 | M5: =SUM(D5:L5) -> 0 | N5: kg
C6: 10 | D6: 39.905108 | E6: 39.905108 | F6: 44.074298 | G6: 14.889966 | H6: 14.889966 | I6: 53.008278 | J6: 53.008278 | K6: 53.008278 | L6: 17.27236 | M6: =SUM(D6:L6) -> 329.96164 | N6: kg
C7: 12 | D7: 17.466495 | E7: 17.466495 | F7: 17.961444 | G7: 6.7045883 | H7: 6.7045883 | I7: 21.519027 | J7: 21.519027 | K7: 21.519027 | L7: 7.8755001 | M7: =SUM(D7:L7) -> 138.73619 | N7: kg
C8: 14 | M8: =SUM(D8:L8) -> 0 | N8: kg
C9: 16 | D9: 86.093719 | E9: 86.093719 | F9: 89.04857 | G9: 34.038941 | H9: 34.038941 | I9: 106.09094 | J9: 106.09094 | K9: 106.09094 | L9: 39.58993 | M9: =SUM(D9:L9) -> 687.17665 | N9: kg
C10: 18 | M10: =SUM(D10:L10) -> 0 | N10: kg
C11: 20 | M11: =SUM(D11:L11) -> 0 | N11: kg
C12: 22 | M12: =SUM(D12:L12) -> 0 | N12: kg
C13: 25 | M13: =SUM(D13:L13) -> 0 | N13: kg
C14: 28 | M14: =SUM(D14:L14) -> 0 | N14: kg
C15: 32 | M15: =SUM(D15:L15) -> 0 | N15: kg
D16: 143.46532 | E16: 143.46532 | F16: 151.08431 | G16: 55.633495 | H16: 55.633495 | I16: 180.61825 | J16: 180.61825 | K16: 180.61825 | L16: 64.73779 | M16: =SUM(D16:L16) -> 1155.8745 | N16: kg

Sheet Calculation
B1: fy= | C1: ='Beam Estimating V1.1 (721.7.23)'!C1 -> 500 | D1: MPa
B2: f'c= | C2: ='Beam Estimating V1.1 (721.7.23)'!C2 -> 20 | D2: MPa | E2: =C1/(5.4*SQRT(C2)) -> 20.704333
D4: ='Beam Estimating V1.1 (721.7.23)'!D4 -> 0 | E4: ='Beam Estimating V1.1 (721.7.23)'!E4 -> 10 | F4: ='Beam Estimating V1.1 (721.7.23)'!F4 -> 0 | G4: ='Beam Estimating V1.1 (721.7.23)'!G4 -> 16 | H4: ='Beam Estimating V1.1 (721.7.23)'!H4 -> 0 | I4: ='Beam Estimating V1.1 (721.7.23)'!I4 -> 10 | K4: ='Beam Estimating V1.1 (721.7.23)'!K4 -> 0 | L4: ='Beam Estimating V1.1 (721.7.23)'!L4 -> 16 | M4: ='Beam Estimating V1.1 (721.7.23)'!M4 -> 0 | N4: ='Beam Estimating V1.1 (721.7.23)'!N4 -> 16 | O4: ='Beam Estimating V1.1 (721.7.23)'!O4 -> 0 | P4: ='Beam Estimating V1.1 (721.7.23)'!P4 -> 16 | R4: ='Beam Estimating V1.1 (721.7.23)'!R4 -> 0 | S4: ='Beam Estimating V1.1 (721.7.23)'!S4 -> 16 | T4: ='Beam Estimating V1.1 (721.7.23)'!T4 -> 0 | U4: ='Beam Estimating V1.1 (721.7.23)'!U4 -> 16 | V4: ='Beam Estimating V1.1 (721.7.23)'!V4 -> 0 | W4: ='Beam Estimating V1.1 (721.7.23)'!W4 -> 16 | Y4: ='Beam Estimating V1.1 (721.7.23)'!Y4 -> 0 | Z4: ='Beam Estimating V1.1 (721.7.23)'!Z4 -> 16 | AA4: ='Beam Estimating V1.1 (721.7.23)'!AA4 -> 1 | AB4: ='Beam Estimating V1.1 (721.7.23)'!AB4 -> 16 | AC4: ='Beam Estimating V1.1 (721.7.23)'!AC4 -> 0 | AD4: ='Beam Estimating V1.1 (721.7.23)'!AD4 -> 16 | AF4: ='Beam Estimating V1.1 (721.7.23)'!AF4 -> 1 | AG4: ='Beam Estimating V1.1 (721.7.23)'!AG4 -> 16 | AH4: ='Beam Estimating V1.1 (721.7.23)'!AH4 -> 1 | AI4: ='Beam Estimating V1.1 (721.7.23)'!AI4 -> 16 | AJ4: ='Beam Estimating V1.1 (721.7.23)'!AJ4 -> 1 | AK4: ='Beam Estimating V1.1 (721.7.23)'!AK4 -> 16 | AM4: ='Beam Estimating V1.1 (721.7.23)'!AM4 -> 1 | AN4: ='Beam Estimating V1.1 (721.7.23)'!AN4 -> 16 | AO4: ='Beam Estimating V1.1 (721.7.23)'!AO4 -> 1 | AP4: ='Beam Estimating V1.1 (721.7.23)'!AP4 -> 16 | AQ4: ='Beam Estimating V1.1 (721.7.23)'!AQ4 -> 1 | AR4: ='Beam Estimating V1.1 (721.7.23)'!AR4 -> 16 | AT4: ='Beam Estimating V1.1 (721.7.23)'!AT4 -> 1 | AU4: ='Beam Estimating V1.1 (721.7.23)'!AU4 -> 16 | AV4: ='Beam Estimating V1.1 (721.7.23)'!AV4 -> 1 | AW4: ='Beam Estimating V1.1 (721.7.23)'!AW4 -> 16 | AX4: ='Beam Estimating V1.1 (721.7.23)'!AX4 -> 1 | AY4: ='Beam Estimating V1.1 (721.7.23)'!AY4 -> 16 | BA4: ='Beam Estimating V1.1 (721.7.23)'!BA4 -> 1 | BB4: ='Beam Estimating V1.1 (721.7.23)'!BB4 -> 16 | BC4: ='Beam Estimating V1.1 (721.7.23)'!BC4 -> 1 | BD4: ='Beam Estimating V1.1 (721.7.23)'!BD4 -> 16 | BE4: ='Beam Estimating V1.1 (721.7.23)'!BE4 -> 1 | BF4: ='Beam Estimating V1.1 (721.7.23)'!BF4 -> 16 | BH4: ='Beam Estimating V1.1 (721.7.23)'!BH4 -> 1 | BI4: ='Beam Estimating V1.1 (721.7.23)'!BI4 -> 16 | BJ4: ='Beam Estimating V1.1 (721.7.23)'!BJ4 -> 1 | BK4: ='Beam Estimating V1.1 (721.7.23)'!BK4 -> 16 | BL4: ='Beam Estimating V1.1 (721.7.23)'!BL4 -> 1 | BM4: ='Beam Estimating V1.1 (721.7.23)'!BM4 -> 16 | BO4: ='Beam Estimating V1.1 (721.7.23)'!BO4 -> 1 | BP4: ='Beam Estimating V1.1 (721.7.23)'!BP4 -> 16 | BQ4: ='Beam Estimating V1.1 (721.7.23)'!BQ4 -> 1 | BR4: ='Beam Estimating V1.1 (721.7.23)'!BR4 -> 16 | BS4: ='Beam Estimating V1.1 (721.7.23)'!BS4 -> 1 | BT4: ='Beam Estimating V1.1 (721.7.23)'!BT4 -> 16 | BV4: ='Beam Estimating V1.1 (721.7.23)'!BV4 -> 1 | BW4: ='Beam Estimating V1.1 (721.7.23)'!BW4 -> 16 | BX4: ='Beam Estimating V1.1 (721.7.23)'!BX4 -> 1 | BY4: ='Beam Estimating V1.1 (721.7.23)'!BY4 -> 16 | BZ4: ='Beam Estimating V1.1 (721.7.23)'!BZ4 -> 1 | CA4: ='Beam Estimating V1.1 (721.7.23)'!CA4 -> 16 | CC4: ='Beam Estimating V1.1 (721.7.23)'!CC4 -> 1 | CD4: ='Beam Estimating V1.1 (721.7.23)'!CD4 -> 16 | CE4: ='Beam Estimating V1.1 (721.7.23)'!CE4 -> 1 | CF4: ='Beam Estimating V1.1 (721.7.23)'!CF4 -> 16 | CG4: ='Beam Estimating V1.1 (721.7.23)'!CG4 -> 1 | CH4: ='Beam Estimating V1.1 (721.7.23)'!CH4 -> 16
D5: ='Beam Estimating V1.1 (721.7.23)'!D5 -> 1 | E5: ='Beam Estimating V1.1 (721.7.23)'!E5 -> 16 | F5: ='Beam Estimating V1.1 (721.7.23)'!F5 -> 2 | G5: ='Beam Estimating V1.1 (721.7.23)'!G5 -> 16 | H5: ='Beam Estimating V1.1 (721.7.23)'!H5 -> 1 | I5: ='Beam Estimating V1.1 (721.7.23)'!I5 -> 16 | K5: ='Beam Estimating V1.1 (721.7.23)'!K5 -> 1 | L5: ='Beam Estimating V1.1 (721.7.23)'!L5 -> 16 | M5: ='Beam Estimating V1.1 (721.7.23)'!M5 -> 2 | N5: ='Beam Estimating V1.1 (721.7.23)'!N5 -> 16 | O5: ='Beam Estimating V1.1 (721.7.23)'!O5 -> 1 | P5: ='Beam Estimating V1.1 (721.7.23)'!P5 -> 16 | R5: ='Beam Estimating V1.1 (721.7.23)'!R5 -> 1 | S5: ='Beam Estimating V1.1 (721.7.23)'!S5 -> 16 | T5: ='Beam Estimating V1.1 (721.7.23)'!T5 -> 2 | U5: ='Beam Estimating V1.1 (721.7.23)'!U5 -> 16 | V5: ='Beam Estimating V1.1 (721.7.23)'!V5 -> 1 | W5: ='Beam Estimating V1.1 (721.7.23)'!W5 -> 16 | Y5: ='Beam Estimating V1.1 (721.7.23)'!Y5 -> 0 | Z5: ='Beam Estimating V1.1 (721.7.23)'!Z5 -> 16 | AA5: ='Beam Estimating V1.1 (721.7.23)'!AA5 -> 2 | AB5: ='Beam Estimating V1.1 (721.7.23)'!AB5 -> 16 | AC5: ='Beam Estimating V1.1 (721.7.23)'!AC5 -> 2 | AD5: ='Beam Estimating V1.1 (721.7.23)'!AD5 -> 16 | AF5: ='Beam Estimating V1.1 (721.7.23)'!AF5 -> 2 | AG5: ='Beam Estimating V1.1 (721.7.23)'!AG5 -> 16 | AH5: ='Beam Estimating V1.1 (721.7.23)'!AH5 -> 2 | AI5: ='Beam Estimating V1.1 (721.7.23)'!AI5 -> 16 | AJ5: ='Beam Estimating V1.1 (721.7.23)'!AJ5 -> 2 | AK5: ='Beam Estimating V1.1 (721.7.23)'!AK5 -> 16 | AM5: ='Beam Estimating V1.1 (721.7.23)'!AM5 -> 2 | AN5: ='Beam Estimating V1.1 (721.7.23)'!AN5 -> 16 | AO5: ='Beam Estimating V1.1 (721.7.23)'!AO5 -> 2 | AP5: ='Beam Estimating V1.1 (721.7.23)'!AP5 -> 16 | AQ5: ='Beam Estimating V1.1 (721.7.23)'!AQ5 -> 2 | AR5: ='Beam Estimating V1.1 (721.7.23)'!AR5 -> 16 | AT5: ='Beam Estimating V1.1 (721.7.23)'!AT5 -> 2 | AU5: ='Beam Estimating V1.1 (721.7.23)'!AU5 -> 16 | AV5: ='Beam Estimating V1.1 (721.7.23)'!AV5 -> 2 | AW5: ='Beam Estimating V1.1 (721.7.23)'!AW5 -> 16 | AX5: ='Beam Estimating V1.1 (721.7.23)'!AX5 -> 2 | AY5: ='Beam Estimating V1.1 (721.7.23)'!AY5 -> 16 | BA5: ='Beam Estimating V1.1 (721.7.23)'!BA5 -> 2 | BB5: ='Beam Estimating V1.1 (721.7.23)'!BB5 -> 16 | BC5: ='Beam Estimating V1.1 (721.7.23)'!BC5 -> 2 | BD5: ='Beam Estimating V1.1 (721.7.23)'!BD5 -> 16 | BE5: ='Beam Estimating V1.1 (721.7.23)'!BE5 -> 2 | BF5: ='Beam Estimating V1.1 (721.7.23)'!BF5 -> 16 | BH5: ='Beam Estimating V1.1 (721.7.23)'!BH5 -> 2 | BI5: ='Beam Estimating V1.1 (721.7.23)'!BI5 -> 16 | BJ5: ='Beam Estimating V1.1 (721.7.23)'!BJ5 -> 2 | BK5: ='Beam Estimating V1.1 (721.7.23)'!BK5 -> 16 | BL5: ='Beam Estimating V1.1 (721.7.23)'!BL5 -> 2 | BM5: ='Beam Estimating V1.1 (721.7.23)'!BM5 -> 16 | BO5: ='Beam Estimating V1.1 (721.7.23)'!BO5 -> 2 | BP5: ='Beam Estimating V1.1 (721.7.23)'!BP5 -> 16 | BQ5: ='Beam Estimating V1.1 (721.7.23)'!BQ5 -> 2 | BR5: ='Beam Estimating V1.1 (721.7.23)'!BR5 -> 16 | BS5: ='Beam Estimating V1.1 (721.7.23)'!BS5 -> 2 | BT5: ='Beam Estimating V1.1 (721.7.23)'!BT5 -> 16 | BV5: ='Beam Estimating V1.1 (721.7.23)'!BV5 -> 2 | BW5: ='Beam Estimating V1.1 (721.7.23)'!BW5 -> 16 | BX5: ='Beam Estimating V1.1 (721.7.23)'!BX5 -> 2 | BY5: ='Beam Estimating V1.1 (721.7.23)'!BY5 -> 16 | BZ5: ='Beam Estimating V1.1 (721.7.23)'!BZ5 -> 2 | CA5: ='Beam Estimating V1.1 (721.7.23)'!CA5 -> 16 | CC5: ='Beam Estimating V1.1 (721.7.23)'!CC5 -> 2 | CD5: ='Beam Estimating V1.1 (721.7.23)'!CD5 -> 16 | CE5: ='Beam Estimating V1.1 (721.7.23)'!CE5 -> 2 | CF5: ='Beam Estimating V1.1 (721.7.23)'!CF5 -> 16 | CG5: ='Beam Estimating V1.1 (721.7.23)'!CG5 -> 2 | CH5: ='Beam Estimating V1.1 (721.7.23)'!CH5 -> 16
C7: ='Beam Estimating V1.1 (721.7.23)'!C7 -> 12 | D7: ='Beam Estimating V1.1 (721.7.23)'!D7 -> 2 | E7: ='Beam Estimating V1.1 (721.7.23)'!E7 -> 16 | F7: ='Beam Estimating V1.1 (721.7.23)'!F7 -> 10 | H7: ='Beam Estimating V1.1 (721.7.23)'!H7 -> 1 | I7: ='Beam Estimating V1.1 (721.7.23)'!I7 -> 16 | J7: ='Beam Estimating V1.1 (721.7.23)'!J7 -> 12 | K7: ='Beam Estimating V1.1 (721.7.23)'!K7 -> 2 | L7: ='Beam Estimating V1.1 (721.7.23)'!L7 -> 16 | M7: ='Beam Estimating V1.1 (721.7.23)'!M7 -> 10 | O7: ='Beam Estimating V1.1 (721.7.23)'!O7 -> 1 | P7: ='Beam Estimating V1.1 (721.7.23)'!P7 -> 16 | Q7: ='Beam Estimating V1.1 (721.7.23)'!Q7 -> 12 | R7: ='Beam Estimating V1.1 (721.7.23)'!R7 -> 2 | S7: ='Beam Estimating V1.1 (721.7.23)'!S7 -> 16 | T7: ='Beam Estimating V1.1 (721.7.23)'!T7 -> 10 | V7: ='Beam Estimating V1.1 (721.7.23)'!V7 -> 1 | W7: ='Beam Estimating V1.1 (721.7.23)'!W7 -> 16 | X7: ='Beam Estimating V1.1 (721.7.23)'!X7 -> 12 | Y7: ='Beam Estimating V1.1 (721.7.23)'!Y7 -> 0 | Z7: ='Beam Estimating V1.1 (721.7.23)'!Z7 -> 16 | AA7: ='Beam Estimating V1.1 (721.7.23)'!AA7 -> 10 | AC7: ='Beam Estimating V1.1 (721.7.23)'!AC7 -> 2 | AD7: ='Beam Estimating V1.1 (721.7.23)'!AD7 -> 16 | AE7: ='Beam Estimating V1.1 (721.7.23)'!AE7 -> 12 | AF7: ='Beam Estimating V1.1 (721.7.23)'!AF7 -> 2 | AG7: ='Beam Estimating V1.1 (721.7.23)'!AG7 -> 16 | AH7: ='Beam Estimating V1.1 (721.7.23)'!AH7 -> 10 | AJ7: ='Beam Estimating V1.1 (721.7.23)'!AJ7 -> 2 | AK7: ='Beam Estimating V1.1 (721.7.23)'!AK7 -> 16 | AL7: ='Beam Estimating V1.1 (721.7.23)'!AL7 -> 12 | AM7: ='Beam Estimating V1.1 (721.7.23)'!AM7 -> 2 | AN7: ='Beam Estimating V1.1 (721.7.23)'!AN7 -> 16 | AO7: ='Beam Estimating V1.1 (721.7.23)'!AO7 -> 10 | AQ7: ='Beam Estimating V1.1 (721.7.23)'!AQ7 -> 2 | AR7: ='Beam Estimating V1.1 (721.7.23)'!AR7 -> 16 | AS7: ='Beam Estimating V1.1 (721.7.23)'!AS7 -> 12 | AT7: ='Beam Estimating V1.1 (721.7.23)'!AT7 -> 2 | AU7: ='Beam Estimating V1.1 (721.7.23)'!AU7 -> 16 | AV7: ='Beam Estimating V1.1 (721.7.23)'!AV7 -> 10 | AX7: ='Beam Estimating V1.1 (721.7.23)'!AX7 -> 2 | AY7: ='Beam Estimating V1.1 (721.7.23)'!AY7 -> 16 | AZ7: ='Beam Estimating V1.1 (721.7.23)'!AZ7 -> 12 | BA7: ='Beam Estimating V1.1 (721.7.23)'!BA7 -> 2 | BB7: ='Beam Estimating V1.1 (721.7.23)'!BB7 -> 16 | BC7: ='Beam Estimating V1.1 (721.7.23)'!BC7 -> 10 | BE7: ='Beam Estimating V1.1 (721.7.23)'!BE7 -> 2 | BF7: ='Beam Estimating V1.1 (721.7.23)'!BF7 -> 16 | BG7: ='Beam Estimating V1.1 (721.7.23)'!BG7 -> 12 | BH7: ='Beam Estimating V1.1 (721.7.23)'!BH7 -> 2 | BI7: ='Beam Estimating V1.1 (721.7.23)'!BI7 -> 16 | BJ7: ='Beam Estimating V1.1 (721.7.23)'!BJ7 -> 10 | BL7: ='Beam Estimating V1.1 (721.7.23)'!BL7 -> 2 | BM7: ='Beam Estimating V1.1 (721.7.23)'!BM7 -> 16 | BN7: ='Beam Estimating V1.1 (721.7.23)'!BN7 -> 12 | BO7: ='Beam Estimating V1.1 (721.7.23)'!BO7 -> 2 | BP7: ='Beam Estimating V1.1 (721.7.23)'!BP7 -> 16 | BQ7: ='Beam Estimating V1.1 (721.7.23)'!BQ7 -> 10 | BS7: ='Beam Estimating V1.1 (721.7.23)'!BS7 -> 2 | BT7: ='Beam Estimating V1.1 (721.7.23)'!BT7 -> 16 | BU7: ='Beam Estimating V1.1 (721.7.23)'!BU7 -> 12 | BV7: ='Beam Estimating V1.1 (721.7.23)'!BV7 -> 2 | BW7: ='Beam Estimating V1.1 (721.7.23)'!BW7 -> 16 | BX7: ='Beam Estimating V1.1 (721.7.23)'!BX7 -> 10 | BZ7: ='Beam Estimating V1.1 (721.7.23)'!BZ7 -> 2 | CA7: ='Beam Estimating V1.1 (721.7.23)'!CA7 -> 16 | CB7: ='Beam Estimating V1.1 (721.7.23)'!CB7 -> 12 | CC7: ='Beam Estimating V1.1 (721.7.23)'!CC7 -> 2 | CD7: ='Beam Estimating V1.1 (721.7.23)'!CD7 -> 16 | CE7: ='Beam Estimating V1.1 (721.7.23)'!CE7 -> 10 | CG7: ='Beam Estimating V1.1 (721.7.23)'!CG7 -> 2 | CH7: ='Beam Estimating V1.1 (721.7.23)'!CH7 -> 16 | CI7: ='Beam Estimating V1.1 (721.7.23)'!CI7 -> 12
D8: ='Beam Estimating V1.1 (721.7.23)'!D8 -> 2 | E8: ='Beam Estimating V1.1 (721.7.23)'!E8 -> 12 | H8: ='Beam Estimating V1.1 (721.7.23)'!H8 -> 0 | I8: ='Beam Estimating V1.1 (721.7.23)'!I8 -> 16 | K8: ='Beam Estimating V1.1 (721.7.23)'!K8 -> 2 | L8: ='Beam Estimating V1.1 (721.7.23)'!L8 -> 12 | O8: ='Beam Estimating V1.1 (721.7.23)'!O8 -> 0 | P8: ='Beam Estimating V1.1 (721.7.23)'!P8 -> 16 | R8: ='Beam Estimating V1.1 (721.7.23)'!R8 -> 2 | S8: ='Beam Estimating V1.1 (721.7.23)'!S8 -> 12 | V8: ='Beam Estimating V1.1 (721.7.23)'!V8 -> 0 | W8: ='Beam Estimating V1.1 (721.7.23)'!W8 -> 16 | Y8: ='Beam Estimating V1.1 (721.7.23)'!Y8 -> 0 | Z8: ='Beam Estimating V1.1 (721.7.23)'!Z8 -> 16 | AC8: ='Beam Estimating V1.1 (721.7.23)'!AC8 -> 1 | AD8: ='Beam Estimating V1.1 (721.7.23)'!AD8 -> 16 | AF8: ='Beam Estimating V1.1 (721.7.23)'!AF8 -> 1 | AG8: ='Beam Estimating V1.1 (721.7.23)'!AG8 -> 16 | AJ8: ='Beam Estimating V1.1 (721.7.23)'!AJ8 -> 1 | AK8: ='Beam Estimating V1.1 (721.7.23)'!AK8 -> 16 | AM8: ='Beam Estimating V1.1 (721.7.23)'!AM8 -> 1 | AN8: ='Beam Estimating V1.1 (721.7.23)'!AN8 -> 16 | AQ8: ='Beam Estimating V1.1 (721.7.23)'!AQ8 -> 1 | AR8: ='Beam Estimating V1.1 (721.7.23)'!AR8 -> 16 | AT8: ='Beam Estimating V1.1 (721.7.23)'!AT8 -> 1 | AU8: ='Beam Estimating V1.1 (721.7.23)'!AU8 -> 16 | AX8: ='Beam Estimating V1.1 (721.7.23)'!AX8 -> 1 | AY8: ='Beam Estimating V1.1 (721.7.23)'!AY8 -> 16 | BA8: ='Beam Estimating V1.1 (721.7.23)'!BA8 -> 1 | BB8: ='Beam Estimating V1.1 (721.7.23)'!BB8 -> 16 | BE8: ='Beam Estimating V1.1 (721.7.23)'!BE8 -> 1 | BF8: ='Beam Estimating V1.1 (721.7.23)'!BF8 -> 16 | BH8: ='Beam Estimating V1.1 (721.7.23)'!BH8 -> 1 | BI8: ='Beam Estimating V1.1 (721.7.23)'!BI8 -> 16 | BL8: ='Beam Estimating V1.1 (721.7.23)'!BL8 -> 1 | BM8: ='Beam Estimating V1.1 (721.7.23)'!BM8 -> 16 | BO8: ='Beam Estimating V1.1 (721.7.23)'!BO8 -> 1 | BP8: ='Beam Estimating V1.1 (721.7.23)'!BP8 -> 16 | BS8: ='Beam Estimating V1.1 (721.7.23)'!BS8 -> 1 | BT8: ='Beam Estimating V1.1 (721.7.23)'!BT8 -> 16 | BV8: ='Beam Estimating V1.1 (721.7.23)'!BV8 -> 1 | BW8: ='Beam Estimating V1.1 (721.7.23)'!BW8 -> 16 | BZ8: ='Beam Estimating V1.1 (721.7.23)'!BZ8 -> 1 | CA8: ='Beam Estimating V1.1 (721.7.23)'!CA8 -> 16 | CC8: ='Beam Estimating V1.1 (721.7.23)'!CC8 -> 1 | CD8: ='Beam Estimating V1.1 (721.7.23)'!CD8 -> 16 | CG8: ='Beam Estimating V1.1 (721.7.23)'!CG8 -> 1 | CH8: ='Beam Estimating V1.1 (721.7.23)'!CH8 -> 16
B12: Top ST= | D12: =F4*(F7+(12*G4/304.8)+MAX((8*G4/304.8),0.5,($E$2*G4/304.8))) -> 0 | E12: =G4 -> 16 | F12: =D12*E12*E12/533 -> 0 | G12: B= | H12: ='Beam Estimating V1.1 (721.7.23)'!H10 -> 12 | I12: Top ST= | K12: =M4*(M7+J7/12) -> 0 | L12: =N4 -> 16 | M12: =K12*L12*L12/533 -> 0 | N12: B= | O12: ='Beam Estimating V1.1 (721.7.23)'!O10 -> 12 | P12: Top ST= | R12: =T4*(T7+Q7/12) -> 0 | S12: =U4 -> 16 | T12: =R12*S12*S12/533 -> 0 | U12: B= | V12: ='Beam Estimating V1.1 (721.7.23)'!V10 -> 12 | W12: Top ST= | Y12: =AA4*(AA7+X7/12) -> 11 | Z12: =AB4 -> 16 | AA12: =Y12*Z12*Z12/533 -> 5.2833021 | AB12: B= | AC12: ='Beam Estimating V1.1 (721.7.23)'!AC10 -> 12 | AD12: Top ST= | AF12: =AH4*(AH7+AE7/12) -> 11 | AG12: =AI4 -> 16 | AH12: =AF12*AG12*AG12/533 -> 5.2833021 | AI12: B= | AJ12: ='Beam Estimating V1.1 (721.7.23)'!AJ10 -> 12 | AK12: Top ST= | AM12: =AO4*(AO7+AL7/12) -> 11 | AN12: =AP4 -> 16 | AO12: =AM12*AN12*AN12/533 -> 5.2833021 | AP12: B= | AQ12: ='Beam Estimating V1.1 (721.7.23)'!AQ10 -> 12 | AR12: Top ST= | AT12: =AV4*(AV7+AS7/12) -> 11 | AU12: =AW4 -> 16 | AV12: =AT12*AU12*AU12/533 -> 5.2833021 | AW12: B= | AX12: ='Beam Estimating V1.1 (721.7.23)'!AX10 -> 12 | AY12: Top ST= | BA12: =BC4*(BC7+AZ7/12) -> 11 | BB12: =BD4 -> 16 | BC12: =BA12*BB12*BB12/533 -> 5.2833021 | BD12: B= | BE12: ='Beam Estimating V1.1 (721.7.23)'!BE10 -> 12 | BF12: Top ST= | BH12: =BJ4*(BJ7+BG7/12) -> 11 | BI12: =BK4 -> 16 | BJ12: =BH12*BI12*BI12/533 -> 5.2833021 | BK12: B= | BL12: ='Beam Estimating V1.1 (721.7.23)'!BL10 -> 12 | BM12: Top ST= | BO12: =BQ4*(BQ7+BN7/12) -> 11 | BP12: =BR4 -> 16 | BQ12: =BO12*BP12*BP12/533 -> 5.2833021 | BR12: B= | BS12: ='Beam Estimating V1.1 (721.7.23)'!BS10 -> 12 | BT12: Top ST= | BV12: =BX4*(BX7+BU7/12) -> 11 | BW12: =BY4 -> 16 | BX12: =BV12*BW12*BW12/533 -> 5.2833021 | BY12: B= | BZ12: ='Beam Estimating V1.1 (721.7.23)'!BZ10 -> 12 | CA12: Top ST= | CC12: =CE4*(CE7+CB7/12) -> 11 | CD12: =CF4 -> 16 | CE12: =CC12*CD12*CD12/533 -> 5.2833021 | CF12: B= | CG12: ='Beam Estimating V1.1 (721.7.23)'!CG10 -> 12
B13: Top ST= | D13: =F5*(F7+(12*G5/304.8)+MAX((8*G5/304.8),0.5,($E$2*G5/304.8))) -> 23.433526 | E13: =G5 -> 16 | F13: =D13*E13*E13/533 -> 11.255127 | G13: H= | H13: ='Beam Estimating V1.1 (721.7.23)'!H11 -> 12 | I13: Top ST= | K13: =M5*(M7+J7/12) -> 22 | L13: =N5 -> 16 | M13: =K13*L13*L13/533 -> 10.566604 | N13: H= | O13: ='Beam Estimating V1.1 (721.7.23)'!O11 -> 12 | P13: Top ST= | R13: =T5*(T7+Q7/12) -> 22 | S13: =U5 -> 16 | T13: =R13*S13*S13/533 -> 10.566604 | U13: H= | V13: ='Beam Estimating V1.1 (721.7.23)'!V11 -> 12 | W13: Top ST= | Y13: =AA5*(AA7+X7/12) -> 22 | Z13: =AB5 -> 16 | AA13: =Y13*Z13*Z13/533 -> 10.566604 | AB13: H= | AC13: ='Beam Estimating V1.1 (721.7.23)'!AC11 -> 12 | AD13: Top ST= | AF13: =AH5*(AH7+AE7/12) -> 22 | AG13: =AI5 -> 16 | AH13: =AF13*AG13*AG13/533 -> 10.566604 | AI13: H= | AJ13: ='Beam Estimating V1.1 (721.7.23)'!AJ11 -> 12 | AK13: Top ST= | AM13: =AO5*(AO7+AL7/12) -> 22 | AN13: =AP5 -> 16 | AO13: =AM13*AN13*AN13/533 -> 10.566604 | AP13: H= | AQ13: ='Beam Estimating V1.1 (721.7.23)'!AQ11 -> 12 | AR13: Top ST= | AT13: =AV5*(AV7+AS7/12) -> 22 | AU13: =AW5 -> 16 | AV13: =AT13*AU13*AU13/533 -> 10.566604 | AW13: H= | AX13: ='Beam Estimating V1.1 (721.7.23)'!AX11 -> 12 | AY13: Top ST= | BA13: =BC5*(BC7+AZ7/12) -> 22 | BB13: =BD5 -> 16 | BC13: =BA13*BB13*BB13/533 -> 10.566604 | BD13: H= | BE13: ='Beam Estimating V1.1 (721.7.23)'!BE11 -> 12 | BF13: Top ST= | BH13: =BJ5*(BJ7+BG7/12) -> 22 | BI13: =BK5 -> 16 | BJ13: =BH13*BI13*BI13/533 -> 10.566604 | BK13: H= | BL13: ='Beam Estimating V1.1 (721.7.23)'!BL11 -> 12 | BM13: Top ST= | BO13: =BQ5*(BQ7+BN7/12) -> 22 | BP13: =BR5 -> 16 | BQ13: =BO13*BP13*BP13/533 -> 10.566604 | BR13: H= | BS13: ='Beam Estimating V1.1 (721.7.23)'!BS11 -> 12 | BT13: Top ST= | BV13: =BX5*(BX7+BU7/12) -> 22 | BW13: =BY5 -> 16 | BX13: =BV13*BW13*BW13/533 -> 10.566604 | BY13: H= | BZ13: ='Beam Estimating V1.1 (721.7.23)'!BZ11 -> 12 | CA13: Top ST= | CC13: =CE5*(CE7+CB7/12) -> 22 | CD13: =CF5 -> 16 | CE13: =CC13*CD13*CD13/533 -> 10.566604 | CF13: H= | CG13: ='Beam Estimating V1.1 (721.7.23)'!CG11 -> 12
B14: Btm ST= | D14: =D7*(F7+(12*E7/304.8)+MAX((8*E7/304.8),0.5,($E$2*E7/304.8))) -> 23.433526 | E14: =E7 -> 16 | F14: =D14*E14*E14/533 -> 11.255127 | G14: n= | H14: ='Beam Estimating V1.1 (721.7.23)'!H12 -> 29 | I14: Btm ST= | K14: =K7*(M7+J7/12) -> 22 | L14: =L7 -> 16 | M14: =K14*L14*L14/533 -> 10.566604 | N14: n= | O14: ='Beam Estimating V1.1 (721.7.23)'!O12 -> 28 | P14: Btm ST= | R14: =R7*(T7+Q7/12) -> 22 | S14: =S7 -> 16 | T14: =R14*S14*S14/533 -> 10.566604 | U14: n= | V14: ='Beam Estimating V1.1 (721.7.23)'!V12 -> 32 | W14: Btm ST= | Y14: =Y7*(AA7+X7/12) -> 0 | Z14: =Z7 -> 16 | AA14: =Y14*Z14*Z14/533 -> 0 | AB14: n= | AC14: ='Beam Estimating V1.1 (721.7.23)'!AC12 -> 10 | AD14: Btm ST= | AF14: =AF7*(AH7+AE7/12) -> 22 | AG14: =AG7 -> 16 | AH14: =AF14*AG14*AG14/533 -> 10.566604 | AI14: n= | AJ14: ='Beam Estimating V1.1 (721.7.23)'!AJ12 -> 10 | AK14: Btm ST= | AM14: =AM7*(AO7+AL7/12) -> 22 | AN14: =AN7 -> 16 | AO14: =AM14*AN14*AN14/533 -> 10.566604 | AP14: n= | AQ14: ='Beam Estimating V1.1 (721.7.23)'!AQ12 -> 10 | AR14: Btm ST= | AT14: =AT7*(AV7+AS7/12) -> 22 | AU14: =AU7 -> 16 | AV14: =AT14*AU14*AU14/533 -> 10.566604 | AW14: n= | AX14: ='Beam Estimating V1.1 (721.7.23)'!AX12 -> 10 | AY14: Btm ST= | BA14: =BA7*(BC7+AZ7/12) -> 22 | BB14: =BB7 -> 16 | BC14: =BA14*BB14*BB14/533 -> 10.566604 | BD14: n= | BE14: ='Beam Estimating V1.1 (721.7.23)'!BE12 -> 10 | BF14: Btm ST= | BH14: =BH7*(BJ7+BG7/12) -> 22 | BI14: =BI7 -> 16 | BJ14: =BH14*BI14*BI14/533 -> 10.566604 | BK14: n= | BL14: ='Beam Estimating V1.1 (721.7.23)'!BL12 -> 10 | BM14: Btm ST= | BO14: =BO7*(BQ7+BN7/12) -> 22 | BP14: =BP7 -> 16 | BQ14: =BO14*BP14*BP14/533 -> 10.566604 | BR14: n= | BS14: ='Beam Estimating V1.1 (721.7.23)'!BS12 -> 10 | BT14: Btm ST= | BV14: =BV7*(BX7+BU7/12) -> 22 | BW14: =BW7 -> 16 | BX14: =BV14*BW14*BW14/533 -> 10.566604 | BY14: n= | BZ14: ='Beam Estimating V1.1 (721.7.23)'!BZ12 -> 10 | CA14: Btm ST= | CC14: =CC7*(CE7+CB7/12) -> 22 | CD14: =CD7 -> 16 | CE14: =CC14*CD14*CD14/533 -> 10.566604 | CF14: n= | CG14: ='Beam Estimating V1.1 (721.7.23)'!CG12 -> 10
B15: Btm ST= | D15: =D8*(F7+(12*E8/304.8)+MAX((8*E8/304.8),0.5,($E$2*E8/304.8))) -> 22.575144 | E15: =E8 -> 12 | F15: =D15*E15*E15/533 -> 6.0991009 | G15: cc= | H15: ='Beam Estimating V1.1 (721.7.23)'!H13 -> 1.5 | I15: Btm ST= | K15: =K8*(M7+J7/12) -> 22 | L15: =L8 -> 12 | M15: =K15*L15*L15/533 -> 5.9437148 | N15: cc= | O15: ='Beam Estimating V1.1 (721.7.23)'!O13 -> 1.5 | P15: Btm ST= | R15: =R8*(T7+Q7/12) -> 22 | S15: =S8 -> 12 | T15: =R15*S15*S15/533 -> 5.9437148 | U15: cc= | V15: ='Beam Estimating V1.1 (721.7.23)'!V13 -> 1.5 | W15: Btm ST= | Y15: =Y8*(AA7+X7/12) -> 0 | Z15: =Z8 -> 16 | AA15: =Y15*Z15*Z15/533 -> 0 | AB15: cc= | AC15: ='Beam Estimating V1.1 (721.7.23)'!AC13 -> 1.5 | AD15: Btm ST= | AF15: =AF8*(AH7+AE7/12) -> 11 | AG15: =AG8 -> 16 | AH15: =AF15*AG15*AG15/533 -> 5.2833021 | AI15: cc= | AJ15: ='Beam Estimating V1.1 (721.7.23)'!AJ13 -> 1.5 | AK15: Btm ST= | AM15: =AM8*(AO7+AL7/12) -> 11 | AN15: =AN8 -> 16 | AO15: =AM15*AN15*AN15/533 -> 5.2833021 | AP15: cc= | AQ15: ='Beam Estimating V1.1 (721.7.23)'!AQ13 -> 1.5 | AR15: Btm ST= | AT15: =AT8*(AV7+AS7/12) -> 11 | AU15: =AU8 -> 16 | AV15: =AT15*AU15*AU15/533 -> 5.2833021 | AW15: cc= | AX15: ='Beam Estimating V1.1 (721.7.23)'!AX13 -> 1.5 | AY15: Btm ST= | BA15: =BA8*(BC7+AZ7/12) -> 11 | BB15: =BB8 -> 16 | BC15: =BA15*BB15*BB15/533 -> 5.2833021 | BD15: cc= | BE15: ='Beam Estimating V1.1 (721.7.23)'!BE13 -> 1.5 | BF15: Btm ST= | BH15: =BH8*(BJ7+BG7/12) -> 11 | BI15: =BI8 -> 16 | BJ15: =BH15*BI15*BI15/533 -> 5.2833021 | BK15: cc= | BL15: ='Beam Estimating V1.1 (721.7.23)'!BL13 -> 1.5 | BM15: Btm ST= | BO15: =BO8*(BQ7+BN7/12) -> 11 | BP15: =BP8 -> 16 | BQ15: =BO15*BP15*BP15/533 -> 5.2833021 | BR15: cc= | BS15: ='Beam Estimating V1.1 (721.7.23)'!BS13 -> 1.5 | BT15: Btm ST= | BV15: =BV8*(BX7+BU7/12) -> 11 | BW15: =BW8 -> 16 | BX15: =BV15*BW15*BW15/533 -> 5.2833021 | BY15: cc= | BZ15: ='Beam Estimating V1.1 (721.7.23)'!BZ13 -> 1.5 | CA15: Btm ST= | CC15: =CC8*(CE7+CB7/12) -> 11 | CD15: =CD8 -> 16 | CE15: =CC15*CD15*CD15/533 -> 5.2833021 | CF15: cc= | CG15: ='Beam Estimating V1.1 (721.7.23)'!CG13 -> 1.5
B16: Top L EXT= | D16: =D4*((F7/4)+(6*E4/(25.4*12))+(12*E4/304.8)+MAX((8*E4/304.8),0.5,($E$2*E4/304.8))) -> 0 | E16: =E4 -> 10 | F16: =D16*E16*E16/533 -> 0 | G16: Db= | H16: ='Beam Estimating V1.1 (721.7.23)'!H14 -> 10 | I16: Top L EXT= | K16: =K4*((M7/3)+(6*L4/(25.4*12))+(J7/12)) -> 0 | L16: =L4 -> 16 | M16: =K16*L16*L16/533 -> 0 | N16: Db= | O16: ='Beam Estimating V1.1 (721.7.23)'!O14 -> 10 | P16: Top L EXT= | R16: =R4*((T7/3)+(6*S4/(25.4*12))+(Q7/12)) -> 0 | S16: =S4 -> 16 | T16: =R16*S16*S16/533 -> 0 | U16: Db= | V16: ='Beam Estimating V1.1 (721.7.23)'!V14 -> 10 | W16: Top L EXT= | Y16: =Y4*((AA7/3)+(6*Z4/(25.4*12))+(X7/12)) -> 0 | Z16: =Z4 -> 16 | AA16: =Y16*Z16*Z16/533 -> 0 | AB16: Db= | AC16: ='Beam Estimating V1.1 (721.7.23)'!AC14 -> 10 | AD16: Top L EXT= | AF16: =AF4*((AH7/3)+(6*AG4/(25.4*12))+(AE7/12)) -> 4.648294 | AG16: =AG4 -> 16 | AH16: =AF16*AG16*AG16/533 -> 2.2325765 | AI16: Db= | AJ16: ='Beam Estimating V1.1 (721.7.23)'!AJ14 -> 10 | AK16: Top L EXT= | AM16: =AM4*((AO7/3)+(6*AN4/(25.4*12))+(AL7/12)) -> 4.648294 | AN16: =AN4 -> 16 | AO16: =AM16*AN16*AN16/533 -> 2.2325765 | AP16: Db= | AQ16: ='Beam Estimating V1.1 (721.7.23)'!AQ14 -> 10 | AR16: Top L EXT= | AT16: =AT4*((AV7/3)+(6*AU4/(25.4*12))+(AS7/12)) -> 4.648294 | AU16: =AU4 -> 16 | AV16: =AT16*AU16*AU16/533 -> 2.2325765 | AW16: Db= | AX16: ='Beam Estimating V1.1 (721.7.23)'!AX14 -> 10 | AY16: Top L EXT= | BA16: =BA4*((BC7/3)+(6*BB4/(25.4*12))+(AZ7/12)) -> 4.648294 | BB16: =BB4 -> 16 | BC16: =BA16*BB16*BB16/533 -> 2.2325765 | BD16: Db= | BE16: ='Beam Estimating V1.1 (721.7.23)'!BE14 -> 10 | BF16: Top L EXT= | BH16: =BH4*((BJ7/3)+(6*BI4/(25.4*12))+(BG7/12)) -> 4.648294 | BI16: =BI4 -> 16 | BJ16: =BH16*BI16*BI16/533 -> 2.2325765 | BK16: Db= | BL16: ='Beam Estimating V1.1 (721.7.23)'!BL14 -> 10 | BM16: Top L EXT= | BO16: =BO4*((BQ7/3)+(6*BP4/(25.4*12))+(BN7/12)) -> 4.648294 | BP16: =BP4 -> 16 | BQ16: =BO16*BP16*BP16/533 -> 2.2325765 | BR16: Db= | BS16: ='Beam Estimating V1.1 (721.7.23)'!BS14 -> 10 | BT16: Top L EXT= | BV16: =BV4*((BX7/3)+(6*BW4/(25.4*12))+(BU7/12)) -> 4.648294 | BW16: =BW4 -> 16 | BX16: =BV16*BW16*BW16/533 -> 2.2325765 | BY16: Db= | BZ16: ='Beam Estimating V1.1 (721.7.23)'!BZ14 -> 10 | CA16: Top L EXT= | CC16: =CC4*((CE7/3)+(6*CD4/(25.4*12))+(CB7/12)) -> 4.648294 | CD16: =CD4 -> 16 | CE16: =CC16*CD16*CD16/533 -> 2.2325765 | CF16: Db= | CG16: ='Beam Estimating V1.1 (721.7.23)'!CG14 -> 10
B17: Top L EXT= | D17: =D5*((F7/4)+(6*E5/(25.4*12))+(12*E5/304.8)+MAX((8*E5/304.8),0.5,($E$2*E5/304.8))) -> 4.5317235 | E17: =E5 -> 16 | F17: =D17*E17*E17/533 -> 2.1765877 | I17: Top L EXT= | K17: =K5*((M7/3)+(6*L5/(25.4*12))+(J7/12)) -> 4.648294 | L17: =L5 -> 16 | M17: =K17*L17*L17/533 -> 2.2325765 | P17: Top L EXT= | R17: =R5*((T7/3)+(6*S5/(25.4*12))+(Q7/12)) -> 4.648294 | S17: =S5 -> 16 | T17: =R17*S17*S17/533 -> 2.2325765 | W17: Top L EXT= | Y17: =Y5*((AA7/3)+(6*Z5/(25.4*12))+(X7/12)) -> 0 | Z17: =Z5 -> 16 | AA17: =Y17*Z17*Z17/533 -> 0 | AD17: Top L EXT= | AF17: =AF5*((AH7/3)+(6*AG5/(25.4*12))+(AE7/12)) -> 9.2965879 | AG17: =AG5 -> 16 | AH17: =AF17*AG17*AG17/533 -> 4.4651529 | AK17: Top L EXT= | AM17: =AM5*((AO7/3)+(6*AN5/(25.4*12))+(AL7/12)) -> 9.2965879 | AN17: =AN5 -> 16 | AO17: =AM17*AN17*AN17/533 -> 4.4651529 | AR17: Top L EXT= | AT17: =AT5*((AV7/3)+(6*AU5/(25.4*12))+(AS7/12)) -> 9.2965879 | AU17: =AU5 -> 16 | AV17: =AT17*AU17*AU17/533 -> 4.4651529 | AY17: Top L EXT= | BA17: =BA5*((BC7/3)+(6*BB5/(25.4*12))+(AZ7/12)) -> 9.2965879 | BB17: =BB5 -> 16 | BC17: =BA17*BB17*BB17/533 -> 4.4651529 | BF17: Top L EXT= | BH17: =BH5*((BJ7/3)+(6*BI5/(25.4*12))+(BG7/12)) -> 9.2965879 | BI17: =BI5 -> 16 | BJ17: =BH17*BI17*BI17/533 -> 4.4651529 | BM17: Top L EXT= | BO17: =BO5*((BQ7/3)+(6*BP5/(25.4*12))+(BN7/12)) -> 9.2965879 | BP17: =BP5 -> 16 | BQ17: =BO17*BP17*BP17/533 -> 4.4651529 | BT17: Top L EXT= | BV17: =BV5*((BX7/3)+(6*BW5/(25.4*12))+(BU7/12)) -> 9.2965879 | BW17: =BW5 -> 16 | BX17: =BV17*BW17*BW17/533 -> 4.4651529 | CA17: Top L EXT= | CC17: =CC5*((CE7/3)+(6*CD5/(25.4*12))+(CB7/12)) -> 9.2965879 | CD17: =CD5 -> 16 | CE17: =CC17*CD17*CD17/533 -> 4.4651529
B18: Top R EXT= | D18: =H4*((F7/3)+(6*I4/(25.4*12))) -> 0 | E18: =I4 -> 10 | F18: =D18*E18*E18/533 -> 0 | G18: L= | H18: =IF(F7=0,0,((2*(H12-(2*H15)))+(2*(H13-(2*H15)))+(2*(MAX(6*H16/25.4,3)))-(5*3*H16/25.4))*H14/12) -> 87.228346 | I18: Top R EXT= | K18: =O4*((M7/3)+(6*P4/(25.4*12))) -> 0 | L18: =P4 -> 16 | M18: =K18*L18*L18/533 -> 0 | N18: L= | O18: =IF(M7=0,0,((2*(O12-(2*O15)))+(2*(O13-(2*O15)))+(2*(MAX(6*O16/25.4,3)))-(5*3*O16/25.4))*O14/12) -> 84.220472 | P18: Top R EXT= | R18: =V4*((T7/3)+(6*W4/(25.4*12))) -> 0 | S18: =W4 -> 16 | T18: =R18*S18*S18/533 -> 0 | U18: L= | V18: =IF(T7=0,0,((2*(V12-(2*V15)))+(2*(V13-(2*V15)))+(2*(MAX(6*V16/25.4,3)))-(5*3*V16/25.4))*V14/12) -> 96.251969 | W18: Top R EXT= | Y18: =AC4*((AA7/3)+(6*AD4/(25.4*12))) -> 0 | Z18: =AD4 -> 16 | AA18: =Y18*Z18*Z18/533 -> 0 | AB18: L= | AC18: =IF(AA7=0,0,((2*(AC12-(2*AC15)))+(2*(AC13-(2*AC15)))+(2*(MAX(6*AC16/25.4,3)))-(5*3*AC16/25.4))*AC14/12) -> 30.07874 | AD18: Top R EXT= | AF18: =AJ4*((AH7/3)+(6*AK4/(25.4*12))) -> 3.648294 | AG18: =AK4 -> 16 | AH18: =AF18*AG18*AG18/533 -> 1.7522763 | AI18: L= | AJ18: =IF(AH7=0,0,((2*(AJ12-(2*AJ15)))+(2*(AJ13-(2*AJ15)))+(2*(MAX(6*AJ16/25.4,3)))-(5*3*AJ16/25.4))*AJ14/12) -> 30.07874 | AK18: Top R EXT= | AM18: =AQ4*((AO7/3)+(6*AR4/(25.4*12))) -> 3.648294 | AN18: =AR4 -> 16 | AO18: =AM18*AN18*AN18/533 -> 1.7522763 | AP18: L= | AQ18: =IF(AO7=0,0,((2*(AQ12-(2*AQ15)))+(2*(AQ13-(2*AQ15)))+(2*(MAX(6*AQ16/25.4,3)))-(5*3*AQ16/25.4))*AQ14/12) -> 30.07874 | AR18: Top R EXT= | AT18: =AX4*((AV7/3)+(6*AY4/(25.4*12))) -> 3.648294 | AU18: =AY4 -> 16 | AV18: =AT18*AU18*AU18/533 -> 1.7522763 | AW18: L= | AX18: =IF(AV7=0,0,((2*(AX12-(2*AX15)))+(2*(AX13-(2*AX15)))+(2*(MAX(6*AX16/25.4,3)))-(5*3*AX16/25.4))*AX14/12) -> 30.07874 | AY18: Top R EXT= | BA18: =BE4*((BC7/3)+(6*BF4/(25.4*12))) -> 3.648294 | BB18: =BF4 -> 16 | BC18: =BA18*BB18*BB18/533 -> 1.7522763 | BD18: L= | BE18: =IF(BC7=0,0,((2*(BE12-(2*BE15)))+(2*(BE13-(2*BE15)))+(2*(MAX(6*BE16/25.4,3)))-(5*3*BE16/25.4))*BE14/12) -> 30.07874 | BF18: Top R EXT= | BH18: =BL4*((BJ7/3)+(6*BM4/(25.4*12))) -> 3.648294 | BI18: =BM4 -> 16 | BJ18: =BH18*BI18*BI18/533 -> 1.7522763 | BK18: L= | BL18: =IF(BJ7=0,0,((2*(BL12-(2*BL15)))+(2*(BL13-(2*BL15)))+(2*(MAX(6*BL16/25.4,3)))-(5*3*BL16/25.4))*BL14/12) -> 30.07874 | BM18: Top R EXT= | BO18: =BS4*((BQ7/3)+(6*BT4/(25.4*12))) -> 3.648294 | BP18: =BT4 -> 16 | BQ18: =BO18*BP18*BP18/533 -> 1.7522763 | BR18: L= | BS18: =IF(BQ7=0,0,((2*(BS12-(2*BS15)))+(2*(BS13-(2*BS15)))+(2*(MAX(6*BS16/25.4,3)))-(5*3*BS16/25.4))*BS14/12) -> 30.07874 | BT18: Top R EXT= | BV18: =BZ4*((BX7/3)+(6*CA4/(25.4*12))) -> 3.648294 | BW18: =CA4 -> 16 | BX18: =BV18*BW18*BW18/533 -> 1.7522763 | BY18: L= | BZ18: =IF(BX7=0,0,((2*(BZ12-(2*BZ15)))+(2*(BZ13-(2*BZ15)))+(2*(MAX(6*BZ16/25.4,3)))-(5*3*BZ16/25.4))*BZ14/12) -> 30.07874 | CA18: Top R EXT= | CC18: =CG4*((CE7/3)+(6*CH4/(25.4*12))) -> 3.648294 | CD18: =CH4 -> 16 | CE18: =CC18*CD18*CD18/533 -> 1.7522763 | CF18: L= | CG18: =IF(CE7=0,0,((2*(CG12-(2*CG15)))+(2*(CG13-(2*CG15)))+(2*(MAX(6*CG16/25.4,3)))-(5*3*CG16/25.4))*CG14/12) -> 30.07874
B19: Top R EXT= | D19: =H5*((F7/3)+(6*I5/(25.4*12))) -> 3.648294 | E19: =I5 -> 16 | F19: =D19*E19*E19/533 -> 1.7522763 | I19: Top R EXT= | K19: =O5*((M7/3)+(6*P5/(25.4*12))) -> 3.648294 | L19: =P5 -> 16 | M19: =K19*L19*L19/533 -> 1.7522763 | P19: Top R EXT= | R19: =V5*((T7/3)+(6*W5/(25.4*12))) -> 3.648294 | S19: =W5 -> 16 | T19: =R19*S19*S19/533 -> 1.7522763 | W19: Top R EXT= | Y19: =AC5*((AA7/3)+(6*AD5/(25.4*12))) -> 7.2965879 | Z19: =AD5 -> 16 | AA19: =Y19*Z19*Z19/533 -> 3.5045526 | AD19: Top R EXT= | AF19: =AJ5*((AH7/3)+(6*AK5/(25.4*12))) -> 7.2965879 | AG19: =AK5 -> 16 | AH19: =AF19*AG19*AG19/533 -> 3.5045526 | AK19: Top R EXT= | AM19: =AQ5*((AO7/3)+(6*AR5/(25.4*12))) -> 7.2965879 | AN19: =AR5 -> 16 | AO19: =AM19*AN19*AN19/533 -> 3.5045526 | AR19: Top R EXT= | AT19: =AX5*((AV7/3)+(6*AY5/(25.4*12))) -> 7.2965879 | AU19: =AY5 -> 16 | AV19: =AT19*AU19*AU19/533 -> 3.5045526 | AY19: Top R EXT= | BA19: =BE5*((BC7/3)+(6*BF5/(25.4*12))) -> 7.2965879 | BB19: =BF5 -> 16 | BC19: =BA19*BB19*BB19/533 -> 3.5045526 | BF19: Top R EXT= | BH19: =BL5*((BJ7/3)+(6*BM5/(25.4*12))) -> 7.2965879 | BI19: =BM5 -> 16 | BJ19: =BH19*BI19*BI19/533 -> 3.5045526 | BM19: Top R EXT= | BO19: =BS5*((BQ7/3)+(6*BT5/(25.4*12))) -> 7.2965879 | BP19: =BT5 -> 16 | BQ19: =BO19*BP19*BP19/533 -> 3.5045526 | BT19: Top R EXT= | BV19: =BZ5*((BX7/3)+(6*CA5/(25.4*12))) -> 7.2965879 | BW19: =CA5 -> 16 | BX19: =BV19*BW19*BW19/533 -> 3.5045526 | CA19: Top R EXT= | CC19: =CG5*((CE7/3)+(6*CH5/(25.4*12))) -> 7.2965879 | CD19: =CH5 -> 16 | CE19: =CC19*CD19*CD19/533 -> 3.5045526
B20: Btm EXT= | D20: =H7*(F7-(2*F7/8)+(2*6*I7/(25.4*12))) -> 8.1299213 | E20: =I7 -> 16 | F20: =D20*E20*E20/533 -> 3.9048027 | I20: Btm EXT= | K20: =O7*(M7-(2*M7/8)+(2*6*P7/(25.4*12))) -> 8.1299213 | L20: =P7 -> 16 | M20: =K20*L20*L20/533 -> 3.9048027 | P20: Btm EXT= | R20: =V7*(T7-(2*T7/8)+(2*6*W7/(25.4*12))) -> 8.1299213 | S20: =W7 -> 16 | T20: =R20*S20*S20/533 -> 3.9048027 | W20: Btm EXT= | Y20: =AC7*(AA7-(2*AA7/8)+(2*6*AD7/(25.4*12))) -> 16.259843 | Z20: =AD7 -> 16 | AA20: =Y20*Z20*Z20/533 -> 7.8096054 | AD20: Btm EXT= | AF20: =AJ7*(AH7-(2*AH7/8)+(2*6*AK7/(25.4*12))) -> 16.259843 | AG20: =AK7 -> 16 | AH20: =AF20*AG20*AG20/533 -> 7.8096054 | AK20: Btm EXT= | AM20: =AQ7*(AO7-(2*AO7/8)+(2*6*AR7/(25.4*12))) -> 16.259843 | AN20: =AR7 -> 16 | AO20: =AM20*AN20*AN20/533 -> 7.8096054 | AR20: Btm EXT= | AT20: =AX7*(AV7-(2*AV7/8)+(2*6*AY7/(25.4*12))) -> 16.259843 | AU20: =AY7 -> 16 | AV20: =AT20*AU20*AU20/533 -> 7.8096054 | AY20: Btm EXT= | BA20: =BE7*(BC7-(2*BC7/8)+(2*6*BF7/(25.4*12))) -> 16.259843 | BB20: =BF7 -> 16 | BC20: =BA20*BB20*BB20/533 -> 7.8096054 | BF20: Btm EXT= | BH20: =BL7*(BJ7-(2*BJ7/8)+(2*6*BM7/(25.4*12))) -> 16.259843 | BI20: =BM7 -> 16 | BJ20: =BH20*BI20*BI20/533 -> 7.8096054 | BM20: Btm EXT= | BO20: =BS7*(BQ7-(2*BQ7/8)+(2*6*BT7/(25.4*12))) -> 16.259843 | BP20: =BT7 -> 16 | BQ20: =BO20*BP20*BP20/533 -> 7.8096054 | BT20: Btm EXT= | BV20: =BZ7*(BX7-(2*BX7/8)+(2*6*CA7/(25.4*12))) -> 16.259843 | BW20: =CA7 -> 16 | BX20: =BV20*BW20*BW20/533 -> 7.8096054 | CA20: Btm EXT= | CC20: =CG7*(CE7-(2*CE7/8)+(2*6*CH7/(25.4*12))) -> 16.259843 | CD20: =CH7 -> 16 | CE20: =CC20*CD20*CD20/533 -> 7.8096054
B21: Btm EXT= | D21: =H8*(F7-(2*F7/8)+(2*6*I8/(25.4*12))) -> 0 | E21: =I8 -> 16 | F21: =D21*E21*E21/533 -> 0 | I21: Btm EXT= | K21: =O8*(M7-(2*M7/8)+(2*6*P8/(25.4*12))) -> 0 | L21: =P8 -> 16 | M21: =K21*L21*L21/533 -> 0 | P21: Btm EXT= | R21: =V8*(T7-(2*T7/8)+(2*6*W8/(25.4*12))) -> 0 | S21: =W8 -> 16 | T21: =R21*S21*S21/533 -> 0 | W21: Btm EXT= | Y21: =AC8*(AA7-(2*AA7/8)+(2*6*AD8/(25.4*12))) -> 8.1299213 | Z21: =AD8 -> 16 | AA21: =Y21*Z21*Z21/533 -> 3.9048027 | AD21: Btm EXT= | AF21: =AJ8*(AH7-(2*AH7/8)+(2*6*AK8/(25.4*12))) -> 8.1299213 | AG21: =AK8 -> 16 | AH21: =AF21*AG21*AG21/533 -> 3.9048027 | AK21: Btm EXT= | AM21: =AQ8*(AO7-(2*AO7/8)+(2*6*AR8/(25.4*12))) -> 8.1299213 | AN21: =AR8 -> 16 | AO21: =AM21*AN21*AN21/533 -> 3.9048027 | AR21: Btm EXT= | AT21: =AX8*(AV7-(2*AV7/8)+(2*6*AY8/(25.4*12))) -> 8.1299213 | AU21: =AY8 -> 16 | AV21: =AT21*AU21*AU21/533 -> 3.9048027 | AY21: Btm EXT= | BA21: =BE8*(BC7-(2*BC7/8)+(2*6*BF8/(25.4*12))) -> 8.1299213 | BB21: =BF8 -> 16 | BC21: =BA21*BB21*BB21/533 -> 3.9048027 | BF21: Btm EXT= | BH21: =BL8*(BJ7-(2*BJ7/8)+(2*6*BM8/(25.4*12))) -> 8.1299213 | BI21: =BM8 -> 16 | BJ21: =BH21*BI21*BI21/533 -> 3.9048027 | BM21: Btm EXT= | BO21: =BS8*(BQ7-(2*BQ7/8)+(2*6*BT8/(25.4*12))) -> 8.1299213 | BP21: =BT8 -> 16 | BQ21: =BO21*BP21*BP21/533 -> 3.9048027 | BT21: Btm EXT= | BV21: =BZ8*(BX7-(2*BX7/8)+(2*6*CA8/(25.4*12))) -> 8.1299213 | BW21: =CA8 -> 16 | BX21: =BV21*BW21*BW21/533 -> 3.9048027 | CA21: Btm EXT= | CC21: =CG8*(CE7-(2*CE7/8)+(2*6*CH8/(25.4*12))) -> 8.1299213 | CD21: =CH8 -> 16 | CE21: =CC21*CD21*CD21/533 -> 3.9048027
K22: 1 | R22: 2 | Y22: 3 | AF22: 4 | AM22: 5 | AT22: 6 | BA22: 7 | BH22: 8 | BO22: 9 | BV22: 10 | CC22: 11 | CJ22: 12
H23: Top ST= | J23: =F4*((12*G4/304.8)+MAX((8*G4/304.8),0.5,($E$2*G4/304.8))) -> 0 | K23: =IF($E$44=K22,G4,0) -> 0 | L23: =IF($E$44=K22,(J23*K23*K23/533),0) -> 0 | O23: Top ST= | Q23: =M4*((12*N4/304.8)+MAX((8*N4/304.8),0.5,($E$2*N4/304.8))) -> 0 | R23: =IF($E$44=R22,N4,0) -> 16 | S23: =IF($E$44=R22,(Q23*R23*R23/533),0) -> 0 | V23: Top ST= | X23: =T4*((12*U4/304.8)+MAX((8*U4/304.8),0.5,($E$2*U4/304.8))) -> 0 | Y23: =IF($E$44=Y22,U4,0) -> 0 | Z23: =IF($E$44=Y22,(X23*Y23*Y23/533),0) -> 0 | AC23: Top ST= | AE23: =AA4*((12*AB4/304.8)+MAX((8*AB4/304.8),0.5,($E$2*AB4/304.8))) -> 1.7167629 | AF23: =IF($E$44=AF22,AB4,0) -> 0 | AG23: =IF($E$44=AF22,(AE23*AF23*AF23/533),0) -> 0 | AJ23: Top ST= | AL23: =AH4*((12*AI4/304.8)+MAX((8*AI4/304.8),0.5,($E$2*AI4/304.8))) -> 1.7167629 | AM23: =IF($E$44=AM22,AI4,0) -> 0 | AN23: =IF($E$44=AM22,(AL23*AM23*AM23/533),0) -> 0 | AQ23: Top ST= | AS23: =AO4*((12*AP4/304.8)+MAX((8*AP4/304.8),0.5,($E$2*AP4/304.8))) -> 1.7167629 | AT23: =IF($E$44=AT22,AP4,0) -> 0 | AU23: =IF($E$44=AT22,(AS23*AT23*AT23/533),0) -> 0 | AX23: Top ST= | AZ23: =AV4*((12*AW4/304.8)+MAX((8*AW4/304.8),0.5,($E$2*AW4/304.8))) -> 1.7167629 | BA23: =IF($E$44=BA22,AW4,0) -> 0 | BB23: =IF($E$44=BA22,(AZ23*BA23*BA23/533),0) -> 0 | BE23: Top ST= | BG23: =BC4*((12*BD4/304.8)+MAX((8*BD4/304.8),0.5,($E$2*BD4/304.8))) -> 1.7167629 | BH23: =IF($E$44=BH22,BD4,0) -> 0 | BI23: =IF($E$44=BH22,(BG23*BH23*BH23/533),0) -> 0 | BL23: Top ST= | BN23: =BJ4*((12*BK4/304.8)+MAX((8*BK4/304.8),0.5,($E$2*BK4/304.8))) -> 1.7167629 | BO23: =IF($E$44=BO22,BK4,0) -> 0 | BP23: =IF($E$44=BO22,(BN23*BO23*BO23/533),0) -> 0 | BS23: Top ST= | BU23: =BQ4*((12*BR4/304.8)+MAX((8*BR4/304.8),0.5,($E$2*BR4/304.8))) -> 1.7167629 | BV23: =IF($E$44=BV22,BR4,0) -> 0 | BW23: =IF($E$44=BV22,(BU23*BV23*BV23/533),0) -> 0 | BZ23: Top ST= | CB23: =BX4*((12*BY4/304.8)+MAX((8*BY4/304.8),0.5,($E$2*BY4/304.8))) -> 1.7167629 | CC23: =IF($E$44=CC22,BY4,0) -> 0 | CD23: =IF($E$44=CC22,(CB23*CC23*CC23/533),0) -> 0 | CG23: Top ST= | CI23: =CE4*((12*CF4/304.8)+MAX((8*CF4/304.8),0.5,($E$2*CF4/304.8))) -> 1.7167629 | CJ23: =IF($E$44=CJ22,CF4,0) -> 0 | CK23: =IF($E$44=CJ22,(CI23*CJ23*CJ23/533),0) -> 0 | CL23: =SUM(CJ23,CC23,BV23,BO23,BH23,BA23,AT23,AM23,AF23,Y23,R23,K23) -> 16 | CM23: =SUM(CK23,CD23,BW23,BP23,BI23,BB23,AU23,AN23,AG23,Z23,S23,L23) -> 0
H24: Top ST= | J24: =F5*((12*G5/304.8)+MAX((8*G5/304.8),0.5,($E$2*G5/304.8))) -> 3.4335258 | K24: =IF($E$44=K22,G5,0) -> 0 | L24: =IF($E$44=K22,(J24*K24*K24/533),0) -> 0 | O24: Top ST= | Q24: =M5*((12*N5/304.8)+MAX((8*N5/304.8),0.5,($E$2*N5/304.8))) -> 3.4335258 | R24: =IF($E$44=R22,N5,0) -> 16 | S24: =IF($E$44=R22,(Q24*R24*R24/533),0) -> 1.6491231 | V24: Top ST= | X24: =T5*((12*U5/304.8)+MAX((8*U5/304.8),0.5,($E$2*U5/304.8))) -> 3.4335258 | Y24: =IF($E$44=Y22,U5,0) -> 0 | Z24: =IF($E$44=Y22,(X24*Y24*Y24/533),0) -> 0 | AC24: Top ST= | AE24: =AA5*((12*AB5/304.8)+MAX((8*AB5/304.8),0.5,($E$2*AB5/304.8))) -> 3.4335258 | AF24: =IF($E$44=AF22,AB5,0) -> 0 | AG24: =IF($E$44=AF22,(AE24*AF24*AF24/533),0) -> 0 | AJ24: Top ST= | AL24: =AH5*((12*AI5/304.8)+MAX((8*AI5/304.8),0.5,($E$2*AI5/304.8))) -> 3.4335258 | AM24: =IF($E$44=AM22,AI5,0) -> 0 | AN24: =IF($E$44=AM22,(AL24*AM24*AM24/533),0) -> 0 | AQ24: Top ST= | AS24: =AO5*((12*AP5/304.8)+MAX((8*AP5/304.8),0.5,($E$2*AP5/304.8))) -> 3.4335258 | AT24: =IF($E$44=AT22,AP5,0) -> 0 | AU24: =IF($E$44=AT22,(AS24*AT24*AT24/533),0) -> 0 | AX24: Top ST= | AZ24: =AV5*((12*AW5/304.8)+MAX((8*AW5/304.8),0.5,($E$2*AW5/304.8))) -> 3.4335258 | BA24: =IF($E$44=BA22,AW5,0) -> 0 | BB24: =IF($E$44=BA22,(AZ24*BA24*BA24/533),0) -> 0 | BE24: Top ST= | BG24: =BC5*((12*BD5/304.8)+MAX((8*BD5/304.8),0.5,($E$2*BD5/304.8))) -> 3.4335258 | BH24: =IF($E$44=BH22,BD5,0) -> 0 | BI24: =IF($E$44=BH22,(BG24*BH24*BH24/533),0) -> 0 | BL24: Top ST= | BN24: =BJ5*((12*BK5/304.8)+MAX((8*BK5/304.8),0.5,($E$2*BK5/304.8))) -> 3.4335258 | BO24: =IF($E$44=BO22,BK5,0) -> 0 | BP24: =IF($E$44=BO22,(BN24*BO24*BO24/533),0) -> 0 | BS24: Top ST= | BU24: =BQ5*((12*BR5/304.8)+MAX((8*BR5/304.8),0.5,($E$2*BR5/304.8))) -> 3.4335258 | BV24: =IF($E$44=BV22,BR5,0) -> 0 | BW24: =IF($E$44=BV22,(BU24*BV24*BV24/533),0) -> 0 | BZ24: Top ST= | CB24: =BX5*((12*BY5/304.8)+MAX((8*BY5/304.8),0.5,($E$2*BY5/304.8))) -> 3.4335258 | CC24: =IF($E$44=CC22,BY5,0) -> 0 | CD24: =IF($E$44=CC22,(CB24*CC24*CC24/533),0) -> 0 | CG24: Top ST= | CI24: =CE5*((12*CF5/304.8)+MAX((8*CF5/304.8),0.5,($E$2*CF5/304.8))) -> 3.4335258 | CJ24: =IF($E$44=CJ22,CF5,0) -> 0 | CK24: =IF($E$44=CJ22,(CI24*CJ24*CJ24/533),0) -> 0 | CL24: =SUM(CJ24,CC24,BV24,BO24,BH24,BA24,AT24,AM24,AF24,Y24,R24,K24) -> 16 | CM24: =SUM(CK24,CD24,BW24,BP24,BI24,BB24,AU24,AN24,AG24,Z24,S24,L24) -> 1.6491231
H25: Btm ST= | J25: =D7*((12*E7/304.8)+MAX((8*E7/304.8),0.5,($E$2*E7/304.8))) -> 3.4335258 | K25: =IF($E$44=K22,E7,0) -> 0 | L25: =IF($E$44=K22,(J25*K25*K25/533),0) -> 0 | O25: Btm ST= | Q25: =K7*((12*L7/304.8)+MAX((8*L7/304.8),0.5,($E$2*L7/304.8))) -> 3.4335258 | R25: =IF($E$44=R22,L7,0) -> 16 | S25: =IF($E$44=R22,(Q25*R25*R25/533),0) -> 1.6491231 | V25: Btm ST= | X25: =R7*((12*S7/304.8)+MAX((8*S7/304.8),0.5,($E$2*S7/304.8))) -> 3.4335258 | Y25: =IF($E$44=Y22,S7,0) -> 0 | Z25: =IF($E$44=Y22,(X25*Y25*Y25/533),0) -> 0 | AC25: Btm ST= | AE25: =Y7*((12*Z7/304.8)+MAX((8*Z7/304.8),0.5,($E$2*Z7/304.8))) -> 0 | AF25: =IF($E$44=AF22,Z7,0) -> 0 | AG25: =IF($E$44=AF22,(AE25*AF25*AF25/533),0) -> 0 | AJ25: Btm ST= | AL25: =AF7*((12*AG7/304.8)+MAX((8*AG7/304.8),0.5,($E$2*AG7/304.8))) -> 3.4335258 | AM25: =IF($E$44=AM22,AG7,0) -> 0 | AN25: =IF($E$44=AM22,(AL25*AM25*AM25/533),0) -> 0 | AQ25: Btm ST= | AS25: =AM7*((12*AN7/304.8)+MAX((8*AN7/304.8),0.5,($E$2*AN7/304.8))) -> 3.4335258 | AT25: =IF($E$44=AT22,AN7,0) -> 0 | AU25: =IF($E$44=AT22,(AS25*AT25*AT25/533),0) -> 0 | AX25: Btm ST= | AZ25: =AT7*((12*AU7/304.8)+MAX((8*AU7/304.8),0.5,($E$2*AU7/304.8))) -> 3.4335258 | BA25: =IF($E$44=BA22,AU7,0) -> 0 | BB25: =IF($E$44=BA22,(AZ25*BA25*BA25/533),0) -> 0 | BE25: Btm ST= | BG25: =BA7*((12*BB7/304.8)+MAX((8*BB7/304.8),0.5,($E$2*BB7/304.8))) -> 3.4335258 | BH25: =IF($E$44=BH22,BB7,0) -> 0 | BI25: =IF($E$44=BH22,(BG25*BH25*BH25/533),0) -> 0 | BL25: Btm ST= | BN25: =BH7*((12*BI7/304.8)+MAX((8*BI7/304.8),0.5,($E$2*BI7/304.8))) -> 3.4335258 | BO25: =IF($E$44=BO22,BI7,0) -> 0 | BP25: =IF($E$44=BO22,(BN25*BO25*BO25/533),0) -> 0 | BS25: Btm ST= | BU25: =BO7*((12*BP7/304.8)+MAX((8*BP7/304.8),0.5,($E$2*BP7/304.8))) -> 3.4335258 | BV25: =IF($E$44=BV22,BP7,0) -> 0 | BW25: =IF($E$44=BV22,(BU25*BV25*BV25/533),0) -> 0 | BZ25: Btm ST= | CB25: =BV7*((12*BW7/304.8)+MAX((8*BW7/304.8),0.5,($E$2*BW7/304.8))) -> 3.4335258 | CC25: =IF($E$44=CC22,BW7,0) -> 0 | CD25: =IF($E$44=CC22,(CB25*CC25*CC25/533),0) -> 0 | CG25: Btm ST= | CI25: =CC7*((12*CD7/304.8)+MAX((8*CD7/304.8),0.5,($E$2*CD7/304.8))) -> 3.4335258 | CJ25: =IF($E$44=CJ22,CD7,0) -> 0 | CK25: =IF($E$44=CJ22,(CI25*CJ25*CJ25/533),0) -> 0 | CL25: =SUM(CJ25,CC25,BV25,BO25,BH25,BA25,AT25,AM25,AF25,Y25,R25,K25) -> 16 | CM25: =SUM(CK25,CD25,BW25,BP25,BI25,BB25,AU25,AN25,AG25,Z25,S25,L25) -> 1.6491231
H26: Btm ST= | J26: =D8*((12*E8/304.8)+MAX((8*E8/304.8),0.5,($E$2*E8/304.8))) -> 2.5751443 | K26: =IF($E$44=K22,E8,0) -> 0 | L26: =IF($E$44=K22,(J26*K26*K26/533),0) -> 0 | O26: Btm ST= | Q26: =K8*((12*L8/304.8)+MAX((8*L8/304.8),0.5,($E$2*L8/304.8))) -> 2.5751443 | R26: =IF($E$44=R22,L8,0) -> 12 | S26: =IF($E$44=R22,(Q26*R26*R26/533),0) -> 0.6957238 | V26: Btm ST= | X26: =R8*((12*S8/304.8)+MAX((8*S8/304.8),0.5,($E$2*S8/304.8))) -> 2.5751443 | Y26: =IF($E$44=Y22,S8,0) -> 0 | Z26: =IF($E$44=Y22,(X26*Y26*Y26/533),0) -> 0 | AC26: Btm ST= | AE26: =Y8*((12*Z8/304.8)+MAX((8*Z8/304.8),0.5,($E$2*Z8/304.8))) -> 0 | AF26: =IF($E$44=AF22,Z8,0) -> 0 | AG26: =IF($E$44=AF22,(AE26*AF26*AF26/533),0) -> 0 | AJ26: Btm ST= | AL26: =AF8*((12*AG8/304.8)+MAX((8*AG8/304.8),0.5,($E$2*AG8/304.8))) -> 1.7167629 | AM26: =IF($E$44=AM22,AG8,0) -> 0 | AN26: =IF($E$44=AM22,(AL26*AM26*AM26/533),0) -> 0 | AQ26: Btm ST= | AS26: =AM8*((12*AN8/304.8)+MAX((8*AN8/304.8),0.5,($E$2*AN8/304.8))) -> 1.7167629 | AT26: =IF($E$44=AT22,AN8,0) -> 0 | AU26: =IF($E$44=AT22,(AS26*AT26*AT26/533),0) -> 0 | AX26: Btm ST= | AZ26: =AT8*((12*AU8/304.8)+MAX((8*AU8/304.8),0.5,($E$2*AU8/304.8))) -> 1.7167629 | BA26: =IF($E$44=BA22,AU8,0) -> 0 | BB26: =IF($E$44=BA22,(AZ26*BA26*BA26/533),0) -> 0 | BE26: Btm ST= | BG26: =BA8*((12*BB8/304.8)+MAX((8*BB8/304.8),0.5,($E$2*BB8/304.8))) -> 1.7167629 | BH26: =IF($E$44=BH22,BB8,0) -> 0 | BI26: =IF($E$44=BH22,(BG26*BH26*BH26/533),0) -> 0 | BL26: Btm ST= | BN26: =BH8*((12*BI8/304.8)+MAX((8*BI8/304.8),0.5,($E$2*BI8/304.8))) -> 1.7167629 | BO26: =IF($E$44=BO22,BI8,0) -> 0 | BP26: =IF($E$44=BO22,(BN26*BO26*BO26/533),0) -> 0 | BS26: Btm ST= | BU26: =BO8*((12*BP8/304.8)+MAX((8*BP8/304.8),0.5,($E$2*BP8/304.8))) -> 1.7167629 | BV26: =IF($E$44=BV22,BP8,0) -> 0 | BW26: =IF($E$44=BV22,(BU26*BV26*BV26/533),0) -> 0 | BZ26: Btm ST= | CB26: =BV8*((12*BW8/304.8)+MAX((8*BW8/304.8),0.5,($E$2*BW8/304.8))) -> 1.7167629 | CC26: =IF($E$44=CC22,BW8,0) -> 0 | CD26: =IF($E$44=CC22,(CB26*CC26*CC26/533),0) -> 0 | CG26: Btm ST= | CI26: =CC8*((12*CD8/304.8)+MAX((8*CD8/304.8),0.5,($E$2*CD8/304.8))) -> 1.7167629 | CJ26: =IF($E$44=CJ22,CD8,0) -> 0 | CK26: =IF($E$44=CJ22,(CI26*CJ26*CJ26/533),0) -> 0 | CL26: =SUM(CJ26,CC26,BV26,BO26,BH26,BA26,AT26,AM26,AF26,Y26,R26,K26) -> 12 | CM26: =SUM(CK26,CD26,BW26,BP26,BI26,BB26,AU26,AN26,AG26,Z26,S26,L26) -> 0.6957238
H27: Top L EXT= | J27: =H4*((12*I4/304.8)+MAX((8*I4/304.8),0.5,($E$2*I4/304.8))) -> 0 | K27: =IF($E$44=K22,I4,0) -> 0 | L27: =IF($E$44=K22,(J27*K27*K27/533),0) -> 0 | O27: Top L EXT= | Q27: =O4*((12*P4/304.8)+MAX((8*P4/304.8),0.5,($E$2*P4/304.8))) -> 0 | R27: =IF($E$44=R22,P4,0) -> 16 | S27: =IF($E$44=R22,(Q27*R27*R27/533),0) -> 0 | V27: Top L EXT= | X27: =V4*((12*W4/304.8)+MAX((8*W4/304.8),0.5,($E$2*W4/304.8))) -> 0 | Y27: =IF($E$44=Y22,W4,0) -> 0 | Z27: =IF($E$44=Y22,(X27*Y27*Y27/533),0) -> 0 | AC27: Top L EXT= | AE27: =AC4*((12*AD4/304.8)+MAX((8*AD4/304.8),0.5,($E$2*AD4/304.8))) -> 0 | AF27: =IF($E$44=AF22,AD4,0) -> 0 | AG27: =IF($E$44=AF22,(AE27*AF27*AF27/533),0) -> 0 | AJ27: Top L EXT= | AL27: =AJ4*((12*AK4/304.8)+MAX((8*AK4/304.8),0.5,($E$2*AK4/304.8))) -> 1.7167629 | AM27: =IF($E$44=AM22,AK4,0) -> 0 | AN27: =IF($E$44=AM22,(AL27*AM27*AM27/533),0) -> 0 | AQ27: Top L EXT= | AS27: =AQ4*((12*AR4/304.8)+MAX((8*AR4/304.8),0.5,($E$2*AR4/304.8))) -> 1.7167629 | AT27: =IF($E$44=AT22,AR4,0) -> 0 | AU27: =IF($E$44=AT22,(AS27*AT27*AT27/533),0) -> 0 | AX27: Top L EXT= | AZ27: =AX4*((12*AY4/304.8)+MAX((8*AY4/304.8),0.5,($E$2*AY4/304.8))) -> 1.7167629 | BA27: =IF($E$44=BA22,AY4,0) -> 0 | BB27: =IF($E$44=BA22,(AZ27*BA27*BA27/533),0) -> 0 | BE27: Top L EXT= | BG27: =BE4*((12*BF4/304.8)+MAX((8*BF4/304.8),0.5,($E$2*BF4/304.8))) -> 1.7167629 | BH27: =IF($E$44=BH22,BF4,0) -> 0 | BI27: =IF($E$44=BH22,(BG27*BH27*BH27/533),0) -> 0 | BL27: Top L EXT= | BN27: =BL4*((12*BM4/304.8)+MAX((8*BM4/304.8),0.5,($E$2*BM4/304.8))) -> 1.7167629 | BO27: =IF($E$44=BO22,BM4,0) -> 0 | BP27: =IF($E$44=BO22,(BN27*BO27*BO27/533),0) -> 0 | BS27: Top L EXT= | BU27: =BS4*((12*BT4/304.8)+MAX((8*BT4/304.8),0.5,($E$2*BT4/304.8))) -> 1.7167629 | BV27: =IF($E$44=BV22,BT4,0) -> 0 | BW27: =IF($E$44=BV22,(BU27*BV27*BV27/533),0) -> 0 | BZ27: Top L EXT= | CB27: =BZ4*((12*CA4/304.8)+MAX((8*CA4/304.8),0.5,($E$2*CA4/304.8))) -> 1.7167629 | CC27: =IF($E$44=CC22,CA4,0) -> 0 | CD27: =IF($E$44=CC22,(CB27*CC27*CC27/533),0) -> 0 | CG27: Top L EXT= | CI27: =CG4*((12*CH4/304.8)+MAX((8*CH4/304.8),0.5,($E$2*CH4/304.8))) -> 1.7167629 | CJ27: =IF($E$44=CJ22,CH4,0) -> 0 | CK27: =IF($E$44=CJ22,(CI27*CJ27*CJ27/533),0) -> 0 | CL27: =SUM(CJ27,CC27,BV27,BO27,BH27,BA27,AT27,AM27,AF27,Y27,R27,K27) -> 16 | CM27: =SUM(CK27,CD27,BW27,BP27,BI27,BB27,AU27,AN27,AG27,Z27,S27,L27) -> 0
H28: Top L EXT= | J28: =H5*((12*I5/304.8)+MAX((8*I5/304.8),0.5,($E$2*I5/304.8))) -> 1.7167629 | K28: =IF($E$44=K22,I5,0) -> 0 | L28: =IF($E$44=K22,(J28*K28*K28/533),0) -> 0 | O28: Top L EXT= | Q28: =O5*((12*P5/304.8)+MAX((8*P5/304.8),0.5,($E$2*P5/304.8))) -> 1.7167629 | R28: =IF($E$44=R22,P5,0) -> 16 | S28: =IF($E$44=R22,(Q28*R28*R28/533),0) -> 0.82456154 | V28: Top L EXT= | X28: =V5*((12*W5/304.8)+MAX((8*W5/304.8),0.5,($E$2*W5/304.8))) -> 1.7167629 | Y28: =IF($E$44=Y22,W5,0) -> 0 | Z28: =IF($E$44=Y22,(X28*Y28*Y28/533),0) -> 0 | AC28: Top L EXT= | AE28: =AC5*((12*AD5/304.8)+MAX((8*AD5/304.8),0.5,($E$2*AD5/304.8))) -> 3.4335258 | AF28: =IF($E$44=AF22,AD5,0) -> 0 | AG28: =IF($E$44=AF22,(AE28*AF28*AF28/533),0) -> 0 | AJ28: Top L EXT= | AL28: =AJ5*((12*AK5/304.8)+MAX((8*AK5/304.8),0.5,($E$2*AK5/304.8))) -> 3.4335258 | AM28: =IF($E$44=AM22,AK5,0) -> 0 | AN28: =IF($E$44=AM22,(AL28*AM28*AM28/533),0) -> 0 | AQ28: Top L EXT= | AS28: =AQ5*((12*AR5/304.8)+MAX((8*AR5/304.8),0.5,($E$2*AR5/304.8))) -> 3.4335258 | AT28: =IF($E$44=AT22,AR5,0) -> 0 | AU28: =IF($E$44=AT22,(AS28*AT28*AT28/533),0) -> 0 | AX28: Top L EXT= | AZ28: =AX5*((12*AY5/304.8)+MAX((8*AY5/304.8),0.5,($E$2*AY5/304.8))) -> 3.4335258 | BA28: =IF($E$44=BA22,AY5,0) -> 0 | BB28: =IF($E$44=BA22,(AZ28*BA28*BA28/533),0) -> 0 | BE28: Top L EXT= | BG28: =BE5*((12*BF5/304.8)+MAX((8*BF5/304.8),0.5,($E$2*BF5/304.8))) -> 3.4335258 | BH28: =IF($E$44=BH22,BF5,0) -> 0 | BI28: =IF($E$44=BH22,(BG28*BH28*BH28/533),0) -> 0 | BL28: Top L EXT= | BN28: =BL5*((12*BM5/304.8)+MAX((8*BM5/304.8),0.5,($E$2*BM5/304.8))) -> 3.4335258 | BO28: =IF($E$44=BO22,BM5,0) -> 0 | BP28: =IF($E$44=BO22,(BN28*BO28*BO28/533),0) -> 0 | BS28: Top L EXT= | BU28: =BS5*((12*BT5/304.8)+MAX((8*BT5/304.8),0.5,($E$2*BT5/304.8))) -> 3.4335258 | BV28: =IF($E$44=BV22,BT5,0) -> 0 | BW28: =IF($E$44=BV22,(BU28*BV28*BV28/533),0) -> 0 | BZ28: Top L EXT= | CB28: =BZ5*((12*CA5/304.8)+MAX((8*CA5/304.8),0.5,($E$2*CA5/304.8))) -> 3.4335258 | CC28: =IF($E$44=CC22,CA5,0) -> 0 | CD28: =IF($E$44=CC22,(CB28*CC28*CC28/533),0) -> 0 | CG28: Top L EXT= | CI28: =CG5*((12*CH5/304.8)+MAX((8*CH5/304.8),0.5,($E$2*CH5/304.8))) -> 3.4335258 | CJ28: =IF($E$44=CJ22,CH5,0) -> 0 | CK28: =IF($E$44=CJ22,(CI28*CJ28*CJ28/533),0) -> 0 | CL28: =SUM(CJ28,CC28,BV28,BO28,BH28,BA28,AT28,AM28,AF28,Y28,R28,K28) -> 16 | CM28: =SUM(CK28,CD28,BW28,BP28,BI28,BB28,AU28,AN28,AG28,Z28,S28,L28) -> 0.82456154
E30: Bar Dia | F30: Long Bar | G30: Trns Bar | L30: Bar Dia | M30: Long Bar | N30: Trns Bar | S30: Bar Dia | T30: Long Bar | U30: Trns Bar | Z30: Bar Dia | AA30: Long Bar | AB30: Trns Bar | AG30: Bar Dia | AH30: Long Bar | AI30: Trns Bar | AN30: Bar Dia | AO30: Long Bar | AP30: Trns Bar | AU30: Bar Dia | AV30: Long Bar | AW30: Trns Bar | BB30: Bar Dia | BC30: Long Bar | BD30: Trns Bar | BI30: Bar Dia | BJ30: Long Bar | BK30: Trns Bar | BP30: Bar Dia | BQ30: Long Bar | BR30: Trns Bar | BW30: Bar Dia | BX30: Long Bar | BY30: Trns Bar | CD30: Bar Dia | CE30: Long Bar | CF30: Trns Bar
E31: 8 | F31: =SUMIF($E$12:$E$21,E31,$F$12:$F$21) -> 0 | G31: =IF(E31=$H$16,$H$18*E31*E31/533,0) -> 0 | L31: 8 | M31: =SUMIF($L$12:$L$21,L31,$M$12:$M$21) -> 0 | N31: =IF(L31=$O$16,$O$18*L31*L31/533,0) -> 0 | S31: 8 | T31: =SUMIF($S$12:$S$21,S31,$T$12:$T$21) -> 0 | U31: =IF(S31=$V$16,$V$18*S31*S31/533,0) -> 0 | Z31: 8 | AA31: =SUMIF($Z$12:$Z$21,Z31,$AA$12:$AA$21) -> 0 | AB31: =IF(Z31=$AC$16,$AC$18*Z31*Z31/533,0) -> 0 | AG31: 8 | AH31: =SUMIF($AG$12:$AG$21,AG31,$AH$12:$AH$21) -> 0 | AI31: =IF(AG31=$AJ$16,$AJ$18*AG31*AG31/533,0) -> 0 | AN31: 8 | AO31: =SUMIF($AN$12:$AN$21,AN31,$AO$12:$AO$21) -> 0 | AP31: =IF(AN31=$AQ$16,$AQ$18*AN31*AN31/533,0) -> 0 | AU31: 8 | AV31: =SUMIF($AU$12:$AU$21,AU31,$AV$12:$AV$21) -> 0 | AW31: =IF(AU31=$AX$16,$AX$18*AU31*AU31/533,0) -> 0 | BB31: 8 | BC31: =SUMIF($BB$12:$BB$21,BB31,$BC$12:$BC$21) -> 0 | BD31: =IF(BB31=$BE$16,$BE$18*BB31*BB31/533,0) -> 0 | BI31: 8 | BJ31: =SUMIF($BI$12:$BI$21,BI31,$BJ$12:$BJ$21) -> 0 | BK31: =IF(BI31=$BL$16,$BL$18*BI31*BI31/533,0) -> 0 | BP31: 8 | BQ31: =SUMIF($BP$12:$BP$21,BP31,$BQ$12:$BQ$21) -> 0 | BR31: =IF(BP31=$BS$16,$BS$18*BP31*BP31/533,0) -> 0 | BW31: 8 | BX31: =SUMIF($BW$12:$BW$21,BW31,$BX$12:$BX$21) -> 0 | BY31: =IF(BW31=$BZ$16,$BZ$18*BW31*BW31/533,0) -> 0 | CD31: 8 | CE31: =SUMIF($CD$12:$CD$21,CD31,$CE$12:$CE$21) -> 0 | CF31: =IF(CD31=$CG$16,$CG$18*CD31*CD31/533,0) -> 0
